Workbook
Name CENTER_DISTANCE_MAX: 'Center Distance'!$D$21
Name CENTER_DISTANCE_MIN: 'Center Distance'!$D$20
Name Center_DistanceO: Data!$B$22
Name Construction: Data!$B$18
Name FAN_A: 'Fan Data'!$G$3
Name FAN_AH: 'Fan Data'!$AG$3
Name FAN_B: 'Fan Data'!$H$3
Name FAN_BAH: 'Fan Data'!$I$3
Name FAN_BAT: 'Fan Data'!$K$3
Name FAN_BAW: 'Fan Data'!$J$3
Name FAN_BH: 'Fan Data'!$L$3
Name FAN_BH_NOM: 'Fan Data'!$M$3
Name FAN_BRG_DIA: 'Fan Data'!$AR$3
Name FAN_BRG_H: 'Fan Data'!$AT$3
Name FAN_BRG_SUP_T: 'Fan Data'!$AQ$3
Name FAN_BRG_SUP_W: 'Fan Data'!$AP$3
Name FAN_BRG_W: 'Fan Data'!$AS$3
Name FAN_CF: 'Fan Data'!#REF!
Name FAN_D: 'Fan Data'!#REF!
Name Fan_Data_Column_Names: 'Fan Data'!$C$3:$DM$3
Name Fan_Data_Table: 'Fan Data'!$C$3:$DM$66
Name FAN_DC: 'Fan Data'!$N$3
Name FAN_DD: 'Fan Data'!$O$3
Name FAN_DE: 'Fan Data'!$P$3
Name FAN_DX: 'Fan Data'!$Q$3
Name FAN_E: 'Fan Data'!#REF!
Name FAN_G: 'Fan Data'!$R$3
Name FAN_GA: 'Fan Data'!$S$3
Name FAN_GB: 'Fan Data'!$T$3
Name FAN_GC: 'Fan Data'!$U$3
Name FAN_H: 'Fan Data'!$V$3
Name FAN_HE: 'Fan Data'!$W$3
Name FAN_HJ: 'Fan Data'!$X$3
Name FAN_HN: 'Fan Data'!$Y$3
Name FAN_HY: 'Fan Data'!#REF!
Name FAN_INLET_FLG_W: 'Fan Data'!$AO$3
Name FAN_J: 'Fan Data'!$Z$3
Name FAN_K: 'Fan Data'!$AH$3
Name FAN_KSD: 'Fan Data'!$AF$3
Name FAN_KSL: 'Fan Data'!$AD$3
Name FAN_KSW: 'Fan Data'!$AE$3
Name FAN_M: 'Fan Data'!$AI$3
Name FAN_N: 'Fan Data'!$AJ$3
Name FAN_ND: 'Fan Data'!$AK$3
Name FAN_P: 'Fan Data'!$AA$3
Name FAN_Q: 'Fan Data'!$AB$3
Name FAN_SD: 'Fan Data'!$AC$3
Name FAN_SHAFT_DIAMETER: 'Center Distance'!$D$33
Name Fan_Start: Data!$B$19
Name FAN_U: 'Fan Data'!#REF!
Name FAN_WID: 'Fan Data'!$AM$3
Name FAN_WOD: 'Fan Data'!$AL$3
Name FAN_WW: 'Fan Data'!$AN$3
Name FAN_X_LOCATION: Data!$B$14
Name FanBase_Type_ForcedO: Data!$B$21
Name FANCLASS: Data!$B$7
Name FANDISCHARGELOC: Data!$B$9
Name FANSIZE: Data!$B$6
Name FanStndStrBasePadThk: Data!$G$4
Name FANWEIGHT: Data!$B$8

Sheet Sheet1
A1: HOLE | B1: VALUE | C1: DESCRIPTION | E1: NAME | F1: VALUE | G1: COMMENT | I1: ITEM | J1: DESCRIPTION | K1: PART NO. | L1: QTY
A2: F1 | B2: ='Excel Calcs'!B164 -> 1.13 | C2: =CONCATENATE('Excel Calcs'!B123," THRU") -> 0.5 THRU | E2: ISOX | F2: ='Excel Calcs'!B151 -> 87.03 | G2: =IF(F2="-","-","ISO to ISO OVERALL WIDTH") -> ISO to ISO OVERALL WIDTH | I2: 1 | J2: =IF('Excel Calcs'!B86=4,CONCATENATE(VLOOKUP('Excel Calcs'!N17,Steel_List_Table,MATCH(STL_DESC,Steel_List_Column_Names,0),FALSE)," x ",ROUND('Excel Calcs'!N18,2)),CONCATENATE(VLOOKUP('Excel Calcs'!K13,Steel_List_Table,MATCH(STL_DESC,Steel_List_Column_Names,0),FALSE)," x ",ROUND('Excel Calcs'!K14,2))) -> 6" x 8.2# Structural Channel x 77.53 | K2: =IF('Excel Calcs'!B86=4,VLOOKUP('Excel Calcs'!N17,Steel_List_Table,MATCH(STL_PNUM,Steel_List_Column_Names,0),FALSE),VLOOKUP('Excel Calcs'!K13,Steel_List_Table,MATCH(STL_PNUM,Steel_List_Column_Names,0),FALSE)) -> 001 08405 006 | L2: 1
A3: F2 | B3: ='Excel Calcs'!B165 -> 45.5 | C3: =IF(B3="-","-",$C$2) -> 0.5 THRU | E3: ISOZ | F3: ='Excel Calcs'!B152 -> 43.61 | G3: =IF(F3="-","-","ISO to ISO OVERALL LENGTH") -> ISO to ISO OVERALL LENGTH | I3: 2 | J3: =IF('Excel Calcs'!B86=4,CONCATENATE(VLOOKUP('Excel Calcs'!N39,Steel_List_Table,MATCH(STL_DESC,Steel_List_Column_Names,0),FALSE)," x ",ROUND('Excel Calcs'!N40,2)),CONCATENATE(VLOOKUP('Excel Calcs'!K13,Steel_List_Table,MATCH(STL_DESC,Steel_List_Column_Names,0),FALSE)," x ",ROUND('Excel Calcs'!K14,2))) -> 6" x 8.2# Structural Channel x 77.53 | K3: =IF('Excel Calcs'!B86=4,VLOOKUP('Excel Calcs'!N39,Steel_List_Table,MATCH(STL_PNUM,Steel_List_Column_Names,0),FALSE),VLOOKUP('Excel Calcs'!K13,Steel_List_Table,MATCH(STL_PNUM,Steel_List_Column_Names,0),FALSE)) -> 001 08405 006 | L3: 1
A4: F3 | B4: ='Excel Calcs'!B166 -> 30.9 | C4: =IF(B4="-","-",$C$2) -> 0.5 THRU | E4: D1 | F4: ='Excel Calcs'!B153 -> 51.61 | G4: =IF(F4="-","-","TOTAL FAN SKID LENGTH") -> TOTAL FAN SKID LENGTH | I4: 3 | J4: =IF('Excel Calcs'!B86=4,CONCATENATE(VLOOKUP('Excel Calcs'!N60,Steel_List_Table,MATCH(STL_DESC,Steel_List_Column_Names,0),FALSE)," x ",ROUND('Excel Calcs'!N62,2)),CONCATENATE(VLOOKUP('Excel Calcs'!K24,Steel_List_Table,MATCH(STL_DESC,Steel_List_Column_Names,0),FALSE)," x ",ROUND('Excel Calcs'!K25,2))) -> 6" x 8.2# Structural Channel x 47.77 | K4: =IF('Excel Calcs'!B86=4,VLOOKUP('Excel Calcs'!N60,Steel_List_Table,MATCH(STL_PNUM,Steel_List_Column_Names,0),FALSE),VLOOKUP('Excel Calcs'!K24,Steel_List_Table,MATCH(STL_PNUM,Steel_List_Column_Names,0),FALSE)) -> 001 08405 006 | L4: 1
A5: F4 | B5: ='Excel Calcs'!B167 -> 11.92 | C5: =IF(B5="-","-",$C$2) -> 0.5 THRU | E5: D2 | F5: ='Excel Calcs'!B154 -> 77.53 | G5: =IF(F5="-","-","TOTAL FAN SKID WIDTH") -> TOTAL FAN SKID WIDTH | I5: 4 | J5: =IF('Excel Calcs'!B86=4,CONCATENATE(VLOOKUP('Excel Calcs'!N60,Steel_List_Table,MATCH(STL_DESC,Steel_List_Column_Names,0),FALSE)," x ",ROUND('Excel Calcs'!N62,2)),CONCATENATE(VLOOKUP('Excel Calcs'!K24,Steel_List_Table,MATCH(STL_DESC,Steel_List_Column_Names,0),FALSE)," x ",ROUND('Excel Calcs'!K25,2))) -> 6" x 8.2# Structural Channel x 47.77 | K5: =IF('Excel Calcs'!B86=4,VLOOKUP('Excel Calcs'!N60,Steel_List_Table,MATCH(STL_PNUM,Steel_List_Column_Names,0),FALSE),VLOOKUP('Excel Calcs'!K24,Steel_List_Table,MATCH(STL_PNUM,Steel_List_Column_Names,0),FALSE)) -> 001 08405 006 | L5: 1
A6: F5 | B6: ='Excel Calcs'!B168 -> 31.76 | C6: =IF(B6="-","-",$C$2) -> 0.5 THRU | E6: D3 | F6: ='Excel Calcs'!B155 -> 45.5 | G6: =IF(F6="-","-","INTERNAL DOA RAIL1 LOCATION") -> INTERNAL DOA RAIL1 LOCATION | I6: 5 | J6: =IF('Excel Calcs'!B86=4,CONCATENATE(VLOOKUP('Excel Calcs'!N75,Steel_List_Table,MATCH(STL_DESC,Steel_List_Column_Names,0),FALSE)," x ",ROUND('Excel Calcs'!N76,2)),CONCATENATE(VLOOKUP('Excel Calcs'!K41,Steel_List_Table,MATCH(STL_DESC,Steel_List_Column_Names,0),FALSE)," x ",ROUND('Excel Calcs'!K42,2))) -> 6" x 8.2# Structural Channel x 47.77 | K6: =IF('Excel Calcs'!B86=4,VLOOKUP('Excel Calcs'!N75,Steel_List_Table,MATCH(STL_PNUM,Steel_List_Column_Names,0),FALSE),VLOOKUP('Excel Calcs'!K41,Steel_List_Table,MATCH(STL_PNUM,Steel_List_Column_Names,0),FALSE)) -> 001 08405 006 | L6: =IF(J6="-","-",IF(AND('Excel Calcs'!N72=1,'Excel Calcs'!B9=1),2,'Excel Calcs'!K35+'Excel Calcs'!K36)) -> 2
A7: F6 | B7: ='Excel Calcs'!B169 -> 7.93 | C7: =IF(B7="-","-",$C$2) -> 0.5 THRU | E7: D4 | F7: ='Excel Calcs'!B156 -> 62.56 | G7: =IF(F7="-","-","INTERNAL DOA RAIL2 LOCATION") -> INTERNAL DOA RAIL2 LOCATION | I7: 6 | J7: =IF('Excel Calcs'!B86=4,"-",CONCATENATE(VLOOKUP('Excel Calcs'!K66,Steel_List_Table,MATCH(STL_DESC,Steel_List_Column_Names,0),FALSE)," x ",ROUND('Excel Calcs'!K69,2))) -> 4" x 5.4# Structural Channel x 21.25 | K7: =IF(J7="-","-",VLOOKUP('Excel Calcs'!K66,Steel_List_Table,MATCH(STL_PNUM,Steel_List_Column_Names,0),FALSE)) -> 001 08405 004 | L7: =IF(J7="-","-",2) -> 2
A8: MB1 | B8: ='Excel Calcs'!B170 -> 1.38 | C8: =CONCATENATE('Excel Calcs'!B136," THRU") -> 0.75 THRU | E8: D5 | F8: ='Excel Calcs'!B157 -> - | G8: =IF(F8="-","-","INTERNAL DOW RAIL LOCATION") -> - | I8: 7 | J8: =IF(AND(B520=0,B521=0),"-",IF(OR(B520=1,Sheet1!B520=2),CONCATENATE(VLOOKUP('Excel Calcs'!N50,Steel_List_Table,MATCH(STL_DESC,Steel_List_Column_Names,0),FALSE)," x ",ROUND('Excel Calcs'!N51,2)),CONCATENATE(VLOOKUP('Excel Calcs'!K55,Steel_List_Table,MATCH(STL_DESC,Steel_List_Column_Names,0),FALSE)," x ",ROUND('Excel Calcs'!K56,2)))) -> - | K8: =IF(J8="-","-",IF(B491=4,VLOOKUP('Excel Calcs'!N50,Steel_List_Table,MATCH(STL_PNUM,Steel_List_Column_Names,0),FALSE),VLOOKUP('Excel Calcs'!K55,Steel_List_Table,MATCH(STL_PNUM,Steel_List_Column_Names,0),FALSE))) -> - | L8: =IF(J8="-","-",1) -> -
A9: MB2 | B9: ='Excel Calcs'!B171 -> 18.5 | C9: =IF(B9="-","-",$C$8) -> 0.75 THRU | E9: D6 | F9: ='Excel Calcs'!B158 -> - | G9: =IF(F9="-","-","INTERNAL BTM DISCH DOW RAIL LOCATION") -> - | I9: 8 | J9: =IF(Sheet1!B402=4,"-",CONCATENATE("Isolator Support Angle - S1 Location")) -> Isolator Support Angle - S1 Location | K9: =IF(J9="-","-",VLOOKUP('Excel Calcs'!K83,Isolator_SupAng_Table,MATCH(SUPANG_PN,Isolator_SupAng_Column_Names,0),FALSE)) -> 091 20019 010 | L9: =IF(J9="-","-",1) -> 1
A10: MB3 | B10: ='Excel Calcs'!B172 -> 1.37 | C10: =IF(B10="-","-",$C$8) -> 0.75 THRU | E10: D7 | F10: ='Excel Calcs'!B159 -> - | G10: =IF(F10="-","-","FIA DOW RAIL LOCATION") -> - | I10: 9 | J10: =IF(Sheet1!B402=4,"-",CONCATENATE("Isolator Support Angle - S2 Location")) -> Isolator Support Angle - S2 Location | K10: =IF(J10="-","-",VLOOKUP('Excel Calcs'!K85,Isolator_SupAng_Table,MATCH(SUPANG_PN,Isolator_SupAng_Column_Names,0),FALSE)) -> 091 20019 010 | L10: =IF(J10="-","-",1) -> 1
A11: MB4 | B11: ='Excel Calcs'!B173 -> 2 | C11: =IF(B11="-","-",$C$8) -> 0.75 THRU | E11: D8 | F11: ='Excel Calcs'!B160 -> - | G11: =IF(F11="-","-","LIA DOW RAIL LOCATION") -> - | I11: 10 | J11: =IF(Sheet1!B402=4,"-",CONCATENATE("Isolator Support Angle - S3 Location")) -> Isolator Support Angle - S3 Location | K11: =IF(J11="-","-",VLOOKUP('Excel Calcs'!K87,Isolator_SupAng_Table,MATCH(SUPANG_PN,Isolator_SupAng_Column_Names,0),FALSE)) -> 091 20019 010 | L11: =IF(J11="-","-",1) -> 1
A12: MB5 | B12: ='Excel Calcs'!B174 -> 16 | C12: =IF(B12="-","-",$C$8) -> 0.75 THRU | E12: D9 | F12: ='Excel Calcs'!B161 -> 1.92 | G12: =IF(F12="-","-","MOTOR SUP RAIL Z LOCATION") -> MOTOR SUP RAIL Z LOCATION | I12: 11 | J12: =IF(Sheet1!B402=4,"-",CONCATENATE("Isolator Support Angle - S4 Location")) -> Isolator Support Angle - S4 Location | K12: =IF(J12="-","-",VLOOKUP('Excel Calcs'!K89,Isolator_SupAng_Table,MATCH(SUPANG_PN,Isolator_SupAng_Column_Names,0),FALSE)) -> 091 20019 010 | L12: =IF(J12="-","-",1) -> 1
A13: MB6 | B13: ='Excel Calcs'!B175 -> - | C13: =IF(B13="-","-",$C$8) -> - | E13: D10 | F13: ='Excel Calcs'!B162 -> 16 | G13: =IF(F13="-","-","MOTOR SUP RAIL SPACING") -> MOTOR SUP RAIL SPACING
E14: D11 | F14: ='Excel Calcs'!B163 -> 2.48 | G14: =IF(F14="-","-","MOTOR SUP RAIL, MOTOR SIDE OVERHANG") -> MOTOR SUP RAIL, MOTOR SIDE OVERHANG
A19: Parameter | B19: Value | C19: UM
A20: Inside_Height | B20: ='Excel Calcs'!B5 -> 106 | C20: in
A21: Inside_Width | B21: ='Excel Calcs'!B6 -> 134 | C21: in
A22: Core_Segment_Length | B22: ='Excel Calcs'!B7 -> 76 | C22: in
A23: MotorHand | B23: ='Excel Calcs'!B8 -> 1 | C23: ul
A24: MotorLocation | B24: ='Excel Calcs'!B9 -> 1 | C24: ul
A25: Tolerance_Gap | B25: ='Excel Calcs'!B10 -> 0.031 | C25: in
A26: Side_BH_To_Shell_Clearance | B26: ='Excel Calcs'!B12 -> 0.31 | C26: in
A27: Base_Fan_Z_Location | B27: ='Excel Calcs'!B15 -> 48.69 | C27: in
A28: Base_Fan_Y_Location | B28: ='Excel Calcs'!B16 -> 8.90601 | C28: in
A29: Base_Fan_X_Location | B29: ='Excel Calcs'!B17 -> 47.845 | C29: in
A30: FAN_Location_In_Segment | B30: =IF('Excel Calcs'!B26="FIA",1,2) -> 2 | C30: ul
A31: FAN_FanType_Selection | B31: ='Excel Calcs'!B27 -> 3 | C31: ul
A32: FAN_FanBlade_Direction | B32: ='Excel Calcs'!B28 -> 1 | C32: ul
A33: FAN_WH_DIA_Nominal | B33: ='Excel Calcs'!B29 -> 30 | C33: in
A34: FAN_LB | B34: ='Excel Calcs'!B30 -> 1024 | C34: in
A35: FAN_Sheave_LB | B35: ='Excel Calcs'!B31 -> 25 | C35: in
A36: FAN_A | B36: ='Excel Calcs'!B32 -> 31.81 | C36: in
A37: FAN_B | B37: ='Excel Calcs'!B33 -> 42.75 | C37: in
A38: FAN_BAH | B38: ='Excel Calcs'!B34 -> 2.5 | C38: in
A39: FAN_BAW | B39: ='Excel Calcs'!B35 -> 2.5 | C39: in
A40: FAN_BAT | B40: ='Excel Calcs'!B36 -> 0.25 | C40: in
A41: FAN_BH | B41: ='Excel Calcs'!B37 -> 0.56 | C41: in
A42: FAN_BH_NOM | B42: ='Excel Calcs'!B38 -> 0.5 | C42: in
... A78: FAN_FRAME_TOP_Suppresion | B78: ='Excel Calcs'!B74 -> 1 | C78: ul
A79: MTR_C | B79: ='Excel Calcs'!E4 -> 30.28 | C79: in
...

Sheet Data
A1: INPUTS
A2: Parameter | B2: Value | C2: Description | F2: THIS BOX IS OUTPUT ONLY … DO NOT USE AS INPUTS
A3: IH | B3: 106 | C3: Inside Height | F3: Thickness Outputs
A4: IW | B4: 134 | C4: Inside Width | F4: InertiaPlateThk | G4: =IF(InertiaPlateThkO="-",'Excel Calcs'!Q18,InertiaPlateThkO) -> 0.05601 | H4: INERTIA FAN BASE SHEETMETAL BTM PANEL THICKNESS
A5: SEGL | B5: 76 | C5: Segment Length | F5: TopDischTransThk | G5: =IF(TopDischTransThkO="-",'Excel Calcs'!E98,InertiaPlateThkO) -> 0.05601 | H5: TOP DISCHARGE TRANSITION THICKNESS
A6: FANSIZE | B6: 300 | C6: 122 to 600 Class 1 & 2 182 to 600 Class 3
A7: FANCLASS | B7: 2 | C7: Fan Class 1, 2 or 3 | D7: 1, 2, 3
A8: FANWEIGHT | B8: 1024 | C8: Standard Fan Weights extracted from XML by MOM - Can be used as manual override for SQ purposes.
A9: FANDISCHARGELOC | B9: R | C9: F, FI, R, RI, T, TI, B, BI (Front, Front Inverted, Rear, Rear Inverted, Top, Top Inverted, Btm, Btm Inverted) | D9: F, FI, R, RI, T, TI, B, BI
A10: MOTORFRAME | B10: 326T | C10: Motor Frame Size
A11: MOTORLOCATION | B11: BESIDE | C11: BESIDE or BEHIND | D11: BESIDE, BEHIND
A12: MOTORHAND | B12: L | C12: L or R (Left or Right looking at air entering side of fan with airflow at your back) | D12: L, R
A13: MOTORWEIGHT | B13: 700 | C13: Standard Motor Weights extracted from XML by MOM - Can be used as manual override for SQ purposes. Edit manual (section 003) contains documentation on motor weights
A14: FAN_X_LOCATION | B14: 47.845 | C14: Location of "Base" fan in X direction (across width of unit). Dim is from RH origin plane (RH side of IW of unit) to center of Fan Discharge Default = 0 - Default value centers fan discharge in IW of unit
A15: ISOLATORDEFLECTION | B15: 2 | C15: 1 or 2 - Default = 2 | D15: 1, 2
A16: INERTIA | B16: NO | C16: YES or NO - Default = NO - Smaller fans that default to Type A base are forced to Type B when inertia is selected | D16: Yes, No
A17: MaterialStyle | B17: STL GALV | C17: Material Style | D17: STL GALV, SST304
A18: Construction | B18: BASELINE | C18: See "Isolator Plate" tab | D18: BASELINE, SEISMIC
A19: Fan_Start | B19: 0 | C19: Distance from segment start to fan discharge start - Default = 0"
A20: Motor_ChannelO | B20: 0 | C20: Only valid Channel sizes from steel list can be used. Enter as Channel Height followed a space followed by LB/FT (ie. 3 4.1 is 3" channel 4.1 lb/ft) - Default = 0
A21: FanBase_Type_ForcedO | B21: - | C21: "-", TYPEA, TYPEB, or TYPEC - Forces fan base to Type A, B or C regardless of fan size - STD = TypeA fan <=222, TypeB fan >222 and <=365, TypeC fan >365 - Default = "-" | D21: -, TYPEA, TYPEB, or TYPEC
A22: Center_DistanceO | B22: 0 | C22: Center Distance override - Default = 0
A23: InertiaPlateThkO | B23: - | C23: Inertia Bottom Plate Thickness Override - set to "-" when using defaults - Default = 16ga
A24: TopDischTransThkO | B24: - | C24: Top Discharge Transition Thickness Override - set to "-" when using defaults - Default = 16ga
A26: =IF(OR('Load Calculations'!B4>Isolators!G22,'Load Calculations'!C4>Isolators!G22,'Load Calculations'!D4>Isolators!G22,'Load Calculations'!E4>Isolators!G22),"WEIGHT CALCULATIONS EXCEED SINGLE ISOLATOR USE OF 2050LBS IN ONE OR MORE ISOLATOR LOCATIONS. PLEASE SEE LOAD CALCULATIONS TAB FOR LOAD DATA AND ADD/ADJUST ISOLATORS AS NEEDED TO MEET LOAD REQUIREMENT.",IF(AND(OR('Load Calculations'!B4>Isolators!G10,'Load Calculations'!C4>Isolators!G10,'Load Calculations'!D4>Isolators!G10,'Load Calculations'!E4>Isolators!G10),ISOLATORDEFLECTION=1),"LOAD EXCEEDS LARGEST SPRING FOR 1 INCH ISOLATOR DEFLECTION, PLEASE CHANGE ISOLATOR DEFLECTION TO 2"," "))

Sheet Excel Calcs
E1: =B17-B52+E10-E14-E16+E19-E17/2 -> 2.34
A2: Parameter | B2: Value | D2: Parameter | E2: Value | G2: Parameter | H2: Value | J2: Parameter | K2: Value | M2: Parameter | N2: Value | P2: Parameter | Q2: Value
A3: General | D3: Motor Data | G3: Isolator Plate Data | J3: Structural Fan Base Data Type B & C | M3: Structural Fan Base Data Type A | P3: Inertia Base Data
A4: Sheetmetal Weight lb/sqft/in | B4: 40.793 | D4: MTR_C | E4: =VLOOKUP(MOTORFRAME,Motor_Table,MATCH(MTR_C,Motor_Data_Column_Names,0),FALSE) -> 30.28 | G4: PLT_W | H4: ='Isolator Plate'!I4 -> 9 | J4: Min_Dist_HoleCtr_To_SteelWeb_FIA/LIA/DOA_Rail | K4: =E61/2+K18+K19*0.8 -> 1.1304 | M4: Min_Dist_HoleCtr_To_SteelWeb_DOA_Rail | N4: =IF(E61/2+N65+N66*0.666<1.5,1.5,E61/2+N65+N66*0.666) -> 1.5 | P4: FanBase_Str_Inertia_Internal_DOA_ChannelSpace | Q4: =K28+2.5 -> 4.42
A5: Inside Height | B5: =IH -> 106 | D5: MTR_D | E5: =VLOOKUP(MOTORFRAME,Motor_Table,MATCH(MTR_D,Motor_Data_Column_Names,0),FALSE) -> 8 | G5: PLT_L | H5: ='Isolator Plate'!J4 -> 13 | J5: DOA_INT_MTR_CHAN_to_MTRBS_Hole | K5: 0.5 | M5: Min_Dist_HoleCtr_To_SteelWeb_FIA/LIA_Rail | N5: =E61/2+N21+N22*0.666 -> 1.364 | P5: FanBase_Str_Inertia_BtmPlate_OutsideTollerance | Q5: 0.5
A6: Inside Width | B6: =IW -> 134 | D6: MTR_E | E6: =VLOOKUP(MOTORFRAME,Motor_Table,MATCH(MTR_E,Motor_Data_Column_Names,0),FALSE) -> 6.25 | G6: PLT_T | H6: ='Isolator Plate'!K4 -> 0.15601 | J6: FIAtoLIA_Channel_Distance | K6: =K12-K11+K21*2 -> 51.61 | M6: Min_Dist_FanMntHole_to_FIA/LIA_Rail | N6: =N5 -> 1.364 | P6: FanBase_Str_Inertia_Total_Plate_XDim | Q6: =IF(OR(B27=6,B27=8),K14+K28*2-Q5*2,K14-Q5*2) -> 76.5306
A7: Core_Segment_Length | B7: =Data!B5 -> 76 | D7: MTR_2F | E7: =VLOOKUP(MOTORFRAME,Motor_Table,MATCH(MTR_2F,Motor_Data_Column_Names,0),FALSE) -> 12 | G7: PLT_PH | H7: ='Isolator Plate'!L4 -> 0.25 | J7: FanFace_to_StructBaseFace | K7: =IF(AND(B9=2,OR(B27=1,B27=2,B27=3,B27=4,B27=5,B27=7)),0.5,IF(OR(B27=6,B27=8),K17+B11,IF(OR(B27=1,B27=2,B27=7),IF(B60<B49+0.5-K17-N6,0.5,K17-N6-(B49-B60)),IF(OR(B27=3,B27=4,B27=5),IF(B60<B49+0.5-K17-N6,0.5,K17-N6+B60-B49))))) -> 0.5 | M7: FIAtoLIA_Angle_Distance | N7: =N47-N26+N24+N46 -> 49.19 | P7: FanBase_Str_Inertia_Total_Plate_ZDim | Q7: =IF(B27=6,K54-K11-K21+K17-Q5*2,IF(B27=8,K25-(K54-(K11+K21-K17))-Q5*2,K25+K17*2-Q5*2)) -> 50.61
A8: MotorHand | B8: =IF(MOTORHAND="L",1,2) -> 1 | D8: MTR_H | E8: =VLOOKUP(MOTORFRAME,Motor_Table,MATCH(MTR_H,Motor_Data_Column_Names,0),FALSE) -> 0.656 | G8: PLT_SH | H8: =VLOOKUP(H11,Isolator_Plate_Table,MATCH(PLT_SH,Isolator_Plate_Column_Names,0),FALSE) -> 0.75 | J8: FanBase_Str_CHAN_Suppresion | K8: =IF(B20<>"TYPEA",1,0) -> 1 | M8: FanFace_to_StructBaseFace | N8: =IF(AND(B9=2,OR(B27=1,B27=2,B27=3,B27=4,B27=5,B27=7)),0.5,IF(B27=6,N42+B11,IF(B27=8,N20+B11,IF(OR(B27=1,B27=2,B27=7),IF(B60<B49+0.5-N20-N6,0.5,N20-N6-(B49-B60)),IF(OR(B27=3,B27=4,B27=5),IF(B60<B49+0.5-N42-N6,0.5,N42-N6+B60-B49)))))) -> 0.5 | P8: FanBase_Str_Inertia_MaxPlate_XDim | Q8: 36
A9: MotorLocation | B9: =IF(MOTORLOCATION="BESIDE",1,2) -> 1 | D9: MTR_P | E9: =VLOOKUP(MOTORFRAME,Motor_Table,MATCH(MTR_P,Motor_Data_Column_Names,0),FALSE) -> 16.5 | G9: PLT_Upstream_SLI | H9: =IF(OR(B27=1,B27=2),'Isolator Plate'!S7,'Isolator Plate'!S6) -> 6.5 | J9: FIA/LIA Channel Data | M9: FanBase_Str_ANG_Suppresion | N9: =IF(B20="TYPEA",1,0) -> 0 | P9: FanBase_Str_Inertia_Plate1_Suppresion | Q9: =IF(AND(B9=1,B27=8),0,IF(Q17>=1,1,0)) -> 0
A10: Tolerance_Gap | B10: 0.031 | D10: MTR_KWL | E10: =VLOOKUP(MOTORFRAME,Motor_Table,MATCH(MTR_KWL,Motor_Data_Column_Names,0),FALSE) -> 3.875 | G10: PLT_Dnstream_SLI | H10: =IF(OR(B27=3,B27=4),'Excel Calcs'!H5-'Isolator Plate'!S7,'Isolator Plate'!S6) -> 9.1875 | J10: FanBase_Str_FIA_LIA_CHAN_XLoc | K10: =IF(AND(B9=1,B8=1,OR(B27=6,B27=8)),K14/2-(B59-K32)+IF(K32=K4,B11,0),IF(AND(B9=1,B8=2,OR(B27=6,B27=8)),(K14/2-(B59-K32)+IF(K32=K4,B11,0))*-1,IF(AND(B9=1,B8=1),K14/2-(B59+K4),IF(AND(B9=1,B8=2),(K14/2-(B59+K4))*-1,IF(B9=2,0,FALSE))))) -> 14.8849 | M10: Isolator Hole Data | P10: FanBase_Str_Inertia_Plate2_Suppresion | Q10: =IF(Q17>=3,1,0) -> 0
A11: Fan_BtmDisch_Tolerance_Gap | B11: 0.031 | D11: MTR_R | E11: =VLOOKUP(MOTORFRAME,Motor_Table,MATCH(MTR_R,Motor_Data_Column_Names,0),FALSE) -> 1.844 | G11: PLTS1_Designation | H11: =IF(AND(OR(B27=1,B27=2,B27=5,B27=6,B27=7,B27=8),H43<>19,B21=2),3,IF(AND(OR(B27=1,B27=2,B27=5,B27=6,B27=7,B27=8),H43=19,B21=2),5,IF(AND(H43<>19,B21=2),4,IF(AND(H43=19,B21=2),6,IF(AND(OR(B27=1,B27=2,B27=5,B27=6,B27=7,B27=8),B21=1),1,IF(B21=1,2,FALSE)))))) -> 4 | J11: FanBase_Str_FIA_CHAN_ZLoc | K11: =IF(B27=8,B14-K7+K21,IF(B27=7,B14+K21-K7,IF(OR(B27=5,B27=6),B7-B14-B49+E58-E39-K70/2-K21,IF(OR(B27=1,B27=2),B13+K21-K7,IF(OR(B27=3,B27=4),B7-B13-B49+E58-E39-K70/2-K21))))) -> 21.85 | M11: FanBase_Str_DOA_ANG_IsoHole_STLOC | N11: =IF(B21=1,1.375,0.75) -> 0.75 | P11: FanBase_Str_Inertia_Plate3_Suppresion | Q11: =IF(Q17>=4,1,0) -> 0
A12: Side BH to Shell Clearance | B12: 0.31 | D12: MTR_S | E12: =VLOOKUP(MOTORFRAME,Motor_Table,MATCH(MTR_S,Motor_Data_Column_Names,0),FALSE) -> 0.5 | G12: PLTS1_OS | H12: =IF(ISEVEN(H11),0,1) -> 0 | J12: FanBase_Str_LIA_CHAN_ZLoc | K12: =IF(OR(B27=7,B27=8),B14+B49+E58+E39+K70/2+K21,IF(OR(B27=6,B27=5),B7-B14+K7-K21,IF(OR(B27=1,B27=2),B13+B49+E58+E39+K70/2+K21,IF(OR(B27=3,B27=4),B7-B13-K21+K7)))) -> 71.54 | M12: FanBase_Str_DOA_ANG_IsoHole_HS | N12: =K96 -> 2 | P12: FanBase_Str_Inertia_Plate4_Suppresion | Q12: =IF(Q17>=5,1,0) -> 0
A13: Fan_Disch_X_Distance (F, FI, R, RI) | B13: =IF(Fan_Start<>0,Fan_Start,4) -> 4 | D13: MTR_U | E13: =VLOOKUP(MOTORFRAME,Motor_Table,MATCH(MTR_U,Motor_Data_Column_Names,0),FALSE) -> 2.125 | G13: PLTS1_SS | H13: =IF(ISODD(H11),0,1) -> 1 | J13: FanBase_Str_FIA_LIA_CHAN_Lookup | K13: =CONCATENATE("Channel",K15,K16) -> Channel68.2 | M13: FanBase_Str_DOA_ANG_IsoHole_HL | N13: =K97 -> 1.25 | P13: FanBase_Str_Inertia_Plate5_Suppresion | Q13: =IF(AND(B9=1,B27=6),0,IF(AND(B9=1,B27=8,Q17=1),1,IF(Q17>=2,1,0))) -> 0
A14: Fan_Disch_X_Distance (T, TI, B, BI) | B14: =IF(Fan_Start<>0,Fan_Start,7) -> 7 | D14: MTR_V | E14: =VLOOKUP(MOTORFRAME,Motor_Table,MATCH(MTR_V,Motor_Data_Column_Names,0),FALSE) -> 5.25 | G14: PLTS1_SW1 | H14: =VLOOKUP(H11,Isolator_Plate_Table,MATCH(PLT_SW1,Isolator_Plate_Column_Names,0),FALSE) -> 2.625 | J14: FanBase_Str_FIA_LIA_CHAN_L | K14: =IF(AND(B9=2,OR(B27=6,B27=8)),B59*2-K32*2,IF(B9=2,B59*2+K4*2,IF(AND(B9=1,OR(B27=6,B27=8)),IF(K32=K4,B11,0)+(B59-K32)+(MAX(E56,B17)-MIN(E56,B17))+E33/2-K28,IF(K32=K4,B11,0)+(B59-K32)+(MAX(E56,B17)-MIN(E56,B17))+E33/2))) -> 77.5306 | M14: FanBase_Str_DOA_ANG_IsoHole_HD1 | N14: =K98 -> 0.625 | P14: FanBase_Str_Inertia_PlateBeside_Btm_Suppresion | Q14: =IF(AND(B9=1,OR(B27=6,B27=8),Q17>1),1,0) -> 0
A15: Base_Fan_Z_Location | B15: =IF(OR(B27=1,B27=2),B13+B49,IF(OR(B27=3,B27=4),B7-B13-B49,IF(OR(B27=5,B27=6),B7-B14-B49,IF(OR(B27=7,B27=8),B14+B49)))) -> 48.69 | D15: MTR_AB | E15: =VLOOKUP(MOTORFRAME,Motor_Table,MATCH(MTR_AB,Motor_Data_Column_Names,0),FALSE) -> 14.61 | G15: PLTS1_SW2 | H15: =VLOOKUP(H11,Isolator_Plate_Table,MATCH(PLT_SW2,Isolator_Plate_Column_Names,0),FALSE) -> 6.375 | J15: FanBase_Str_FIA_LIA_CHAN_H | K15: =IF(B20="TYPEC",8,6) -> 6 | M15: FanBase_Str_DOA_ANG_IsoHole_HD2 | N15: =K99 -> 0.875 | P15: FanBase_Str_Inertia_PlateBeside_BtmFiller_Suppresion | Q15: =IF(AND(B9=1,B27=6,Q17>=1),1,0) -> 0
A16: Base_Fan_Y_Location | B16: =IF(B20="TYPEA",H6+H42+N65,H6+H42+K94+K101) -> 8.90601 | D16: MTR_BA | E16: =VLOOKUP(MOTORFRAME,Motor_Table,MATCH(MTR_BA,Motor_Data_Column_Names,0),FALSE) -> 5.25 | G16: PLTS1_SL1 | H16: =VLOOKUP(H11,Isolator_Plate_Table,MATCH(PLT_SL1,Isolator_Plate_Column_Names,0),FALSE) -> 1.125 | J16: FanBase_Str_FIA_LIA_CHAN_LBFT | K16: =IF(K15=6,8.2,11.5) -> 8.2 | M16: FIA Angle Data | P16: FanBase_Str_Inertia_PlateBeside_BtmInvFiller_Suppresion | Q16: =IF(AND(B9=1,B27=8,Q17>=1),1,0) -> 0
A17: Base_Fan_X_Location | B17: =IF(FAN_X_LOCATION=0,B6/2,FAN_X_LOCATION) -> 47.845 | D17: MTR_BL | E17: =VLOOKUP(MOTORFRAME,Motor_Table,MATCH(MTR_BL,Motor_Data_Column_Names,0),FALSE) -> 14 | G17: PLTS1_SL2 | H17: =VLOOKUP(H11,Isolator_Plate_Table,MATCH(PLT_SL2,Isolator_Plate_Column_Names,0),FALSE) -> 6.5 | J17: FanBase_Str_FIA_LIA_CHAN_D | K17: =VLOOKUP(K13,Steel_List_Table,MATCH(STL_D,Steel_List_Column_Names,0),FALSE) -> 1.92 | M17: FanBase_Str_FIA_ANG_Lookup | N17: =CONCATENATE("Angle",N19,N20,N21) -> Angle430.375 | P17: FanBase_Str_Inertia_Plate_Qty | Q17: =IF(INERTIA<>"YES",0,IF(Q7<=Q8,1,IF(Q7/2<=Q8,2,IF(Q7/3<=Q8,3,IF(Q7/4<=Q8,4,5))))) -> 0
A18: MtrBehind_MinDistance_FanToMtr | B18: 0.5 | D18: MTR_BW | E18: =VLOOKUP(MOTORFRAME,Motor_Table,MATCH(MTR_BW,Motor_Data_Column_Names,0),FALSE) -> 14.5 | G18: PLTS2_Designation | H18: =IF(AND(OR(B27=3,B27=4,B27=5,B27=6,B27=7,B27=8),H56<>19,B21=2),3,IF(AND(OR(B27=3,B27=4,B27=5,B27=6,B27=7,B27=8),H56=19,B21=2),5,IF(AND(H56<>19,B21=2),4,IF(AND(H56=19,B21=2),6,IF(AND(OR(B27=3,B27=4,B27=5,B27=6,B27=7,B27=8),B21=1),1,IF(B21=1,2,FALSE)))))) -> 3 | J18: FanBase_Str_FIA_LIA_CHAN_WT | K18: =VLOOKUP(K13,Steel_List_Table,MATCH(STL_WT,Steel_List_Column_Names,0),FALSE) -> 0.2 | M18: FanBase_Str_FIA_ANG_L | N18: =IF(B9=2,B33,B33/2+B52-E10+E14+E16+E7/2+E40-N4) -> 74.63 | P18: FanBase_Str_Inertia_Plate_Thk | Q18: =IF(InertiaPlateThkO<>"-",InertiaPlateThkO,VLOOKUP(CONCATENATE(Q19,MaterialStyle),'Material List'!$A$8:$S$501,8,FALSE)) -> 0.05601
A19: Min_Isolator_CntrDist_DOA | B19: =H5-H9+0.25+H10 -> 15.9375 | D19: MTR_D1 | E19: =VLOOKUP(MOTORFRAME,Motor_Table,MATCH(MTR_D1,Motor_Data_Column_Names,0),FALSE) -> 1 | G19: PLTS2_OS | H19: =IF(ISEVEN(H18),0,1) -> 1 | J19: FanBase_Str_FIA_LIA_CHAN_FTR | K19: =VLOOKUP(K13,Steel_List_Table,MATCH(STL_FTR,Steel_List_Column_Names,0),FALSE) -> 0.343 | M19: FanBase_Str_FIA_ANG_H | N19: 4 | P19: FanBase_Str_Inertia_Plate_GA | Q19: =IF(InertiaPlateThkO<>"-","NA",16) -> 16
A20: FanBase_Type | B20: =IF(FanBase_Type_ForcedO<>"-",FanBase_Type_ForcedO,IF(AND(VALUE(LEFT(FANSIZE,2))<=22,INERTIA="YES"),"TYPEB",IF(FANSIZE<=22,"TYPEA",IF(AND(FANSIZE>22,FANSIZE<=36),"TYPEB",IF(AND(FANSIZE>36,FANSIZE<=55),"TYPEC",IF(FANSIZE<=222,"TYPEA",IF(AND(FANSIZE>222,FANSIZE<=365),"TYPEB",IF(FANSIZE>365,"TYPEC",FALSE)))))))) -> TYPEB | D20: MTR_D2 | E20: =VLOOKUP(MOTORFRAME,Motor_Table,MATCH(MTR_D2,Motor_Data_Column_Names,0),FALSE) -> 0.44 | G20: PLTS2_SS | H20: =IF(ISODD(H18),0,1) -> 0 | J20: FanBase_Str_FIA_LIA_CHAN_LB | K20: =K14*(VLOOKUP(K13,Steel_List_Table,MATCH(STL_LBFT,Steel_List_Column_Names,0),FALSE)/12) -> 52.979243 | M20: FanBase_Str_FIA_ANG_D | N20: 3 | P20: FanBase_Str_Inertia_Plate_YLoc | Q20: =B16-K15 -> 2.90601
A21: Isolator_Deflection | B21: =ISOLATORDEFLECTION -> 2 | D21: MTR_LB | E21: =MOTORWEIGHT -> 700 | G21: PLTS2_SW1 | H21: =VLOOKUP(H18,Isolator_Plate_Table,MATCH(PLT_SW1,Isolator_Plate_Column_Names,0),FALSE) -> 1.125 | J21: FanBase_Str_FIA_LIA_CHAN_Loc_Plane | K21: =K17/2 -> 0.96 | M21: FanBase_Str_FIA_ANG_WT | N21: 0.375 | P21: FanBase_Str_Inertia_Plate_XLoc | Q21: =K10 -> 14.8849
D22: MTR_Sheave_LB | E22: =(VLOOKUP(MOTORFRAME,Motor_Table,MATCH(MTR_HP,Motor_Data_Column_Names,0),FALSE))/2 -> 25 | G22: PLTS2_SW2 | H22: =VLOOKUP(H18,Isolator_Plate_Table,MATCH(PLT_SW2,Isolator_Plate_Column_Names,0),FALSE) -> 4.875 | J22: DOA Channel Data | M22: FanBase_Str_FIA_ANG_FTR | N22: 0.5 | P22: FanBase_Str_Inertia_Plate_FlangeH | Q22: =Q94-Q88/2 -> 1.75
A23: Parameter | B23: Value | D23: MTR_Hand | E23: =IF(MOTORHAND="L",1,2) -> 1 | G23: PLTS2_SL1 | H23: =VLOOKUP(H18,Isolator_Plate_Table,MATCH(PLT_SL1,Isolator_Plate_Column_Names,0),FALSE) -> 3.8125 | J23: FanBase_Str_DOA_CHAN_Suppresion | K23: =IF(K8=0,0,IF(OR(B27=6,B27=8),2,1)) -> 1 | M23: FanBase_Str_FIA_ANG_LB | N23: =N18*(VLOOKUP(N17,Steel_List_Table,MATCH(STL_LBFT,Steel_List_Column_Names,0),FALSE)/12) -> 52.862917 | P23: FanBase_Str_Inertia_Plate_Flange_EndNotch | Q23: =K17-Q5+0.125 -> 1.545
A24: Fan Data | D24: MTR_Beside_X_Location | E24: =IF(B8=1,B17+B52-E10+E14+E16-E19+E17/2,B17-B52+E10-E14-E16+E19-E17/2) -> 93.35 | G24: PLTS2_SL2 | H24: =VLOOKUP(H18,Isolator_Plate_Table,MATCH(PLT_SL2,Isolator_Plate_Column_Names,0),FALSE) -> 9.1875 | J24: FanBase_Str_DOA_CHAN_Lookup | K24: =CONCATENATE("Channel",K26,K27) -> Channel68.2 | M24: FanBase_Str_FIA_ANG_HoleLoc_Plane | N24: =N20/2 -> 1.5 | P24: FanBase_Str_Inertia_Plate_Flange_BtmInvDischNotch_Suppresion | Q24: =IF(AND(B9=1,B27=8),1,0) -> 0
A25: FAN_Lookup | B25: =CONCATENATE(FANSIZE,IF(OR(FANDISCHARGELOC="F",FANDISCHARGELOC="FI",FANDISCHARGELOC="R",FANDISCHARGELOC="RI"),"H",IF(OR(FANDISCHARGELOC="T",FANDISCHARGELOC="TI"),"T",IF(OR(FANDISCHARGELOC="B",FANDISCHARGELOC="BI"),"B","")))) -> 300H | D25: MTR_Behind_X_Location | E25: =IF(B8=1,B17+B52-B55-(E14-E10)-E16-E7/2,B17-B52+B55+(E14-E10)+E16+E7/2) -> 62.6 | G25: PLTS3_Designation | H25: =IF(AND(OR(B27=1,B27=2,B27=5,B27=6,B27=7,B27=8),H69<>19,B21=2),3,IF(AND(OR(B27=1,B27=2,B27=5,B27=6,B27=7,B27=8),H69=19,B21=2),5,IF(AND(H69<>19,B21=2),4,IF(AND(H69=19,B21=2),6,IF(AND(OR(B27=1,B27=2,B27=5,B27=6,B27=7,B27=8),B21=1),1,IF(B21=1,2,FALSE)))))) -> 4 | J25: FanBase_Str_DOA_CHAN_L | K25: =IF(OR(B27=6,B27=8),K6,K6-K17*2) -> 47.77 | M25: FanBase_Str_FIA_ANG_XLoc | N25: =IF(AND(B9=1,B8=1),N18/2-B33/2,IF(AND(B9=1,B8=2),(N18/2-B33/2)*-1,IF(B9=2,0,FALSE))) -> 15.94 | P25: FanBase_Str_Inertia_Plate_Flange_BtmDischNotch_Suppresion | Q25: =IF(AND(B9=1,B27=6),1,0) -> 0
A26: FAN_Location_In_Segment | B26: =IF(OR(B27=1,B27=2,B27=7,B27=8),"FIA","LIA") -> LIA | D26: MTR_Y_Location | E26: =E57+E34 -> 12.99001 | G26: PLTS3_OS | H26: =IF(ISEVEN(H25),0,1) -> 0 | J26: FanBase_Str_DOA_CHAN_H | K26: =K15 -> 6 | M26: FanBase_Str_FIA_ANG_ZLoc | N26: =IF(B27=8,B14-N8+N24,IF(B27=7,B14+N24-N8,IF(OR(B27=5,B27=6),B7-B14-B49+E58-E39,IF(OR(B27=1,B27=2),B13+N24-N8,IF(OR(B27=3,B27=4),B7-B13-B49+E58-E39))))) -> 24.81 | P26: FanBase_Str_Inertia_Plate_Flange_SnglPlateNotch_Suppresion | Q26: =IF(AND(Q17=1,OR(Q24=1,Q25=1)),1,0) -> 0
A27: FAN_FanType_Selection | B27: =IF(FANDISCHARGELOC="F",1,IF(FANDISCHARGELOC="FI",2,IF(FANDISCHARGELOC="R",3,IF(FANDISCHARGELOC="RI",4,IF(FANDISCHARGELOC="T",5,IF(FANDISCHARGELOC="B",6,IF(FANDISCHARGELOC="TI",7,IF(FANDISCHARGELOC="BI",8,FALSE)))))))) -> 3 | D27: MTR_Beside_Z_Location | E27: =IF(OR(B27=1,B27=2,B27=7,B27=8),'Center Distance'!D5,'Center Distance'!D5*-1) -> -15.88 | G27: PLTS3_SS | H27: =IF(ISODD(H25),0,1) -> 1 | J27: FanBase_Str_DOA_CHAN_LBFT | K27: =K16 -> 8.2 | M27: MIA Angle Data | P27: FanBase_Str_Inertia_Plate_Flange_BtmDischNotch_XDim | Q27: =IF(B8=1,Q97+K28-Q5+K45+Q5,Q127+K28-Q5+K45+Q5) -> 9.84
A28: FAN_FanBlade_Direction | B28: =IF(OR(B27=2,B27=3,B27=6,B27=7),1,IF(OR(B27=1,B27=4,B27=5,B27=8),2,FALSE)) -> 1 | D28: MTR_Behind_Z_Location | E28: =IF(OR(B27=1,B27=2,B27=7,B27=8),'Center Distance'!D5,'Center Distance'!D5*-1) -> -15.88 | G28: PLTS3_SW1 | H28: =VLOOKUP(H25,Isolator_Plate_Table,MATCH(PLT_SW1,Isolator_Plate_Column_Names,0),FALSE) -> 2.625 | J28: FanBase_Str_DOA_CHAN_D | K28: =VLOOKUP(K24,Steel_List_Table,MATCH(STL_D,Steel_List_Column_Names,0),FALSE) -> 1.92 | M28: FanBase_Str_MIA_ANG_Suppresion | N28: =IF(N9=0,0,IF(MOTORLOCATION="BESIDE",0,1)) -> 0 | P28: FanBase_Str_Inertia_Plate_Flange_BtmDischNotch_XLoc | Q28: =IF(B8=1,Q6/2-Q27/2,(Q6/2-Q27/2)*-1) -> 33.3453
A29: FAN_WH_DIA_Nominal | B29: =VLOOKUP(B25,Fan_Data_Table,MATCH(WH_DIA_Nominal,Fan_Data_Column_Names,0),FALSE) -> 30 | G29: PLTS3_SW2 | H29: =VLOOKUP(H25,Isolator_Plate_Table,MATCH(PLT_SW2,Isolator_Plate_Column_Names,0),FALSE) -> 6.375 | J29: FanBase_Str_DOA_CHAN_WT | K29: =VLOOKUP(K24,Steel_List_Table,MATCH(STL_WT,Steel_List_Column_Names,0),FALSE) -> 0.2 | M29: FanBase_Str_MIA_ANG_Lookup | N29: =CONCATENATE("Angle",N31,N32,N33) -> Angle430.375 | P29: FanBase_Str_Inertia_Plate_Flange_IntFanNotch_XLoc | Q29: =IF(B9=2,6,IF(AND(B8=1,OR(B27=6,B27=8)),Q97+K28-Q5+K45/2,IF(AND(B8=2,OR(B27=6,B27=8)),Q97+K28-Q5+K46*2+Q112-K45/2,IF(B8=1,Q97+K29-Q5+K45/2,IF(B8=2,Q97+K29-Q5+K46*2+Q112-K45/2,FALSE))))) -> 6.66
A30: FAN_LB | B30: =FANWEIGHT -> 1024 | D30: Parameter | E30: Value | G30: PLTS3_SL1 | H30: =VLOOKUP(H25,Isolator_Plate_Table,MATCH(PLT_SL1,Isolator_Plate_Column_Names,0),FALSE) -> 1.125 | J30: FanBase_Str_DOA_CHAN_FTR | K30: =VLOOKUP(K24,Steel_List_Table,MATCH(STL_FTR,Steel_List_Column_Names,0),FALSE) -> 0.343 | M30: FanBase_Str_MIA_ANG_L | N30: =N18 -> 74.63 | P30: FanBase_Str_Inertia_Plate_Flange_IntFanNotch_Suppresion | Q30: =IF(Q26=1,0,IF(K36=0,0,1)) -> 1
A31: FAN_Sheave_LB | B31: =E22 -> 25 | D31: Motor Base Data | G31: PLTS3_SL2 | H31: =VLOOKUP(H25,Isolator_Plate_Table,MATCH(PLT_SL2,Isolator_Plate_Column_Names,0),FALSE) -> 6.5 | J31: FanBase_Str_DOA_CHAN_LB | K31: =K25*(VLOOKUP(K24,Steel_List_Table,MATCH(STL_LBFT,Steel_List_Column_Names,0),FALSE)/12) -> 32.642833 | M31: FanBase_Str_MIA_ANG_H | N31: 4 | P31: FanBase_Str_Inertia_Plate_Flange_IntMtrNotch_XLoc | Q31: =IF(AND(B8=1,B9=1,OR(B27=6,B27=8)),Q97+K28-Q5+K46+Q112+K46-K45/2,IF(AND(B8=1,B9=2,OR(B27=6,B27=8)),Q97+K28-Q5+K29-K45/2,IF(AND(B8=2,OR(B27=6,B27=8)),Q97+K28-Q5+K45/2,IF(AND(B8=1,B9=1),Q97+K29-Q5+K46+Q112+K46-K45/2,IF(B8=1,Q97+K29-Q5+K46-K45/2,IF(B8=2,Q97+K29-Q5+K45/2,FALSE)))))) -> 11.14
A32: FAN_A | B32: =VLOOKUP(B25,Fan_Data_Table,MATCH(FAN_A,Fan_Data_Column_Names,0),FALSE) -> 31.81 | D32: MTRBS_AL | E32: =VLOOKUP(MOTORFRAME,MotorBase_Table,MATCH(MTRBS_AL,MotorBase_Data_Column_Names,0),FALSE) -> 22.75 | G32: PLTS4_Designation | H32: =IF(AND(OR(B27=3,B27=4,B27=5,B27=6,B27=7,B27=8),H82<>19,B21=2),3,IF(AND(OR(B27=3,B27=4,B27=5,B27=6,B27=7,B27=8),H82=19,B21=2),5,IF(AND(H82<>19,B21=2),4,IF(AND(H82=19,B21=2),6,IF(AND(OR(B27=3,B27=4,B27=5,B27=6,B27=7,B27=8),B21=1),1,IF(B21=1,2,FALSE)))))) -> 3 | J32: FanBase_Str_DOA_CHAN_HoleLoc_Plane | K32: =IF(AND(B27<>6,B27<>8),K4,IF(K45-(B59-B33/2-B11+B37/2)<0.25,K45-B37/2-0.25,B59-B33/2-B11)) -> 1.1304 | M32: FanBase_Str_MIA_ANG_D | N32: 3 | P32: FanBase_Str_Inertia_Plate_Flange_IntMtrNotch_BtmFiller_XLoc | Q32: =IF(B8=1,Q31-(Q6-Q78),Q31) -> -52.0706
A33: FAN_B | B33: =VLOOKUP(B25,Fan_Data_Table,MATCH(FAN_B,Fan_Data_Column_Names,0),FALSE) -> 42.75 | D33: MTRBS_AM | E33: =VLOOKUP(MOTORFRAME,MotorBase_Table,MATCH(MTRBS_AM,MotorBase_Data_Column_Names,0),FALSE) -> 20.75 | G33: PLTS4_OS | H33: =IF(ISEVEN(H32),0,1) -> 1 | J33: DOA Internal Channel Data | M33: FanBase_Str_MIA_ANG_WT | N33: =N21 -> 0.375 | P33: FanBase_Str_Inertia_Plate_Flange_IntNotch_W | Q33: =K45+0.5 -> 2.42
A34: FAN_BAH | B34: =VLOOKUP(B25,Fan_Data_Table,MATCH(FAN_BAH,Fan_Data_Column_Names,0),FALSE) -> 2.5 | D34: MTRBS_AX | E34: =VLOOKUP(MOTORFRAME,MotorBase_Table,MATCH(MTRBS_AX,MotorBase_Data_Column_Names,0),FALSE) -> 2.5 | G34: PLTS4_SS | H34: =IF(ISODD(H32),0,1) -> 0 | J34: FanBase_Str_DOA_INT_MTR_CHAN_Coping_Suppresion | K34: =IF(AND(OR(B27=6,B27=8),B8=1,B9=2),1,IF(AND(OR(B27=6,B27=8),B8=2,B9=2),2,0)) -> 0 | M34: FanBase_Str_MIA_ANG_FTR | N34: =VLOOKUP(N29,Steel_List_Table,MATCH(STL_FTR,Steel_List_Column_Names,0),FALSE) -> 0.5 | P34: FanBase_Str_Inertia_Plate_X_Hole_XStart | Q34: 2.375
A35: FAN_BAW | B35: =VLOOKUP(B25,Fan_Data_Table,MATCH(FAN_BAW,Fan_Data_Column_Names,0),FALSE) -> 2.5 | D35: MTRBS_BB | E35: =VLOOKUP(MOTORFRAME,MotorBase_Table,MATCH(MTRBS_BB,MotorBase_Data_Column_Names,0),FALSE) -> 15.5 | G35: PLTS4_SW1 | H35: =VLOOKUP(H32,Isolator_Plate_Table,MATCH(PLT_SW1,Isolator_Plate_Column_Names,0),FALSE) -> 1.125 | J35: FanBase_Str_DOA_INT_MTR_CHAN_Suppresion | K35: =IF(K8=0,0,IF(OR(B9=1,FANSIZE>=402),1,0)) -> 1 | M35: FanBase_Str_MIA_ANG_LB | N35: =N30*(VLOOKUP(N29,Steel_List_Table,MATCH(STL_LBFT,Steel_List_Column_Names,0),FALSE)/12) -> 52.862917 | P35: FanBase_Str_Inertia_Plate_X_Hole_YLoc | Q35: =Q22/2 -> 0.875
A36: FAN_BAT | B36: =VLOOKUP(B25,Fan_Data_Table,MATCH(FAN_BAT,Fan_Data_Column_Names,0),FALSE) -> 0.25 | D36: MTRBS_BT | E36: =VLOOKUP(MOTORFRAME,MotorBase_Table,MATCH(MTRBS_BT,MotorBase_Data_Column_Names,0),FALSE) -> 5.25 | G36: PLTS4_SW2 | H36: =VLOOKUP(H32,Isolator_Plate_Table,MATCH(PLT_SW2,Isolator_Plate_Column_Names,0),FALSE) -> 4.875 | J36: FanBase_Str_DOA_INT_FAN_CHAN_Suppresion | K36: =IF(K8=0,0,IF(B9=1,1,0)) -> 1 | M36: FanBase_Str_MIA_ANG_HoleLoc_Plane | N36: =N32/2 -> 1.5 | P36: FanBase_Str_Inertia_Plate_X_Hole_BtmFiller_StartPlane | Q36: =IF(B8=1,Q54-Q78,0) -> 63.2106
A37: FAN_BH | B37: =VLOOKUP(B25,Fan_Data_Table,MATCH(FAN_BH,Fan_Data_Column_Names,0),FALSE) -> 0.56 | D37: MTRBS_E | E37: =VLOOKUP(MOTORFRAME,MotorBase_Table,MATCH(MTRBS_E,MotorBase_Data_Column_Names,0),FALSE) -> 6.25 | G37: PLTS4_SL1 | H37: =VLOOKUP(H32,Isolator_Plate_Table,MATCH(PLT_SL1,Isolator_Plate_Column_Names,0),FALSE) -> 3.8125 | J37: FanBase_Str_DOA_INT_MTR_CHAN_XLoc | K37: =IF(B8=1,E56-B17-E40+K5+K45-K50,B17-E56-E40+K5+K45-K50) -> 37.5446 | M37: FanBase_Str_MIA_ANG_ZLoc | N37: =IF(OR(B27=1,B27=2,B27=7,B27=8),B15+E58-E39,B15+E58+E39) -> 40.81 | P37: FanBase_Str_Inertia_Plate_X_Hole_Eng_Hole_Dia | Q37: ='Hole Sizes'!I11 -> 0.152
A38: FAN_BH_NOM | B38: =VLOOKUP(B25,Fan_Data_Table,MATCH(FAN_BH_NOM,Fan_Data_Column_Names,0),FALSE) -> 0.5 | D38: MTRBS_F | E38: =VLOOKUP(MOTORFRAME,MotorBase_Table,MATCH(MTRBS_F,MotorBase_Data_Column_Names,0),FALSE) -> 6 | G38: PLTS4_SL2 | H38: =VLOOKUP(H32,Isolator_Plate_Table,MATCH(PLT_SL2,Isolator_Plate_Column_Names,0),FALSE) -> 9.1875 | J38: FanBase_Str_DOA_INT_MTR_CHAN_ZLoc | K38: =IF(AND(B27=6,B9=2),K54-((K25-K17*2-B11*2-B32+K60)/2),IF(AND(B27=8,B9=2),K54+((K25-K17*2-B11*2-B32+K60)/2),IF(OR(B27=6,B27=8),H104-K93/2+K17-K106+K25/2,H104-K93/2+K106+K25/2))) -> 46.695 | M38: LIA Angle Data | P38: FanBase_Str_Inertia_Plate_X_Hole_Clr_Hole_Dia | Q38: ='Hole Sizes'!B7 -> 0.218
A39: FAN_DC | B39: =VLOOKUP(B25,Fan_Data_Table,MATCH(FAN_DC,Fan_Data_Column_Names,0),FALSE) -> 24.5 | D39: MTRBS_AO | E39: =VLOOKUP(MOTORFRAME,MotorBase_Table,MATCH(MTRBS_AO,MotorBase_Data_Column_Names,0),FALSE) -> 8 | J39: FanBase_Str_DOA_INT_FAN_CHAN_XLoc | K39: =B59 -> 22.75 | M39: FanBase_Str_LIA_ANG_Lookup | N39: =CONCATENATE("Angle",N41,N42,N43) -> Angle430.375 | P39: FanBase_Str_Inertia_Plate_X_Hole_Ind_Hole_Dia | Q39: =IF(Q18<=0.09,'Hole Sizes'!B35,IF(AND(Q18>0.09,Q18<0.14),'Hole Sizes'!B36,'Hole Sizes'!B37)) -> 0.125
A40: FAN_DD | B40: =VLOOKUP(B25,Fan_Data_Table,MATCH(FAN_DD,Fan_Data_Column_Names,0),FALSE) -> 30.25 | D40: MTRBS_AR | E40: =VLOOKUP(MOTORFRAME,MotorBase_Table,MATCH(MTRBS_AR,MotorBase_Data_Column_Names,0),FALSE) -> 9.25 | G40: Parameter | H40: Value | J40: FanBase_Str_DOA_INT_FAN_CHAN_ZLoc | K40: =K38 -> 46.695 | M40: FanBase_Str_LIA_ANG_L | N40: =N18 -> 74.63 | P40: FanBase_Str_Inertia_Plate_X_Hole1_PlateBeside_Btm_Suppresion | Q40: =IF(B8=1,0,1) -> 0
...

Sheet Fan Data
C2: Twin City BAE DWDI Fan Data (Horizontal Discharge) | AD2: Key Slot Dimensions | AG2: Isolator Location Dimensions | AL2: Wheel Data Dimensions | AP2: Bearing Data Dimensions | AV2: Class 1 & 2 fans | CH2: Class 3 fans
C3: FAN | D3: WH_DIA_Nominal | E3: MIN_T_FRAME | F3: MAX_T_FRAME | G3: FAN_A | H3: FAN_B | I3: FAN_BAH | J3: FAN_BAW | K3: FAN_BAT | L3: FAN_BH | M3: FAN_BH_NOM | N3: FAN_DC | O3: FAN_DD | P3: FAN_DE | Q3: FAN_DX | R3: FAN_G | S3: FAN_GA | T3: FAN_GB | U3: FAN_GC | V3: FAN_H | W3: FAN_HE | X3: FAN_HJ | Y3: FAN_HN | Z3: FAN_J | AA3: FAN_P | AB3: FAN_Q | AC3: FAN_SD | AD3: FAN_KSL | AE3: FAN_KSW | AF3: FAN_KSD | AG3: FAN_AH (DB Fans Only) | AH3: FAN_K | AI3: FAN_M | AJ3: FAN_N | AK3: FAN_ND | AL3: FAN_WOD | AM3: FAN_WID | AN3: FAN_WW | AO3: FAN_INLET_FLG_W | AP3: FAN_BRG_SUP_W | AQ3: FAN_BRG_SUP_T | AR3: FAN_BRG_DIA | AS3: FAN_BRG_W | AT3: FAN_BRG_H | AV3: FAN_MAX_T_FRAME_CL1 | AW3: FAN_MAX_T_FRAME_CL2 | AX3: FAN_A_CL1/CL2 | AY3: FAN_B_CL1/CL2 | AZ3: FAN_BAH_CL1/CL2 | BA3: FAN_BAW_CL1/CL2 | BB3: FAN_BAT_CL1/CL2 | BC3: FAN_BH_CL1/CL2 | BD3: FAN_DC_T_CL1/CL2 | BE3: FAN_DC_B_CL1/CL2 | BF3: FAN_DX_CL1/CL2 | BG3: FAN_G_CL1/CL2 | BH3: FAN_GA_CL1/CL2 | BI3: FAN_GB_CL1/CL2 | BJ3: FAN_GC_CL1/CL2 | BK3: FAN_H_CL1/CL2 | BL3: FAN_HE_CL1/CL2 | BM3: FAN_HJ_CL1/CL2 | BN3: FAN_HN_T_CL1/CL2 | BO3: FAN_HN_B_CL1/CL2 | BP3: FAN_J_CL1 | BQ3: FAN_J_CL2 | BR3: FAN_K_CL1/CL2 | BS3: FAN_KSL_CL1/CL2 | BT3: FAN_KSW_CL1 | BU3: FAN_KSW_CL2 | BV3: FAN_KSD_CL1 | BW3: FAN_KSD_CL2 | BX3: FAN_M_CL1/CL2 | BY3: FAN_N_CL1/CL2 | BZ3: FAN_P_CL1 | CA3: FAN_P_CL2 | CB3: FAN_Q_CL1/CL2 | CC3: FAN_SD_CL1 | CD3: FAN_SD_CL2 | CE3: FAN_BRG_SUP_W_CL1 | CF3: FAN_BRG_SUP_W_CL2 | CH3: FAN_MAX_T_FRAME_CL3 | CI3: FAN_A_CL3 | CJ3: FAN_B_CL3 | CK3: FAN_BAH_CL3 | CL3: FAN_BAW_CL3 | CM3: FAN_BAT_CL3 | CN3: FAN_BH_CL3 | CO3: FAN_DC_T_CL3 | CP3: FAN_DC_B_CL3 | CQ3: FAN_DX_CL3 | CR3: FAN_G_CL3 | CS3: FAN_GA_CL3 | CT3: FAN_GB_CL3 | CU3: FAN_GC_CL3 | CV3: FAN_H_CL3 | CW3: FAN_HE_CL3 | CX3: FAN_HJ_CL3 | CY3: FAN_HN_T_CL3 | CZ3: FAN_HN_B_CL3 | DA3: FAN_J_CL3 | DB3: FAN_K_CL3 | DC3: FAN_KSL_CL3 | DD3: FAN_KSW_CL3 | DE3: FAN_KSD_CL3 | DF3: FAN_M_CL3 | DG3: FAN_N_CL3 | DH3: FAN_P_CL3 | DI3: FAN_Q_CL3 | DJ3: FAN_SD_CL3 | DK3: FAN_BRG_SUP_W_CL3
B4: TYPE A | C4: 122H | D4: =LEFT(C4,3)/10 -> 12.2 | E4: 143T | F4: =IF(FANCLASS=1,AV4,IF(FANCLASS=2,AW4, IF(FANCLASS=3,CH4))) -> 254T | G4: =IF(OR(FANCLASS=1,FANCLASS=2),AX4, IF(FANCLASS=3,CI4)) -> 13 | H4: =IF(OR(FANCLASS=1,FANCLASS=2),AY4, IF(FANCLASS=3,CJ4)) -> 17.5 | I4: =IF(OR(FANCLASS=1,FANCLASS=2),AZ4, IF(FANCLASS=3,CK4)) -> 1.5 | J4: =IF(OR(FANCLASS=1,FANCLASS=2),BA4, IF(FANCLASS=3,CL4)) -> 1.5 | K4: =IF(OR(FANCLASS=1,FANCLASS=2),BB4, IF(FANCLASS=3,CM4)) -> 0.188 | L4: =IF(OR(FANCLASS=1,FANCLASS=2),BC4, IF(FANCLASS=3,CN4)) -> 0.44 | M4: 0.375 | N4: =IF(AND(OR(FANCLASS=1,FANCLASS=2),OR(FANDISCHARGELOC="F",FANDISCHARGELOC="R")),BD4, IF(AND(FANCLASS=3,OR(FANDISCHARGELOC="F",FANDISCHARGELOC="R")),CO4,IF(OR(FANCLASS=1,FANCLASS=2),BE4, IF(FANCLASS=3,CP4)))) -> 10.25 | O4: =IF(OR(FANDISCHARGELOC="F",FANDISCHARGELOC="R",FANDISCHARGELOC="T",FANDISCHARGELOC="TI"),Y4-1.5,IF(OR(FANDISCHARGELOC="B",FANDISCHARGELOC="BI",FANDISCHARGELOC="FI",FANDISCHARGELOC="RI"),Y4-((TAN(60*PI()/180))*(W4-R4/2))-3)) -> 11.44 | P4: =IF(OR(FANDISCHARGELOC="F",FANDISCHARGELOC="R"),O4-AL4/2+I4,IF(OR(FANDISCHARGELOC="FI",FANDISCHARGELOC="RI"),O4-(AR4+0.5),IF(OR(FANDISCHARGELOC="T",FANDISCHARGELOC="TI",FANDISCHARGELOC="B",FANDISCHARGELOC="BI"),O4-(AR4+2)))) -> 5.19 | Q4: =IF(OR(FANCLASS=1,FANCLASS=2),BF4, IF(FANCLASS=3,CQ4)) -> 1 | R4: =IF(OR(FANCLASS=1,FANCLASS=2),BG4, IF(FANCLASS=3,CR4)) -> 18.5 | S4: =IF(OR(FANCLASS=1,FANCLASS=2),BH4, IF(FANCLASS=3,CS4)) -> 0.07 | T4: =IF(OR(FANCLASS=1,FANCLASS=2),BI4, IF(FANCLASS=3,CT4)) -> 0.07 | U4: =IF(OR(FANCLASS=1,FANCLASS=2),BJ4, IF(FANCLASS=3,CU4)) -> 9.875 | V4: =IF(OR(FANCLASS=1,FANCLASS=2),BK4, IF(FANCLASS=3,CV4)) -> 20.5 | W4: =IF(OR(FANCLASS=1,FANCLASS=2),BL4, IF(FANCLASS=3,CW4)) -> 10.56 | X4: =IF(OR(FANCLASS=1,FANCLASS=2),BM4, IF(FANCLASS=3,CX4)) -> 9.25 | Y4: =IF(AND(OR(FANCLASS=1,FANCLASS=2),OR(FANDISCHARGELOC="F",FANDISCHARGELOC="R")),BN4, IF(AND(FANCLASS=3,OR(FANDISCHARGELOC="F",FANDISCHARGELOC="R")),CY4,IF(OR(FANCLASS=1,FANCLASS=2),BO4, IF(FANCLASS=3,CZ4)))) -> 12.94 | Z4: =IF(FANCLASS=1,BP4,IF(FANCLASS=2,BQ4, IF(FANCLASS=3,DA4))) -> 12.38 | AA4: =IF(FANCLASS=1,BZ4,IF(FANCLASS=2,CA4, IF(FANCLASS=3,DH4))) -> 16.25 | AB4: =IF(OR(FANCLASS=1,FANCLASS=2),CB4, IF(FANCLASS=3,DI4)) -> 6.44 | AC4: =IF(FANCLASS=1,CC4,IF(FANCLASS=2,CD4, IF(FANCLASS=3,DJ4))) -> 1.4375 | AD4: =IF(OR(FANCLASS=1,FANCLASS=2),BS4, IF(FANCLASS=3,DC4)) -> 3 | AE4: =IF(FANCLASS=1,BT4,IF(FANCLASS=2,BU4, IF(FANCLASS=3,DD4))) -> 0.38 | AF4: =IF(FANCLASS=1,BV4,IF(FANCLASS=2,BW4, IF(FANCLASS=3,DE4))) -> 0.19 | AG4: n/a | AH4: =IF(OR(FANCLASS=1,FANCLASS=2),BR4, IF(FANCLASS=3,DB4)) -> 9.63 | AI4: =IF(OR(FANCLASS=1,FANCLASS=2),BX4, IF(FANCLASS=3,DF4)) -> 6.75 | AJ4: =IF(OR(FANCLASS=1,FANCLASS=2),BY4, IF(FANCLASS=3,DG4)) -> 0.63 | AK4: =U4-AI4 -> 3.125 | AL4: =R4-I4*2 -> 15.5 | AM4: =D4*0.78 -> 9.516 | AN4: =H4*0.65 -> 11.375 | AO4: =1.25 -> 1.25 | AP4: =IF(FANCLASS=1,CE4,IF(FANCLASS=2,CF4, IF(FANCLASS=3,DK4))) -> 2.5 | AQ4: 0.375 | AR4: =AC4*1.5 -> 2.15625 | AS4: =AP4-0.5 -> 2 | AT4: =AR4+0.125 -> 2.28125 | AV4: 213T | AW4: 254T | AX4: 13 | AY4: =BK4-BA4*2 -> 17.5 | AZ4: 1.5 | BA4: 1.5 | BB4: 0.188 | BC4: 0.44 | BD4: 10.25 | BE4: 15 | BF4: 1 | BG4: 18.5 | BH4: 0.07 | BI4: 0.07 | BJ4: 9.875 | BK4: 20.5 | BL4: 10.56 | BM4: 9.25 | BN4: 12.94 | BO4: 9.31 | BP4: 11.44 | BQ4: 12.38 | BR4: 9.63 | BS4: 3 | BT4: 0.25 | BU4: 0.38 | BV4: 0.13 | BW4: 0.19 | BX4: 6.75 | BY4: 0.63 | BZ4: 15.25 | CA4: 16.25 | CB4: 6.44 | CC4: 1.1875 | CD4: 1.4375 | CE4: =BA4+1 -> 2.5 | CF4: =BA4+1 -> 2.5 | CH4: 254T | CI4: 13.13 | CJ4: =CV4-CL4*2 -> 17.63 | CK4: 1.5 | CL4: 2 | CM4: 0.188 | CN4: 0.44 | CO4: 10.25 | CP4: 15.5 | CQ4: 1.25 | CR4: 18.63 | CS4: 0.126 | CT4: 0.126 | CU4: 9.875 | CV4: 21.63 | CW4: 10.63 | CX4: 9.75 | CY4: =14.25-CQ4 -> 13 | CZ4: 9.38 | DA4: 12.56 | DB4: 9.94 | DC4: 3.5 | DD4: 0.5 | DE4: 0.25 | DF4: 6.5 | DG4: 0.88 | DH4: 17.06 | DI4: 6.44 | DJ4: 1.9375 | DK4: =CL4+1 -> 3
C5: 135H | D5: =LEFT(C5,3)/10 -> 13.5 | E5: 143T | F5: =IF(FANCLASS=1,AV5,IF(FANCLASS=2,AW5, IF(FANCLASS=3,CH5))) -> 254T | G5: =IF(OR(FANCLASS=1,FANCLASS=2),AX5, IF(FANCLASS=3,CI5)) -> 14.31 | H5: =IF(OR(FANCLASS=1,FANCLASS=2),AY5, IF(FANCLASS=3,CJ5)) -> 19.5 | I5: =IF(OR(FANCLASS=1,FANCLASS=2),AZ5, IF(FANCLASS=3,CK5)) -> 1.5 | J5: =IF(OR(FANCLASS=1,FANCLASS=2),BA5, IF(FANCLASS=3,CL5)) -> 1.5 | K5: =IF(OR(FANCLASS=1,FANCLASS=2),BB5, IF(FANCLASS=3,CM5)) -> 0.188 | L5: =IF(OR(FANCLASS=1,FANCLASS=2),BC5, IF(FANCLASS=3,CN5)) -> 0.44 | M5: 0.375 | N5: =IF(AND(OR(FANCLASS=1,FANCLASS=2),OR(FANDISCHARGELOC="F",FANDISCHARGELOC="R")),BD5, IF(AND(FANCLASS=3,OR(FANDISCHARGELOC="F",FANDISCHARGELOC="R")),CO5,IF(OR(FANCLASS=1,FANCLASS=2),BE5, IF(FANCLASS=3,CP5)))) -> 11.25 | O5: =IF(OR(FANDISCHARGELOC="F",FANDISCHARGELOC="R",FANDISCHARGELOC="T",FANDISCHARGELOC="TI"),Y5-1.5,IF(OR(FANDISCHARGELOC="B",FANDISCHARGELOC="BI",FANDISCHARGELOC="FI",FANDISCHARGELOC="RI"),Y5-((TAN(60*PI()/180))*(W5-R5/2))-3)) -> 12.75 | P5: =IF(OR(FANDISCHARGELOC="F",FANDISCHARGELOC="R"),O5-AL5/2+I5,IF(OR(FANDISCHARGELOC="FI",FANDISCHARGELOC="RI"),O5-(AR5+0.5),IF(OR(FANDISCHARGELOC="T",FANDISCHARGELOC="TI",FANDISCHARGELOC="B",FANDISCHARGELOC="BI"),O5-(AR5+2)))) -> 5.875 | Q5: =IF(OR(FANCLASS=1,FANCLASS=2),BF5, IF(FANCLASS=3,CQ5)) -> 1 | R5: =IF(OR(FANCLASS=1,FANCLASS=2),BG5, IF(FANCLASS=3,CR5)) -> 19.75 | S5: =IF(OR(FANCLASS=1,FANCLASS=2),BH5, IF(FANCLASS=3,CS5)) -> 0.07 | T5: =IF(OR(FANCLASS=1,FANCLASS=2),BI5, IF(FANCLASS=3,CT5)) -> 0.07 | U5: =IF(OR(FANCLASS=1,FANCLASS=2),BJ5, IF(FANCLASS=3,CU5)) -> 10.5 | V5: =IF(OR(FANCLASS=1,FANCLASS=2),BK5, IF(FANCLASS=3,CV5)) -> 22.5 | W5: =IF(OR(FANCLASS=1,FANCLASS=2),BL5, IF(FANCLASS=3,CW5)) -> 11.63 | X5: =IF(OR(FANCLASS=1,FANCLASS=2),BM5, IF(FANCLASS=3,CX5)) -> 10.25 | Y5: =IF(AND(OR(FANCLASS=1,FANCLASS=2),OR(FANDISCHARGELOC="F",FANDISCHARGELOC="R")),BN5, IF(AND(FANCLASS=3,OR(FANDISCHARGELOC="F",FANDISCHARGELOC="R")),CY5,IF(OR(FANCLASS=1,FANCLASS=2),BO5, IF(FANCLASS=3,CZ5)))) -> 14.25 | Z5: =IF(FANCLASS=1,BP5,IF(FANCLASS=2,BQ5, IF(FANCLASS=3,DA5))) -> 13.38 | AA5: =IF(FANCLASS=1,BZ5,IF(FANCLASS=2,CA5, IF(FANCLASS=3,DH5))) -> 17.25 | AB5: =IF(OR(FANCLASS=1,FANCLASS=2),CB5, IF(FANCLASS=3,DI5)) -> 7.13 | AC5: =IF(FANCLASS=1,CC5,IF(FANCLASS=2,CD5, IF(FANCLASS=3,DJ5))) -> 1.6875 | AD5: =IF(OR(FANCLASS=1,FANCLASS=2),BS5, IF(FANCLASS=3,DC5)) -> 3 | AE5: =IF(FANCLASS=1,BT5,IF(FANCLASS=2,BU5, IF(FANCLASS=3,DD5))) -> 3.8 | AF5: =IF(FANCLASS=1,BV5,IF(FANCLASS=2,BW5, IF(FANCLASS=3,DE5))) -> 0.19 | AG5: n/a | AH5: =IF(OR(FANCLASS=1,FANCLASS=2),BR5, IF(FANCLASS=3,DB5)) -> 10.63 | AI5: =IF(OR(FANCLASS=1,FANCLASS=2),BX5, IF(FANCLASS=3,DF5)) -> 7.38 | AJ5: =IF(OR(FANCLASS=1,FANCLASS=2),BY5, IF(FANCLASS=3,DG5)) -> 0.63 | AK5: =U5-AI5 -> 3.12 | AL5: =R5-I5*2 -> 16.75 | AM5: =D5*0.78 -> 10.53 | AN5: =H5*0.65 -> 12.675 | AO5: 1.25 | AP5: =IF(FANCLASS=1,CE5,IF(FANCLASS=2,CF5, IF(FANCLASS=3,DK5))) -> 2.5 | AQ5: 0.375 | AR5: =AC5*1.5 -> 2.53125 | AS5: =AP5-0.5 -> 2 | AT5: =AR5+0.125 -> 2.65625 | AV5: 213T | AW5: 254T | AX5: 14.31 | AY5: =BK5-BA5*2 -> 19.5 | AZ5: 1.5 | BA5: 1.5 | BB5: 0.188 | BC5: 0.44 | BD5: 11.25 | BE5: 16.25 | BF5: 1 | BG5: 19.75 | BH5: 0.07 | BI5: 0.07 | BJ5: 10.5 | BK5: 22.5 | BL5: 11.63 | BM5: 10.25 | BN5: 14.25 | BO5: 10.25 | BP5: 12.44 | BQ5: 13.38 | BR5: 10.63 | BS5: 3 | BT5: 0.25 | BU5: 3.8 | BV5: 0.13 | BW5: 0.19 | BX5: 7.38 | BY5: 0.63 | BZ5: 16.25 | CA5: 17.25 | CB5: 7.13 | CC5: 1.1875 | CD5: 1.6875 | CE5: =BA5+1 -> 2.5 | CF5: =BA5+1 -> 2.5 | CH5: 254T | CI5: 14.44 | CJ5: =CV5-CL5*2 -> 19.63 | CK5: 1.5 | CL5: 2 | CM5: 0.188 | CN5: 0.44 | CO5: 11.25 | CP5: 16.75 | CQ5: 1.25 | CR5: 19.88 | CS5: 0.126 | CT5: 0.126 | CU5: 10.5 | CV5: 23.63 | CW5: 11.69 | CX5: 10.75 | CY5: =15.56-CQ5 -> 14.31 | CZ5: 10.31 | DA5: 13.56 | DB5: 10.94 | DC5: 4 | DD5: 0.5 | DE5: 0.25 | DF5: 7.13 | DG5: 0.88 | DH5: 18.56 | DI5: 7.13 | DJ5: 1.9375 | DK5: =CL5+1 -> 3
C6: 150H | D6: =LEFT(C6,3)/10 -> 15 | E6: 143T | F6: =IF(FANCLASS=1,AV6,IF(FANCLASS=2,AW6, IF(FANCLASS=3,CH6))) -> 256T | G6: =IF(OR(FANCLASS=1,FANCLASS=2),AX6, IF(FANCLASS=3,CI6)) -> 15.88 | H6: =IF(OR(FANCLASS=1,FANCLASS=2),AY6, IF(FANCLASS=3,CJ6)) -> 21.5 | I6: =IF(OR(FANCLASS=1,FANCLASS=2),AZ6, IF(FANCLASS=3,CK6)) -> 1.5 | J6: =IF(OR(FANCLASS=1,FANCLASS=2),BA6, IF(FANCLASS=3,CL6)) -> 1.5 | K6: =IF(OR(FANCLASS=1,FANCLASS=2),BB6, IF(FANCLASS=3,CM6)) -> 0.188 | L6: =IF(OR(FANCLASS=1,FANCLASS=2),BC6, IF(FANCLASS=3,CN6)) -> 0.44 | M6: 0.375 | N6: =IF(AND(OR(FANCLASS=1,FANCLASS=2),OR(FANDISCHARGELOC="F",FANDISCHARGELOC="R")),BD6, IF(AND(FANCLASS=3,OR(FANDISCHARGELOC="F",FANDISCHARGELOC="R")),CO6,IF(OR(FANCLASS=1,FANCLASS=2),BE6, IF(FANCLASS=3,CP6)))) -> 12.25 | O6: =IF(OR(FANDISCHARGELOC="F",FANDISCHARGELOC="R",FANDISCHARGELOC="T",FANDISCHARGELOC="TI"),Y6-1.5,IF(OR(FANDISCHARGELOC="B",FANDISCHARGELOC="BI",FANDISCHARGELOC="FI",FANDISCHARGELOC="RI"),Y6-((TAN(60*PI()/180))*(W6-R6/2))-3)) -> 14.31 | P6: =IF(OR(FANDISCHARGELOC="F",FANDISCHARGELOC="R"),O6-AL6/2+I6,IF(OR(FANDISCHARGELOC="FI",FANDISCHARGELOC="RI"),O6-(AR6+0.5),IF(OR(FANDISCHARGELOC="T",FANDISCHARGELOC="TI",FANDISCHARGELOC="B",FANDISCHARGELOC="BI"),O6-(AR6+2)))) -> 6.56 | Q6: =IF(OR(FANCLASS=1,FANCLASS=2),BF6, IF(FANCLASS=3,CQ6)) -> 1 | R6: =IF(OR(FANCLASS=1,FANCLASS=2),BG6, IF(FANCLASS=3,CR6)) -> 21.5 | S6: =IF(OR(FANCLASS=1,FANCLASS=2),BH6, IF(FANCLASS=3,CS6)) -> 0.07 | T6: =IF(OR(FANCLASS=1,FANCLASS=2),BI6, IF(FANCLASS=3,CT6)) -> 0.07 | U6: =IF(OR(FANCLASS=1,FANCLASS=2),BJ6, IF(FANCLASS=3,CU6)) -> 11.375 | V6: =IF(OR(FANCLASS=1,FANCLASS=2),BK6, IF(FANCLASS=3,CV6)) -> 24.5 | W6: =IF(OR(FANCLASS=1,FANCLASS=2),BL6, IF(FANCLASS=3,CW6)) -> 12.88 | X6: =IF(OR(FANCLASS=1,FANCLASS=2),BM6, IF(FANCLASS=3,CX6)) -> 11.44 | Y6: =IF(AND(OR(FANCLASS=1,FANCLASS=2),OR(FANDISCHARGELOC="F",FANDISCHARGELOC="R")),BN6, IF(AND(FANCLASS=3,OR(FANDISCHARGELOC="F",FANDISCHARGELOC="R")),CY6,IF(OR(FANCLASS=1,FANCLASS=2),BO6, IF(FANCLASS=3,CZ6)))) -> 15.81 | Z6: =IF(FANCLASS=1,BP6,IF(FANCLASS=2,BQ6, IF(FANCLASS=3,DA6))) -> 14.38 | AA6: =IF(FANCLASS=1,BZ6,IF(FANCLASS=2,CA6, IF(FANCLASS=3,DH6))) -> 18.75 | AB6: =IF(OR(FANCLASS=1,FANCLASS=2),CB6, IF(FANCLASS=3,DI6)) -> 7.88 | AC6: =IF(FANCLASS=1,CC6,IF(FANCLASS=2,CD6, IF(FANCLASS=3,DJ6))) -> 1.6875 | AD6: =IF(OR(FANCLASS=1,FANCLASS=2),BS6, IF(FANCLASS=3,DC6)) -> 3.5 | AE6: =IF(FANCLASS=1,BT6,IF(FANCLASS=2,BU6, IF(FANCLASS=3,DD6))) -> 0.38 | AF6: =IF(FANCLASS=1,BV6,IF(FANCLASS=2,BW6, IF(FANCLASS=3,DE6))) -> 0.19 | AG6: n/a | AH6: =IF(OR(FANCLASS=1,FANCLASS=2),BR6, IF(FANCLASS=3,DB6)) -> 11.63 | AI6: =IF(OR(FANCLASS=1,FANCLASS=2),BX6, IF(FANCLASS=3,DF6)) -> 8.25 | AJ6: =IF(OR(FANCLASS=1,FANCLASS=2),BY6, IF(FANCLASS=3,DG6)) -> 0.63 | AK6: =U6-AI6 -> 3.125 | AL6: =R6-I6*2 -> 18.5 | AM6: =D6*0.78 -> 11.7 | AN6: =H6*0.65 -> 13.975 | AO6: 1.25 | AP6: =IF(FANCLASS=1,CE6,IF(FANCLASS=2,CF6, IF(FANCLASS=3,DK6))) -> 2.5 | AQ6: 0.375 | AR6: =AC6*1.5 -> 2.53125 | AS6: =AP6-0.5 -> 2 | AT6: =AR6+0.125 -> 2.65625 | AV6: 215T | AW6: 256T | AX6: 15.88 | AY6: =BK6-BA6*2 -> 21.5 | AZ6: 1.5 | BA6: 1.5 | BB6: 0.188 | BC6: 0.44 | BD6: 12.25 | BE6: 18 | BF6: 1 | BG6: 21.5 | BH6: 0.07 | BI6: 0.07 | BJ6: 11.375 | BK6: 24.5 | BL6: 12.88 | BM6: 11.44 | BN6: 15.81 | BO6: 11.38 | BP6: 14.38 | BQ6: 14.38 | BR6: 11.63 | BS6: 3.5 | BT6: 0.38 | BU6: 0.38 | BV6: 0.19 | BW6: 0.19 | BX6: 8.25 | BY6: 0.63 | BZ6: 18.75 | CA6: 18.75 | CB6: 7.88 | CC6: 1.4375 | CD6: 1.6875 | CE6: =BA6+1 -> 2.5 | CF6: =BA6+1 -> 2.5 | CH6: 256T | CI6: 16 | CJ6: =CV6-CL6*2 -> 21.63 | CK6: 1.5 | CL6: 2 | CM6: 0.188 | CN6: 0.44 | CO6: 12.25 | CP6: 18.5 | CQ6: 1.25 | CR6: 21.63 | CS6: 0.126 | CT6: 0.126 | CU6: 11.375 | CV6: 25.63 | CW6: 12.94 | CX6: 11.94 | CY6: =17.13-CQ6 -> 15.88 | CZ6: 11.44 | DA6: 15.13 | DB6: 11.94 | DC6: 4 | DD6: 0.5 | DE6: 0.25 | DF6: 8 | DG6: 0.88 | DH6: 20.13 | DI6: 7.88 | DJ6: 2.1875 | DK6: =CL6+1.5 -> 3.5
C7: 165H | D7: =LEFT(C7,3)/10 -> 16.5 | E7: 143T | F7: =IF(FANCLASS=1,AV7,IF(FANCLASS=2,AW7, IF(FANCLASS=3,CH7))) -> 256T | G7: =IF(OR(FANCLASS=1,FANCLASS=2),AX7, IF(FANCLASS=3,CI7)) -> 17.44 | H7: =IF(OR(FANCLASS=1,FANCLASS=2),AY7, IF(FANCLASS=3,CJ7)) -> 23.625 | I7: =IF(OR(FANCLASS=1,FANCLASS=2),AZ7, IF(FANCLASS=3,CK7)) -> 1.5 | J7: =IF(OR(FANCLASS=1,FANCLASS=2),BA7, IF(FANCLASS=3,CL7)) -> 2 | K7: =IF(OR(FANCLASS=1,FANCLASS=2),BB7, IF(FANCLASS=3,CM7)) -> 0.188 | L7: =IF(OR(FANCLASS=1,FANCLASS=2),BC7, IF(FANCLASS=3,CN7)) -> 0.44 | M7: 0.375 | N7: =IF(AND(OR(FANCLASS=1,FANCLASS=2),OR(FANDISCHARGELOC="F",FANDISCHARGELOC="R")),BD7, IF(AND(FANCLASS=3,OR(FANDISCHARGELOC="F",FANDISCHARGELOC="R")),CO7,IF(OR(FANCLASS=1,FANCLASS=2),BE7, IF(FANCLASS=3,CP7)))) -> 13.5 | O7: =IF(OR(FANDISCHARGELOC="F",FANDISCHARGELOC="R",FANDISCHARGELOC="T",FANDISCHARGELOC="TI"),Y7-1.5,IF(OR(FANDISCHARGELOC="B",FANDISCHARGELOC="BI",FANDISCHARGELOC="FI",FANDISCHARGELOC="RI"),Y7-((TAN(60*PI()/180))*(W7-R7/2))-3)) -> 15.88 | P7: =IF(OR(FANDISCHARGELOC="F",FANDISCHARGELOC="R"),O7-AL7/2+I7,IF(OR(FANDISCHARGELOC="FI",FANDISCHARGELOC="RI"),O7-(AR7+0.5),IF(OR(FANDISCHARGELOC="T",FANDISCHARGELOC="TI",FANDISCHARGELOC="B",FANDISCHARGELOC="BI"),O7-(AR7+2)))) -> 6.755 | Q7: =IF(OR(FANCLASS=1,FANCLASS=2),BF7, IF(FANCLASS=3,CQ7)) -> 1 | R7: =IF(OR(FANCLASS=1,FANCLASS=2),BG7, IF(FANCLASS=3,CR7)) -> 24.25 | S7: =IF(OR(FANCLASS=1,FANCLASS=2),BH7, IF(FANCLASS=3,CS7)) -> 0.07 | T7: =IF(OR(FANCLASS=1,FANCLASS=2),BI7, IF(FANCLASS=3,CT7)) -> 0.07 | U7: =IF(OR(FANCLASS=1,FANCLASS=2),BJ7, IF(FANCLASS=3,CU7)) -> 12.125 | V7: =IF(OR(FANCLASS=1,FANCLASS=2),BK7, IF(FANCLASS=3,CV7)) -> 27.625 | W7: =IF(OR(FANCLASS=1,FANCLASS=2),BL7, IF(FANCLASS=3,CW7)) -> 14.13 | X7: =IF(OR(FANCLASS=1,FANCLASS=2),BM7, IF(FANCLASS=3,CX7)) -> 12.63 | Y7: =IF(AND(OR(FANCLASS=1,FANCLASS=2),OR(FANDISCHARGELOC="F",FANDISCHARGELOC="R")),BN7, IF(AND(FANCLASS=3,OR(FANDISCHARGELOC="F",FANDISCHARGELOC="R")),CY7,IF(OR(FANCLASS=1,FANCLASS=2),BO7, IF(FANCLASS=3,CZ7)))) -> 17.38 | Z7: =IF(FANCLASS=1,BP7,IF(FANCLASS=2,BQ7, IF(FANCLASS=3,DA7))) -> 15.56 | AA7: =IF(FANCLASS=1,BZ7,IF(FANCLASS=2,CA7, IF(FANCLASS=3,DH7))) -> 20.06 | AB7: =IF(OR(FANCLASS=1,FANCLASS=2),CB7, IF(FANCLASS=3,DI7)) -> 8.69 | AC7: =IF(FANCLASS=1,CC7,IF(FANCLASS=2,CD7, IF(FANCLASS=3,DJ7))) -> 1.9375 | AD7: =IF(OR(FANCLASS=1,FANCLASS=2),BS7, IF(FANCLASS=3,DC7)) -> 3.5 | AE7: =IF(FANCLASS=1,BT7,IF(FANCLASS=2,BU7, IF(FANCLASS=3,DD7))) -> 0.5 | AF7: =IF(FANCLASS=1,BV7,IF(FANCLASS=2,BW7, IF(FANCLASS=3,DE7))) -> 0.25 | AG7: n/a | AH7: =IF(OR(FANCLASS=1,FANCLASS=2),BR7, IF(FANCLASS=3,DB7)) -> 12.94 | AI7: =IF(OR(FANCLASS=1,FANCLASS=2),BX7, IF(FANCLASS=3,DF7)) -> 8.75 | AJ7: =IF(OR(FANCLASS=1,FANCLASS=2),BY7, IF(FANCLASS=3,DG7)) -> 0.88 | AK7: =U7-AI7 -> 3.375 | AL7: =R7-I7*2 -> 21.25 | AM7: =D7*0.78 -> 12.87 | AN7: =H7*0.65 -> 15.35625 | AO7: 1.25 | AP7: =IF(FANCLASS=1,CE7,IF(FANCLASS=2,CF7, IF(FANCLASS=3,DK7))) -> 3 | AQ7: 0.375 | AR7: =AC7*1.5 -> 2.90625 | AS7: =AP7-0.5 -> 2.5 | AT7: =AR7+0.125 -> 3.03125 | AV7: 215T | AW7: 256T | AX7: 17.44 | AY7: =BK7-BA7*2 -> 23.625 | AZ7: 1.5 | BA7: 2 | BB7: 0.188 | BC7: 0.44 | BD7: 13.5 | BE7: 19.5 | BF7: 1 | BG7: 24.25 | BH7: 0.07 | BI7: 0.07 | BJ7: =BG7/2 -> 12.125 | BK7: 27.625 | BL7: 14.13 | BM7: 12.63 | BN7: 17.38 | BO7: 12.5 | BP7: 15.44 | BQ7: 15.56 | BR7: 12.94 | BS7: 3.5 | BT7: 0.38 | BU7: 0.5 | BV7: 0.19 | BW7: 0.25 | BX7: 8.75 | BY7: 0.88 | BZ7: 19.81 | CA7: 20.06 | CB7: 8.69 | CC7: 1.4375 | CD7: 1.9375 | CE7: =BA7+0.5 -> 2.5 | CF7: =BA7+1 -> 3 | CH7: 256T | CI7: 17.56 | CJ7: =CV7-CL7*2 -> 23.75 | CK7: 1.5 | CL7: 2 | CM7: 0.188 | CN7: 0.44 | CO7: 13.5 | CP7: 19.5 | CQ7: 1.25 | CR7: 23.13 | CS7: 0.126 | CT7: 0.126 | CU7: 12.125 | CV7: 27.75 | CW7: 14.19 | CX7: 13.13 | CY7: =18.69-CQ7 -> 17.44 | CZ7: 12.56 | DA7: 16.19 | DB7: 13 | DC7: 4.5 | DD7: 0.5 | DE7: 0.25 | DF7: 8.75 | DG7: 0.88 | DH7: 21.69 | DI7: 8.69 | DJ7: 2.1875 | DK7: =CL7+1.5 -> 3.5
C8: 182H | D8: =LEFT(C8,3)/10 -> 18.2 | E8: 145T | F8: =IF(FANCLASS=1,AV8,IF(FANCLASS=2,AW8, IF(FANCLASS=3,CH8))) -> 286T | G8: =IF(OR(FANCLASS=1,FANCLASS=2),AX8, IF(FANCLASS=3,CI8)) -> 19.38 | H8: =IF(OR(FANCLASS=1,FANCLASS=2),AY8, IF(FANCLASS=3,CJ8)) -> 26 | I8: =IF(OR(FANCLASS=1,FANCLASS=2),AZ8, IF(FANCLASS=3,CK8)) -> 1.5 | J8: =IF(OR(FANCLASS=1,FANCLASS=2),BA8, IF(FANCLASS=3,CL8)) -> 2 | K8: =IF(OR(FANCLASS=1,FANCLASS=2),BB8, IF(FANCLASS=3,CM8)) -> 0.188 | L8: =IF(OR(FANCLASS=1,FANCLASS=2),BC8, IF(FANCLASS=3,CN8)) -> 0.44 | M8: 0.375 | N8: =IF(AND(OR(FANCLASS=1,FANCLASS=2),OR(FANDISCHARGELOC="F",FANDISCHARGELOC="R")),BD8, IF(AND(FANCLASS=3,OR(FANDISCHARGELOC="F",FANDISCHARGELOC="R")),CO8,IF(OR(FANCLASS=1,FANCLASS=2),BE8, IF(FANCLASS=3,CP8)))) -> 14.75 | O8: =IF(OR(FANDISCHARGELOC="F",FANDISCHARGELOC="R",FANDISCHARGELOC="T",FANDISCHARGELOC="TI"),Y8-1.5,IF(OR(FANDISCHARGELOC="B",FANDISCHARGELOC="BI",FANDISCHARGELOC="FI",FANDISCHARGELOC="RI"),Y8-((TAN(60*PI()/180))*(W8-R8/2))-3)) -> 17.81 | P8: =IF(OR(FANDISCHARGELOC="F",FANDISCHARGELOC="R"),O8-AL8/2+I8,IF(OR(FANDISCHARGELOC="FI",FANDISCHARGELOC="RI"),O8-(AR8+0.5),IF(OR(FANDISCHARGELOC="T",FANDISCHARGELOC="TI",FANDISCHARGELOC="B",FANDISCHARGELOC="BI"),O8-(AR8+2)))) -> 7.81 | Q8: =IF(OR(FANCLASS=1,FANCLASS=2),BF8, IF(FANCLASS=3,CQ8)) -> 1.25 | R8: =IF(OR(FANCLASS=1,FANCLASS=2),BG8, IF(FANCLASS=3,CR8)) -> 26 | S8: =IF(OR(FANCLASS=1,FANCLASS=2),BH8, IF(FANCLASS=3,CS8)) -> 0.097 | T8: =IF(OR(FANCLASS=1,FANCLASS=2),BI8, IF(FANCLASS=3,CT8)) -> 0.07 | U8: =IF(OR(FANCLASS=1,FANCLASS=2),BJ8, IF(FANCLASS=3,CU8)) -> 13 | V8: =IF(OR(FANCLASS=1,FANCLASS=2),BK8, IF(FANCLASS=3,CV8)) -> 30 | W8: =IF(OR(FANCLASS=1,FANCLASS=2),BL8, IF(FANCLASS=3,CW8)) -> 15.69 | X8: =IF(OR(FANCLASS=1,FANCLASS=2),BM8, IF(FANCLASS=3,CX8)) -> 14 | Y8: =IF(AND(OR(FANCLASS=1,FANCLASS=2),OR(FANDISCHARGELOC="F",FANDISCHARGELOC="R")),BN8, IF(AND(FANCLASS=3,OR(FANDISCHARGELOC="F",FANDISCHARGELOC="R")),CY8,IF(OR(FANCLASS=1,FANCLASS=2),BO8, IF(FANCLASS=3,CZ8)))) -> 19.31 | Z8: =IF(FANCLASS=1,BP8,IF(FANCLASS=2,BQ8, IF(FANCLASS=3,DA8))) -> 16.75 | AA8: =IF(FANCLASS=1,BZ8,IF(FANCLASS=2,CA8, IF(FANCLASS=3,DH8))) -> 21.75 | AB8: =IF(OR(FANCLASS=1,FANCLASS=2),CB8, IF(FANCLASS=3,DI8)) -> 9.63 | AC8: =IF(FANCLASS=1,CC8,IF(FANCLASS=2,CD8, IF(FANCLASS=3,DJ8))) -> 1.9375 | AD8: =IF(OR(FANCLASS=1,FANCLASS=2),BS8, IF(FANCLASS=3,DC8)) -> 4 | AE8: =IF(FANCLASS=1,BT8,IF(FANCLASS=2,BU8, IF(FANCLASS=3,DD8))) -> 0.5 | AF8: =IF(FANCLASS=1,BV8,IF(FANCLASS=2,BW8, IF(FANCLASS=3,DE8))) -> 0.25 | AG8: n/a | AH8: =IF(OR(FANCLASS=1,FANCLASS=2),BR8, IF(FANCLASS=3,DB8)) -> 14.13 | AI8: =IF(OR(FANCLASS=1,FANCLASS=2),BX8, IF(FANCLASS=3,DF8)) -> 9.63 | AJ8: =IF(OR(FANCLASS=1,FANCLASS=2),BY8, IF(FANCLASS=3,DG8)) -> 0.88 | AK8: =U8-AI8 -> 3.37 | AL8: =R8-I8*2 -> 23 | AM8: =D8*0.78 -> 14.196 | AN8: =H8*0.65 -> 16.9 | AO8: 1.25 | AP8: =IF(FANCLASS=1,CE8,IF(FANCLASS=2,CF8, IF(FANCLASS=3,DK8))) -> 3 | AQ8: 0.375 | AR8: =AC8*1.5 -> 2.90625 | AS8: =AP8-0.5 -> 2.5 | AT8: =AR8+0.125 -> 3.03125 | AV8: 254T | AW8: 286T | AX8: 19.38 | AY8: =BK8-BA8*2 -> 26 | AZ8: 1.5 | BA8: 2 | BB8: 0.188 | BC8: 0.44 | BD8: 14.75 | BE8: 21.5 | BF8: 1.25 | BG8: 26 | BH8: 0.097 | BI8: 0.07 | BJ8: =BG8/2 -> 13 | BK8: 30 | BL8: 15.69 | BM8: 14 | BN8: 19.31 | BO8: 13.81 | BP8: 16.63 | BQ8: 16.75 | BR8: 14.13 | BS8: 4 | BT8: 0.38 | BU8: 0.5 | BV8: 0.19 | BW8: 0.25 | BX8: 9.63 | BY8: 0.88 | BZ8: 21.5 | CA8: 21.75 | CB8: 9.63 | CC8: 1.6875 | CD8: 1.9375 | CE8: =BA8+0.5 -> 2.5 | CF8: =BA8+1 -> 3 | CH8: 284T | CI8: 19.5 | CJ8: =CV8-CL8*2 -> 26.13 | CK8: 2 | CL8: 2 | CM8: 0.25 | CN8: 0.56 | CO8: 14.75 | CP8: 22 | CQ8: 1.25 | CR8: 27 | CS8: 0.126 | CT8: 0.126 | CU8: =CR8/2 -> 13.5 | CV8: 30.13 | CW8: 15.75 | CX8: 14.5 | CY8: =20.63-CQ8 -> 19.38 | CZ8: 13.88 | DA8: 17.38 | DB8: 14.19 | DC8: 4.5 | DD8: 0.5 | DE8: 0.25 | DF8: 9.63 | DG8: 0.88 | DH8: 22.88 | DI8: 9.63 | DJ8: 2.1875 | DK8: =CL8+1.5 -> 3.5
