Workbook
Name BTM_Seam: Data!$B$7
Name Construction: Data!$B$9
Name Corner_Brace_GAO: Data!$B$13
Name Corner_Brace_Thk: Data!$H$4
Name Corner_BraceO: Data!$B$12
Name FLOOR_CHAN_1_X_ARRAY_OFFSET: 'Channel Loc'!$D$6
Name FLOOR_CHAN_1_X_ARRAY_QTY: 'Channel Loc'!$E$6
Name FLOOR_CHAN_1_X_ARRAY_SPACING: 'Channel Loc'!$F$6
Name FLOOR_CHAN_1_Z_LOC: 'Channel Loc'!$C$6
Name FLOOR_CHAN_10_X_ARRAY_OFFSET: 'Channel Loc'!$D$15
Name FLOOR_CHAN_10_X_ARRAY_QTY: 'Channel Loc'!$E$15
Name FLOOR_CHAN_10_X_ARRAY_SPACING: 'Channel Loc'!$F$15
Name FLOOR_CHAN_10_Z_LOC: 'Channel Loc'!$C$15
Name FLOOR_CHAN_11_X_ARRAY_OFFSET: 'Channel Loc'!$D$16
Name FLOOR_CHAN_11_X_ARRAY_QTY: 'Channel Loc'!$E$16
Name FLOOR_CHAN_11_X_ARRAY_SPACING: 'Channel Loc'!$F$16
Name FLOOR_CHAN_11_Z_LOC: 'Channel Loc'!$C$16
Name FLOOR_CHAN_12_X_ARRAY_OFFSET: 'Channel Loc'!$D$17
Name FLOOR_CHAN_12_X_ARRAY_QTY: 'Channel Loc'!$E$17
Name FLOOR_CHAN_12_X_ARRAY_SPACING: 'Channel Loc'!$F$17
Name FLOOR_CHAN_12_Z_LOC: 'Channel Loc'!$C$17
Name FLOOR_CHAN_13_X_ARRAY_OFFSET: 'Channel Loc'!$D$18
Name FLOOR_CHAN_13_X_ARRAY_QTY: 'Channel Loc'!$E$18
Name FLOOR_CHAN_13_X_ARRAY_SPACING: 'Channel Loc'!$F$18
Name FLOOR_CHAN_13_Z_LOC: 'Channel Loc'!$C$18
Name FLOOR_CHAN_14_X_ARRAY_OFFSET: 'Channel Loc'!$D$19
Name FLOOR_CHAN_14_X_ARRAY_QTY: 'Channel Loc'!$E$19
Name FLOOR_CHAN_14_X_ARRAY_SPACING: 'Channel Loc'!$F$19
Name FLOOR_CHAN_14_Z_LOC: 'Channel Loc'!$C$19
Name FLOOR_CHAN_15_X_ARRAY_OFFSET: 'Channel Loc'!$D$20
Name FLOOR_CHAN_15_X_ARRAY_QTY: 'Channel Loc'!$E$20
Name FLOOR_CHAN_15_X_ARRAY_SPACING: 'Channel Loc'!$F$20
Name FLOOR_CHAN_15_Z_LOC: 'Channel Loc'!$C$20
Name FLOOR_CHAN_16_X_ARRAY_OFFSET: 'Channel Loc'!$D$21
Name FLOOR_CHAN_16_X_ARRAY_QTY: 'Channel Loc'!$E$21
Name FLOOR_CHAN_16_X_ARRAY_SPACING: 'Channel Loc'!$F$21
Name FLOOR_CHAN_16_Z_LOC: 'Channel Loc'!$C$21
Name FLOOR_CHAN_17_X_ARRAY_OFFSET: 'Channel Loc'!$D$22
Name FLOOR_CHAN_17_X_ARRAY_QTY: 'Channel Loc'!$E$22
Name FLOOR_CHAN_17_X_ARRAY_SPACING: 'Channel Loc'!$F$22
Name FLOOR_CHAN_17_Z_LOC: 'Channel Loc'!$C$22
Name FLOOR_CHAN_18_X_ARRAY_OFFSET: 'Channel Loc'!$D$23
Name FLOOR_CHAN_18_X_ARRAY_QTY: 'Channel Loc'!$E$23
Name FLOOR_CHAN_18_X_ARRAY_SPACING: 'Channel Loc'!$F$23
Name FLOOR_CHAN_18_Z_LOC: 'Channel Loc'!$C$23
Name FLOOR_CHAN_19_X_ARRAY_OFFSET: 'Channel Loc'!$D$24
Name FLOOR_CHAN_19_X_ARRAY_QTY: 'Channel Loc'!$E$24
Name FLOOR_CHAN_19_X_ARRAY_SPACING: 'Channel Loc'!$F$24
Name FLOOR_CHAN_19_Z_LOC: 'Channel Loc'!$C$24
Name FLOOR_CHAN_2_X_ARRAY_OFFSET: 'Channel Loc'!$D$7
Name FLOOR_CHAN_2_X_ARRAY_QTY: 'Channel Loc'!$E$7
Name FLOOR_CHAN_2_X_ARRAY_SPACING: 'Channel Loc'!$F$7
Name FLOOR_CHAN_2_Z_LOC: 'Channel Loc'!$C$7
Name FLOOR_CHAN_20_X_ARRAY_OFFSET: 'Channel Loc'!$D$25
Name FLOOR_CHAN_20_X_ARRAY_QTY: 'Channel Loc'!$E$25
Name FLOOR_CHAN_20_X_ARRAY_SPACING: 'Channel Loc'!$F$25
Name FLOOR_CHAN_20_Z_LOC: 'Channel Loc'!$C$25
Name FLOOR_CHAN_21_X_ARRAY_OFFSET: 'Channel Loc'!$D$26
Name FLOOR_CHAN_21_X_ARRAY_QTY: 'Channel Loc'!$E$26
Name FLOOR_CHAN_21_X_ARRAY_SPACING: 'Channel Loc'!$F$26

Sheet Sheet1
A1: Parameter | B1: Value | C1: UM | D1: Comments
A2: IH | B2: =Tunnel_H -> 90 | C2: in
A3: IW | B3: =Tunnel_W -> 90 | C3: in
A4: Corner_Brace_Thk | B4: =Corner_Brace_Thk -> 0.09701 | C4: in
A5: Reconnect_Thk | B5: =Reconnect_Thk -> 0.09701 | C5: in
A6: Stiffener_Thk | B6: =Stiffener_Thk -> 0.09701 | C6: in
A7: Clearance | B7: ='Excel Calcs'!B19 -> 0.031 | C7: in
A8: Engagement_Hole_Dia | B8: ='Excel Calcs'!B20 -> 0.152 | C8: in
A9: Clearance_Hole_Dia | B9: ='Excel Calcs'!B21 -> 0.218 | C9: in
A10: CLR_Reconnect_HOLE | B10: ='Excel Calcs'!B22 -> 0.562 | C10: in
A11: Bolt_Reconnect_Hole_Dia | B11: ='Excel Calcs'!B23 -> 0.312 | C11: in
A12: CUL_STD_Hole_Dia | B12: ='Excel Calcs'!B24 -> 0.218 | C12: in
A13: Corner_Brace_Countersunk_Hole | B13: ='Excel Calcs'!B28 -> 0.001 | C13: in
A14: CTR_Hole_DIA | B14: ='Excel Calcs'!B29 -> 0.109 | C14: in
A15: Stamped_Hole_Cut_DIA | B15: ='Excel Calcs'!B30 -> 0.218 | C15: in
A16: Corner_Relief_H | B16: ='Excel Calcs'!B31 -> 0.25 | C16: in
A17: Asy_End_Relief | B17: ='Excel Calcs'!B32 -> 0.03125 | C17: in
A18: Corner_Brace_H | B18: ='Excel Calcs'!E2 -> 5.80598 | C18: in
A19: Corner_Brace_W | B19: ='Excel Calcs'!E3 -> 5.90299 | C19: in
A20: Corner_Brace_Hole_Start | B20: ='Excel Calcs'!E4 -> 0.90299 | C20: in
A21: Corner_Brace_Hole_Qty | B21: ='Excel Calcs'!E5 -> 2 | C21: ul
A22: Corner_Brace_Hole_Spacing | B22: ='Excel Calcs'!E6 -> 4 | C22: in
A23: Clearance_Hole_Dia | B23: ='Excel Calcs'!E7 -> 0.218 | C23: in
A24: Brace_DOA_FLG_L | B24: ='Excel Calcs'!E8 -> 1.3 | C24: in
A25: Brace_DOA_FLG_Hole_Y | B25: ='Excel Calcs'!E9 -> 0.75 | C25: in
A26: Brace_Face_Start_Hole | B26: ='Excel Calcs'!E10 -> 1.25 | C26: in
A27: Brace_Face_Start_Hole_Y | B27: ='Excel Calcs'!E11 -> 0.65299 | C27: in
A28: Brace_Face_Spacing_Hole | B28: ='Excel Calcs'!E12 -> 2.25 | C28: in
A29: Corner_Brace_Vert_Dist_1 | B29: ='Excel Calcs'!E13 -> 89.88693 | C29: in
... A46: Corner_Brace_CLR_Holes | B46: ='Excel Calcs'!E30 -> 0.185 | C46: in
A47: Seam_X_LOC | B47: ='Excel Calcs'!E39 -> 0.12801 | C47: in
A48: Seam_L | B48: ='Excel Calcs'!E40 -> 89.74398 | C48: in
A49: Seam_W | B49: ='Excel Calcs'!E41 -> 3 | C49: in
A50: Seam_Notch_W | B50: ='Excel Calcs'!E42 -> 0.11251 | C50: in
A51: Seam_Notch_W_2 | B51: ='Excel Calcs'!E43 -> 0.25 | C51: in
A52: Seam_Notch_L | B52: ='Excel Calcs'!E44 -> 1.93399 | C52: in
A53: Seam_Hole_To_CTR | B53: ='Excel Calcs'!E45 -> 0.5 | C53: in
A54: Seam_Hole_Array_Qty | B54: ='Excel Calcs'!E46 -> 11 | C54: ul
A55: Seam_Hole_Array_DIST | B55: ='Excel Calcs'!E47 -> 8.174398 | C55: in
A56: Seam_Hole_Start | B56: ='Excel Calcs'!E48 -> 4 | C56: in
...

Sheet Data
A1: INPUTS
A2: Parameter | B2: Value | C2: Description | F2: THIS BOX IS OUTPUT ONLY … DO NOT USE AS INPUTS
A3: Tunnel_H | B3: 90 | C3: Valid Height per tunnel Max Height is 142.5" for 1 Reconnect High= Max sheet size | F3: Thickness Outputs
A4: Tunnel_W | B4: 90 | C4: Valid Width per tunnel <> Max. 120" Width for CUWA and CUWC | F4: Corner_Brace_Thk | G4: =IF(Corner_Brace_GAO=0,CONCATENATE(12,MaterialStyle),CONCATENATE(Corner_Brace_GAO,MaterialStyle)) -> 12STL GALV | H4: =VLOOKUP(G4,Material_List_Table,MATCH(MAT_KEYT,Material_List_Column_Names,0),FALSE) -> 0.09701
A5: Reconnect_Type | B5: STD | C5: STD, CUL, CUWA, CUWC <> Standard (STD), Corridor Unit Length (CUL), Corridor Unit Width AHU(CUWA), Corridor Unit Width Corridor(CUWC) | D5: STD, CUL, CUWA, CUWC | F5: Reconnect_Thk | G5: =IF(Reconnect_GAO=0,CONCATENATE(12,MaterialStyle),CONCATENATE(Reconnect_GAO,MaterialStyle)) -> 12STL GALV | H5: =VLOOKUP(G5,Material_List_Table,MATCH(MAT_KEYT,Material_List_Column_Names,0),FALSE) -> 0.09701
A6: MaterialStyle | B6: STL GALV | C6: STL GALV <> Default, or SST304 | D6: STL GALV, SST304 | F6: Stiffener_Thk | G6: =IF(Stiffener_GAO=0,CONCATENATE(12,MaterialStyle),CONCATENATE(Stiffener_GAO,MaterialStyle)) -> 12STL GALV | H6: =VLOOKUP(G6,Material_List_Table,MATCH(MAT_KEYT,Material_List_Column_Names,0),FALSE) -> 0.09701
A7: BTM_Seam | B7: NO | C7: YES or NO = Default <> Used only for CUWA or CUWC, Bottom Seam Cover | D7: YES, NO
A8: Z_Location | B8: 0 | C8: 0 = Bolted Side to nearest split, Anything > than 0 = Bolted Side away split <> Bolted Side = Butts the adjacent skid
A9: Construction | B9: BASELINE | C9: BASELINE = Default <> Changes the hole spacing | D9: BASELINE
A10: Reconnect_Array_HO | B10: 1 | C10: 1 = Default, 1 2 or 3 <> Works for Valid STD "Reconnect_Type" only | D10: 1, 2, 3
A11: Reconnect_Array_WO | B11: 1 | C11: 1 = Default, 1 2 3 or 4 <> Works for Valid STD "Reconnect_Type" only | D11: 1, 2, 3, 4
A12: Corner_BraceO | B12: YES | C12: YES or NO <> YES is Deafult | D12: YES, NO
A13: Corner_Brace_GAO | B13: 0 | C13: 0 = Default for 12GA, Any valid acceptable GA
A14: Reconnect_GAO | B14: 0 | C14: 0 = Default for 12GA, Any valid acceptable GA
A15: Stiffener_GAO | B15: 0 | C15: 0 = Default for 12GA, Any valid acceptable GA
A17: Errors on Sheet1 | B17: =Sheet1!B273 -> 0
A18: Negative Values on Sheet1 | B18: =Sheet1!B274 -> 0
A22: =CONCATENATE("ASY RECONNECT ",Tunnel_H,"X",Tunnel_W," ",Reconnect_Type," ",IF(MaterialStyle="STL GALV"," GLV",IF(MaterialStyle=" SST","SST",IF(MaterialStyle="STRUCT GALV"," STR G",MaterialStyle)))) -> ASY RECONNECT 90X90 STD GLV | B22: =LEN(A22) -> 28

Sheet Excel Calcs
A1: FROM DATA TAB | D1: Corner Brace Holes | G1: Angle Reconnect Wall | J1: Channel Reconnect Wall | M1: Channel LOC TAB
A2: Tunnel_H | B2: =Tunnel_H -> 90 | D2: Corner_Brace_H | E2: =6-Corner_Brace_Thk*2 -> 5.80598 | G2: Angle_DOA_FLG_L | H2: =1.5 -> 1.5 | J2: Channel_DOA_FLG_L | K2: =1.5 -> 1.5 | M2: Corner_Brace_X_Hole_Start_1 | N2: =1 -> 1
A3: Tunnel_W | B3: =Tunnel_W -> 90 | D3: Corner_Brace_W | E3: =6-Corner_Brace_Thk -> 5.90299 | G3: Angle_Top_FLG_L | H3: =2 -> 2 | J3: Channel_FLG_L | K3: =2 -> 2 | M3: Corner_Brace_X_Hole_Start_2 | N3: =H4-5+Reconnect_Thk*2 -> 84.99744
A4: Reconnect_Type | B4: =Reconnect_Type -> STD | D4: Corner_Brace_Hole_Start | E4: =1-Corner_Brace_Thk -> 0.90299 | G4: Angle_W | H4: =IF(AND(B3<=142.5,B9=1,B10=1),B3-Reconnect_Thk*2-0.00128*2,IF(AND(B3<=285,B9=1,B10=1),B3/2-Reconnect_Thk*2-0.00128*2,IF(AND(B3<=427.5,B9=1,B10=1),B3/3-Reconnect_Thk*2-0.00128*2,IF(AND(B3<=570,B9=1,B10=1),B3/4-Reconnect_Thk*2-0.00128*2,IF(AND(B3<=142.5,B10=1),B3-Reconnect_Thk*2-0.00128*2,IF(AND(B3<=285,B10=2),B3/2-Reconnect_Thk*2-0.00128*2,IF(AND(B3<=288,B10=3),B3/3-Reconnect_Thk*2-0.00128*2,B3/4-Reconnect_Thk*2-0.00128*2))))))) -> 89.80342 | J4: Channel_W | K4: =H4-0.001 -> 89.80242 | M4: Corner_Brace_X_Hole_Start_3 | N4: =IF(OR(B10>=2,B3>142.5),H4+Reconnect_Thk*2+1,0) -> 0
A5: MATL_Type | B5: =MaterialStyle -> STL GALV | D5: Corner_Brace_Hole_Qty | E5: 2 | G5: Angle_W_Hole_Start | H5: 2 | J5: Channel_W_Hole_Start | K5: 2 | M5: Corner_Brace_X_Hole_Start_4 | N5: =IF(OR(B10>=2,B3>142.5),H4*2+Reconnect_Thk*4-5,0) -> 0
A6: BTM_Seam | B6: =BTM_Seam -> NO | D6: Corner_Brace_Hole_Spacing | E6: =4 -> 4 | G6: Angle_W_Hole_Qty | H6: =ROUNDUP(H4/K20,0)+1 -> 11 | J6: Channel_W_Hole_Qty | K6: =ROUNDUP(K4/K20,0)+1 -> 11 | M6: Corner_Brace_X_Hole_Start_5 | N6: =IF(OR(B10>=3,B3>285),(H4+Reconnect_Thk*2)*2+1,0) -> 0
A7: Z_Location | B7: =Z_Location -> 0 | D7: Clearance_Hole_Dia | E7: ='Hole Sizes'!B7 -> 0.218 | G7: Angle_W_Hole_Spacing | H7: =(H4-H5*2)/(H6-1) -> 8.580342 | I7: 6.5" or 9" | J7: Channel_W_Hole_Spacing | K7: =(K4-K5*2)/(K6-1) -> 8.580242 | L7: 6.5" or 9" | M7: Corner_Brace_X_Hole_Start_6 | N7: =IF(OR(B10>=3,B3>285),(H4+Reconnect_Thk*2)*3-5,0) -> 0
A8: Construction | B8: =Construction -> BASELINE | D8: DOA_FLG_L | E8: =1.3 -> 1.3 | G8: Angle_BTM_FLG_L | H8: =2 -> 2 | J8: Channel_H | K8: =H10+0.00028*2 -> 89.80598 | M8: Corner_Brace_X_Hole_Start_7 | N8: =IF(OR(B10=4,B3>427.5),(H4+Reconnect_Thk*2)*3+1,0) -> 0
A9: Reconnect_Array_HO | B9: =Reconnect_Array_HO -> 1 | D9: DOA_FLG_Hole_Y | E9: 0.75 | G9: Angle_Side_FLG_L | H9: =1.5 -> 1.5 | J9: Channel_H_Hole_Start | K9: =2 -> 2 | M9: Corner_Brace_X_Hole_Start_8 | N9: =IF(OR(B10=4,B3>427.5),B3-5,0) -> 0
A10: Reconnect_Array_WO | B10: =Reconnect_Array_WO -> 1 | D10: Brace_Face_Start_Hole | E10: 1.25 | G10: Angle_H | H10: =IF(OR(B4="CUWA",B4="CUWC"),B2-Reconnect_Thk-B28-0.00028*2,IF(B9=1,B2-Reconnect_Thk*2-0.00028*2,IF(B9=2,B2/2-Reconnect_Thk*2-0.00028*2,B2/3-Reconnect_Thk*2-0.00028*2))) -> 89.80542 | J10: Channel_H_Hole_Qty | K10: =ROUNDUP(K8/K20,0)+1 -> 11 | L10: 6.5" or 9" | M10: Corner_Brace_Hole_Qty | N10: 2 | O10: JC
A11: Corner_Brace | B11: =Corner_BraceO -> YES | D11: Brace_Face_Start_Hole_Y | E11: =0.75-Corner_Brace_Thk -> 0.65299 | G11: Angle_H_Hole_Start | H11: =2 -> 2 | J11: Channel_H_Hole_Spacing | K11: =IF(B4="CUWC",H19,(K8-K12*2)/(K10-1)) -> 8.4 | M11: Corner_Brace_Hole_Spacing | N11: =E6 -> 4
A12: Corner_Brace_GAO | B12: =Corner_Brace_GAO -> 0 | D12: Brace_Face_Spacing_Hole | E12: 2.25 | G12: Angle_H_Hole_Qty | H12: =ROUNDUP(H10/K20,0)+1 -> 11 | I12: 6.5" or 9" | J12: Channel_Reconnect_W_Hole_Start | K12: =3-Reconnect_Thk -> 2.90299 | M12: Reconnect_X_Hole_Start_1 | N12: =3 -> 3
A13: Reconnect_GAO | B13: =Reconnect_GAO -> 0 | D13: Corner_Brace_Vert_Dist_1 | E13: =IF(B103=1,H10+Reconnect_Thk-B19/2,K8+Reconnect_Thk) -> 89.88693 | G13: Angle_H_Hole_Spacing | H13: =(H10-H11*2)/(H12-1) -> 8.580542 | J13: Channel_Reconnect_W_Hole_Qty | K13: =ROUNDUP((K4-K12*2)/K20,0)+1 -> 11 | L13: 6.5" or 9" | M13: Reconnect_X_Hole_Start_2 | N13: =IF(OR(B10>=2,B3>142.5),N12+H4+Reconnect_Thk*2,0) -> 0
A14: Stiffener_GAO | B14: =Stiffener_GAO -> 0 | D14: Corner_Brace_Hor_Dist_1 | E14: =IF(B103=1,H4+Reconnect_Thk,K4+Reconnect_Thk) -> 89.90043 | G14: Angle_Reconnect_W_Hole_Start | H14: =3-Reconnect_Thk -> 2.90299 | J14: Channel_Reconnect_W_Hole_Spacing | K14: =IF(B4="CUWC",H16,(K4-K12*2)/(K13-1)) -> 8.399644 | M14: Reconnect_X_Hole_Start_3 | N14: =IF(OR(B10>=3,B3>285),(H4+Reconnect_Thk*2)*2+3,0) -> 0
D15: Corner_Brace_X_LOC_1 | E15: =Reconnect_Thk -> 0.09701 | G15: Angle_Reconnect_W_Hole_Qty | H15: =ROUNDUP((H4-H14*2)/K20,0)+1 -> 11 | I15: 6.5" or 9" | J15: Channel_Reconnect_H_Hole_Start | K15: =3 -> 3 | M15: Reconnect_X_Hole_Start_4 | N15: =IF(OR(B10>=4,B3>427.5),(H4+Reconnect_Thk*2)*3+3,0) -> 0
A16: Parameter | B16: Value | D16: Corner_Brace_X_LOC_2 | E16: =E15+H4 -> 89.90043 | G16: Angle_Reconnect_W_Hole_Spacing | H16: =(H4-H14*2)/(H15-1) -> 8.399744 | J16: Channel_Reconnect_H_Hole_Qty | K16: =ROUNDUP((K8-K15*2)/K20,0)+1 -> 11 | L16: 6.5" or 9" | M16: Reconnect_X_Hole_Qty | N16: =H15 -> 11
A17: General | D17: Corner_Brace_X_LOC_3 | E17: =E16+Reconnect_Thk*2 -> 90.09445 | G17: Angle_Reconnect_H_Hole_Start | H17: =3-Reconnect_Thk -> 2.90299 | J17: Channel_Reconnect_H_Hole_Spacing | K17: =IF(B4="CUWC",H19,(K8-K15*2)/(K16-1)) -> 8.380598 | M17: Reconnect_X_Hole_Spacing | N17: =IF(B4="CUWC",K17,H16) -> 8.399744
A18: Side reconnect to Shell Clearance | B18: 0.25 | D18: Corner_Brace_X_LOC_4 | E18: =E17+H4 -> 179.89787 | G18: Angle_Reconnect_H_Hole_Qty | H18: =IF(H10<=28.5,3,ROUNDUP((H10-H17*2)/K20,0)+1) -> 11 | I18: 6.5" or 9" | J18: Channel_Corner_Brace_Start_Hole_1 | K18: =2+Reconnect_Thk -> 2.09701 | M18: Corner_Brace_Y_Hole_Start_1 | N18: 1
A19: Clearance | B19: 0.031 | D19: Corner_Brace_X_LOC_5 | E19: =E18+Reconnect_Thk*2 -> 180.09189 | G19: Angle_Reconnect_H_Hole_Spacing | H19: =IF(B4="CUWC",(H10-H17*2-Reconnect_Thk)/(H18-1),IF(H10<=28.5,(H10-H17*2)/2,(H10-H17*2)/(H18-1))) -> 8.399944 | J19: Channel_Corner_Brace_Start_Hole_2 | K19: =4.25+Reconnect_Thk -> 4.34701 | M19: Corner_Brace_Y_Hole_Start_2 | N19: =IF(OR(B$4="CUWA",B$4="CUWC"),H10+Reconnect_Thk-5,H10+Reconnect_Thk*2-5) -> 84.99944
A20: Engagement_Hole_Dia | B20: ='Hole Sizes'!E25 -> 0.152 | D20: Corner_Brace_X_LOC_6 | E20: =E19+H4 -> 269.89531 | G20: Angle_Reconnect_Side_CB_Start_Hole | H20: =0.75 -> 0.75 | J20: Hole_Spacing "REF" Seismic | K20: =IF(B8="BASELINE",9,6.5) -> 9 | L20: 6.5" or 9" | M20: Corner_Brace_Y_Hole_Start_3 | N20: =IF(B9<2,0,IF(AND(B9=1,B10=1),0,IF(OR(B$4="CUWA",B$4="CUWC"),0,H10+Reconnect_Thk*2+1))) -> 0
A21: Clearance_Hole_Dia | B21: ='Hole Sizes'!B7 -> 0.218 | D21: Corner_Brace_X_LOC_7 | E21: =E20+Reconnect_Thk*2 -> 270.08933 | G21: Angle_Reconnect_Z_Hole_Inward_FLG | H21: =1.25 -> 1.25 | J21: Channel_CB_X_Start_Hole | K21: =1-Reconnect_Thk -> 0.90299 | M21: Corner_Brace_Y_Hole_Start_4 | N21: =IF(B9<2,0,IF(AND(B9=1,B10=1),0,IF(OR(B$4="CUWA",B$4="CUWC"),0,(H10+Reconnect_Thk*2)*2-5))) -> 0
A22: CLR_Reconnect_HOLE | B22: 0.562 | D22: Corner_Brace_X_LOC_8 | E22: =B3-Reconnect_Thk -> 89.90299 | G22: Angle_Reconnect_Z_Hole_DOA | H22: 0.75 | J22: Channel_CB_Y_Start_Hole | K22: =1.25-Reconnect_Thk -> 1.15299 | M22: Corner_Brace_Y_Hole_Start_5 | N22: =IF(B9<3,0,IF(AND(B9=1,B10=1),0,IF(OR(B$4="CUWA",B$4="CUWC"),0,(H10+Reconnect_Thk*2)*2+1))) -> 0
A23: Bolt_Reconnect_Hole_Dia | B23: 0.312 | D23: Corner_Brace_Y_LOC_1 | E23: =Reconnect_Thk -> 0.09701 | G23: Angle_Reconnect_FLG_2 | H23: =0.75 -> 0.75 | J23: Channel_Reconnect_Z_Hole_Inward_FLG | K23: 1.25 | M23: Corner_Brace_Y_Hole_Start_6 | N23: =IF(B9<3,0,IF(AND(B9=1,B10=1),0,IF(OR(B$4="CUWA",B$4="CUWC"),0,B2-5))) -> 0
A24: CUL_STD_Hole_Dia | B24: =IF(B4="CUWC",B23,B21) -> 0.218 | D24: Corner_Brace_Y_LOC_2 | E24: =IF(AND(B9=1,B10=1),B2-Reconnect_Thk,H10+Reconnect_Thk) -> 89.90299 | G24: Angle_Reconnect_STD_CUL_Hole_Dia | H24: =IF(B4="CUL",B21,IF(B4="STD",B23,B23)) -> 0.312 | J24: Channel_Reconnect_Z_Hole_DOA_FLG | K24: =0.75-Reconnect_Thk -> 0.65299 | M24: Corner_Brace_Y_Hole_Qty | N24: 2
A25: Notch_W | B25: =K3-Data!H5+0.0001+B19 -> 1.93409 | D25: Corner_Brace_Y_LOC_3 | E25: =E24+Reconnect_Thk*2 -> 90.09701 | G25: Angle_Reconnect_CUL_Hole_Dia | H25: =IF(B4="CUL",B23,B23) -> 0.312 | M25: Corner_Brace_Y_Hole_Spacing | N25: =E6 -> 4
A26: Notch_H | B26: =Data!H5 -> 0.09701 | D26: Corner_Brace_Y_LOC_4 | E26: =E25+H10 -> 179.90243 | M26: Reconnect_Y_Hole_Start_1 | N26: =IF(OR(B4="CUWA",B4="CUWC"),3-Corner_Brace_Thk/2,3) -> 3
A27: Corner_Brace_Countersunk_Hole | B27: ='Hole Sizes'!B10 -> 0.437 | D27: Corner_Brace_Y_LOC_5 | E27: =E26+Reconnect_Thk*2 -> 180.09645 | M27: Reconnect_Y_Hole_Start_2 | N27: =IF(OR(B2>142.5,B9>=2),N26+H10+Reconnect_Thk*2,0) -> 0
A28: BendRadius | B28: 0.001 | D28: Corner_Brace_Y_LOC_6 | E28: =IF(B4="CUWC",B2-Reconnect_Thk,IF(B9=1,B2-Reconnect_Thk,B2-Reconnect_Thk)) -> 89.90299 | G28: Stamped Feature | M28: Reconnect_Y_Hole_Start_3 | N28: =IF(OR(B2>285,B9>=3),N27+H10+Reconnect_Thk*2,0) -> 0
A29: CTR_Hole_DIA | B29: =0.109 -> 0.109 | D29: Corner_Brace_Z_LOC | E29: =Reconnect_Thk -> 0.09701 | G29: Feature_H | H29: 0.125 | M29: Reconnect_Y_Hole_Qty | N29: =H18 -> 11
A30: Stamped_Hole_Cut_DIA | B30: ='Hole Sizes'!B38 -> 0.218 | D30: Corner_Brace_CLR_Holes | E30: =0.185 -> 0.185 | G30: Feature_Dia | H30: 0.28 | M30: Reconnect_Y_Hole_Spacing | N30: =H19 -> 8.399944
A31: Corner_Relief_H | B31: =0.25 -> 0.25 | D31: Countersink_1_DIST | E31: 2 | G31: Small_Feature_Angle | H31: 41 | M31: Seam_BTM_Y_Hole_Start | N31: =E48+B19+Reconnect_Thk -> 4.12801
A32: Asy_End_Relief | B32: =0.0625/2 -> 0.03125 | D32: Countersink_2_DIST | E32: 4.25 | G32: Countersink_Engagement_Hole | H32: ='Hole Sizes'!B38 -> 0.218 | M32: Seam_BTM_Y_Hole_Qty | N32: =E46 -> 11
A33: Floor_Clearance_Hole_Dia | B33: ='Hole Sizes'!G26 -> 0.25 | D33: Corner_Brace_Hole_DIA | E33: ='Hole Sizes'!B40 -> 0.25 | G33: Countersink_Callout_Hole | H33: ='Hole Sizes'!B39 -> 0.497 | M33: Seam_BTM_Y_Hole_Spacing | N33: =E47 -> 8.174398
A34: Stiffener | G34: Countersink_Callout_Depth | H34: 0.00125 | M34: Seam_BTM_Z_LOC | N34: =IF(OR(B4="CUWA",B4="CUWC"),0.5,0) -> 0
A35: Stiffener_H | B35: =IF(AND(B9=1,B10=1),B2-Reconnect_Thk*4-B19/2,H10-Reconnect_Thk*2) -> 89.59646 | G35: Countersink_XY_DIST | H35: =0.75-Corner_Brace_Thk-Reconnect_Thk -> 0.55598 | M35: Z_Location_STD_Top | N35: =IF(AND(B7>0,B4="STD"),B7-0.75,IF(AND(B7>0,B4="CUWA"),B7-0.75,IF(AND(B7>0,B4="CUWC"),B7-0.75,0.75))) -> 0.75
A36: Stiffener_FLG_L | B36: =1.5-Reconnect_Thk -> 1.40299 | M36: Z_Location_CUW, CUL | N36: =IF(AND(B4="CUWA",B7>0),B7-1,IF(AND(B4="CUWC",B7>0),B7-1,IF(OR(B4="CUWA",B4="CUWC"),1,0))) -> 0
A37: Stiffener_W | B37: 3 | M37: Z_Location_CTR_Hole | N37: =0.4721-Reconnect_Thk -> 0.37509
A38: Stiffener_Hole_CLR | B38: ='Hole Sizes'!B7 -> 0.218 | D38: Seam Split BTM Flat | M38: Z_Location_BTM | N38: =IF(B4="CUL",0,IF(B4="STD",1.125,0.5)) -> 1.125
A39: Stiffener_X_LOC_1 | B39: =IF(AND(B3>96,B3<=142.5,B9=1,B10=1),H4/2+Reconnect_Thk,IF(AND(B3>142.5,B3<=285,B9=1,B10=1),H4/2+Reconnect_Thk,IF(AND(B3>285,B3<=427.5),H4/2+Reconnect_Thk,IF(AND(B3>427.5,B3<570),H4/2+Reconnect_Thk,IF(OR(H15=2,H15=4,H15=6,H15=8,H15=10,H15=12,H15=14,H15=16,H15=18,H15=20,H15=22,H15=24,H15=26),(B3/B10)/2-(H7/2)-Reconnect_Thk*3,(B3/B10)/2))))) -> 45 | D39: Seam_X_LOC | E39: =B19+Reconnect_Thk -> 0.12801 | M39: Z_Location_Stiff_Hole_Top | N39: =N40 -> 0.75
A40: Stiffener_X_LOC_2 | B40: =IF(OR(H15=2,H15=4,H15=6,H15=8,H15=10,H15=12,H15=14,H15=16,H15=18,H15=20,H15=22,H15=24,H15=26),H4*1.5+Reconnect_Thk*3,H4*1.5+Reconnect_Thk*3) -> 134.99616 | D40: Seam_L | E40: =IF(B3>144,144,B3-Reconnect_Thk*2-B19*2) -> 89.74398 | G40: DIST | J40: Int_Vert_Sup | M40: Z_Location_Stiff_Hole_Btm | N40: =IF(AND(B4="CUWA",B7>0),B7-H2-H22,IF(AND(B4="CUWC",B7>0),B7-H2-H22,IF(AND(B4="CUWA",B7=0),H2-H22,IF(AND(B4="CUWC",B7=0),H2-H22,H2-H22)))) -> 0.75
...

Sheet Hole Sizes
A1: Standard Hole Sizes
A2: Clearance | D2: Engagement
A3: 1/8 Rivet | B3: 0.152 | D3: 1/8 Rivet | E3: 0.140
A4: 3/16 Rivet | B4: 0.218 | D4: 3/16 Rivet | E4: 0.208
A5: #6 Hardware | B5: 0.188 | D5: 28-20 ga. (<.04 thickness)
A6: #8 Hardware | B6: 0.218 | D6: #6 Hardware | E6: 0.109
A7: #10 Hardware | B7: 0.218 | D7: #8 Hardware | E7: 0.109
A8: 1/4 Hardware | B8: 0.312 | D8: #10 Hardware | E8: 0.109
A9: 5/16 Hardware | B9: 0.375 | D9: 1/4 Hardware - galv material | E9: 0.109
A10: 3/8 Hardware | B10: 0.437 | D10: 1/4 Hardware - sst | E10: 0.188
A11: 1/2 Hardware | B11: 0.562 | D11: 5/16 Hardware | E11: 0.109
D12: 3/8 Hardware | E12: 0.109
D13: 18-14 ga. (>=.04 and <=.09 thickness)
D14: #6 Hardware | E14: 0.109
D15: #8 Hardware AB, B | E15: 0.136
D16: #8 Hardware D,F,G &T | E16: 0.140
D17: #10 Hardware | E17: 0.152
D18: 1/4 Hardware AB, B | E18: 0.188
D19: 1/4 Hardware D,F,G&T | E19: 0.203
D20: 5/16 Hardware | E20: 0.218
D21: 3/8 Hardware AB,B | E21: 0.281
D22: 3/8 Hardware D,F,G&T | E22: 0.312
D23: 12 ga and up (>.09 thickness)
D24: #8 Hardware | E24: 0.152 | G24: #12 Hardware
D25: #10 Hardware | E25: 0.152 | G25: Clearance | H25: Engagement
D26: 1/4 Hardware AB, B | E26: 0.203 | G26: 0.25 | H26: 0.109 | I26: 28-20 ga. (<.04 thickness)
D27: 1/4 Hardware D,F,G&T | E27: 0.218 | H27: 0.152 | I27: '18-14 ga. (>=.04 and <=.09 thickness)
D28: 5/16 Hardware AB,B | E28: 0.250 | H28: 0.152 | I28: '12 ga and up (>.09 thickness)
D29: 5/16 Hardware D,F,G&T | E29: 0.281
D30: 3/8 Hardware AB,B | E30: 0.312
D31: 3/8 Hardware D,F,G&T | E31: 0.344
A32: SPECIAL HOLE SIZES
B33: Indicator holes
A34: Ga | B34: dia | C34: spacing
A35: 28 ga - 14 ga (<=.09 thickness) | B35: 0.125 | C35: =B35 -> 0.125
A36: 12 ga - 10 ga (>.09 and < .14) | B36: 0.188 | C36: =B36 -> 0.188
A37: 8 ga. (>= .14 thickness) | B37: 0.25 | C37: =B37 -> 0.25
A38: Countersink_Engagement_Hole | B38: 0.218
A39: Countersink_Callout_Hole | B39: 0.497
A40: Corner_Brace_Hole_DIA | B40: =0.25 -> 0.25

Sheet Channel Loc
B2: CHANNEL LOCATION DIMENSIONS (Z_LOCATION) FROM PRIMARY_Z_PLANE (SEGMENT START) X_ARRAY_OFFSET DIMENSIONED FROM "IW" ZERO LOCATION DIMENSION MUST INCLUDE "Side BH to Shell Clearance"
H3: =CONCATENATE('Excel Calcs'!B4," ",'Excel Calcs'!B2,"H"," x ",'Excel Calcs'!B3,"W") -> STD 90H x 90W
B5: Channel Name | C5: Z_LOCATION | D5: X_ARRAY_OFFSET | E5: X_ARRAY_QTY | F5: X_ARRAY_SPACING | G5: FLOOR CHANNELS
B6: FLOOR_CHAN_1 | C6: =IF(OR('Excel Calcs'!B4="CUWA",'Excel Calcs'!B4="CUWC",'Excel Calcs'!B4="CUL"),0,'Excel Calcs'!N35) -> 0.75 | D6: =IF(FLOOR_CHAN_1_Z_LOC=0,0,'Excel Calcs'!N2) -> 1 | E6: =IF(FLOOR_CHAN_1_Z_LOC=0,0,2) -> 2 | F6: =IF(FLOOR_CHAN_1_Z_LOC=0,0,'Excel Calcs'!N$11) -> 4 | H6: Corner Braces
B7: FLOOR_CHAN_2 | C7: =IF(OR('Excel Calcs'!B4="CUWA",'Excel Calcs'!B4="CUWC",'Excel Calcs'!B4="CUL"),0,'Excel Calcs'!N35) -> 0.75 | D7: =IF(FLOOR_CHAN_2_Z_LOC=0,0,'Excel Calcs'!N3) -> 84.99744 | E7: =IF(FLOOR_CHAN_2_Z_LOC=0,0,2) -> 2 | F7: =IF(FLOOR_CHAN_2_Z_LOC=0,0,'Excel Calcs'!N$11) -> 4
B8: FLOOR_CHAN_3 | C8: =IF(OR('Excel Calcs'!N4=0,'Excel Calcs'!B4="CUL"),0,'Excel Calcs'!N35) -> 0 | D8: =IF(FLOOR_CHAN_3_Z_LOC=0,0,'Excel Calcs'!N4) -> 0 | E8: =IF(FLOOR_CHAN_3_Z_LOC=0,0,2) -> 0 | F8: =IF(FLOOR_CHAN_3_Z_LOC=0,0,'Excel Calcs'!N$11) -> 0
B9: FLOOR_CHAN_4 | C9: =IF(OR('Excel Calcs'!N5=0,'Excel Calcs'!B4="CUL"),0,'Excel Calcs'!N35) -> 0 | D9: =IF(FLOOR_CHAN_4_Z_LOC=0,0,'Excel Calcs'!N5) -> 0 | E9: =IF(FLOOR_CHAN_4_Z_LOC=0,0,2) -> 0 | F9: =IF(FLOOR_CHAN_4_Z_LOC=0,0,'Excel Calcs'!N$11) -> 0
B10: FLOOR_CHAN_5 | C10: =IF(OR('Excel Calcs'!B4="CUL",'Excel Calcs'!N6=0),0,'Excel Calcs'!N35) -> 0 | D10: =IF(FLOOR_CHAN_5_Z_LOC=0,0,'Excel Calcs'!N6) -> 0 | E10: =IF(FLOOR_CHAN_5_Z_LOC=0,0,2) -> 0 | F10: =IF(FLOOR_CHAN_5_Z_LOC=0,0,'Excel Calcs'!N$11) -> 0
B11: FLOOR_CHAN_6 | C11: =IF(OR('Excel Calcs'!B4="CUL",'Excel Calcs'!N7=0),0,'Excel Calcs'!N35) -> 0 | D11: =IF(FLOOR_CHAN_6_Z_LOC=0,0,'Excel Calcs'!N7) -> 0 | E11: =IF(FLOOR_CHAN_6_Z_LOC=0,0,2) -> 0 | F11: =IF(FLOOR_CHAN_6_Z_LOC=0,0,'Excel Calcs'!N$11) -> 0
B12: FLOOR_CHAN_7 | C12: =IF('Excel Calcs'!N8=0,0,'Excel Calcs'!N35) -> 0 | D12: =IF(FLOOR_CHAN_7_Z_LOC=0,0,'Excel Calcs'!N8) -> 0 | E12: =IF(FLOOR_CHAN_7_Z_LOC=0,0,2) -> 0 | F12: =IF(FLOOR_CHAN_7_Z_LOC=0,0,'Excel Calcs'!N$11) -> 0
B13: FLOOR_CHAN_8 | C13: =IF('Excel Calcs'!N9=0,0,'Excel Calcs'!N35) -> 0 | D13: =IF(FLOOR_CHAN_8_Z_LOC=0,0,'Excel Calcs'!N9) -> 0 | E13: =IF(FLOOR_CHAN_8_Z_LOC=0,0,2) -> 0 | F13: =IF(FLOOR_CHAN_8_Z_LOC=0,0,'Excel Calcs'!N$11) -> 0
B14: FLOOR_CHAN_9 | C14: =IF(OR('Excel Calcs'!B4="CUWA",'Excel Calcs'!B4="CUWC",'Excel Calcs'!B4="CUL"),0,IF('Excel Calcs'!N12<0.75,0,IF('Excel Calcs'!B7>0,'Excel Calcs'!B7-'Excel Calcs'!N38,'Excel Calcs'!N38))) -> 1.125 | D14: =IF(FLOOR_CHAN_9_Z_LOC=0,0,'Excel Calcs'!N12) -> 3 | E14: =IF(FLOOR_CHAN_9_Z_LOC=0,0,'Excel Calcs'!N16) -> 11 | F14: =IF(FLOOR_CHAN_9_Z_LOC=0,0,'Excel Calcs'!N17) -> 8.399744 | H14: Bottom (Angle, Channel)
B15: FLOOR_CHAN_10 | C15: =IF('Excel Calcs'!N13<0.75,0,IF('Excel Calcs'!B7>0,'Excel Calcs'!B7-'Excel Calcs'!N38,'Excel Calcs'!N38)) -> 0 | D15: =IF(FLOOR_CHAN_10_Z_LOC=0,0,'Excel Calcs'!N13) -> 0 | E15: =IF(FLOOR_CHAN_10_Z_LOC=0,0,'Excel Calcs'!N16) -> 0 | F15: =IF(FLOOR_CHAN_10_Z_LOC=0,0,'Excel Calcs'!N17) -> 0
B16: FLOOR_CHAN_11 | C16: =IF('Excel Calcs'!N14<0.75,0,IF('Excel Calcs'!B7>0,'Excel Calcs'!B7-'Excel Calcs'!N38,'Excel Calcs'!N38)) -> 0 | D16: =IF(FLOOR_CHAN_11_Z_LOC=0,0,'Excel Calcs'!N14) -> 0 | E16: =IF(FLOOR_CHAN_11_Z_LOC=0,0,'Excel Calcs'!N16) -> 0 | F16: =IF(FLOOR_CHAN_11_Z_LOC=0,0,'Excel Calcs'!N17) -> 0
B17: FLOOR_CHAN_12 | C17: =IF('Excel Calcs'!N15<0.75,0,IF('Excel Calcs'!B7>0,'Excel Calcs'!B7-'Excel Calcs'!N38,'Excel Calcs'!N38)) -> 0 | D17: =IF(FLOOR_CHAN_12_Z_LOC=0,0,'Excel Calcs'!N15) -> 0 | E17: =IF(FLOOR_CHAN_12_Z_LOC=0,0,'Excel Calcs'!N16) -> 0 | F17: =IF(FLOOR_CHAN_12_Z_LOC=0,0,'Excel Calcs'!N17) -> 0
B18: FLOOR_CHAN_13 | C18: =IF(OR('Excel Calcs'!B4="STD",'Excel Calcs'!B4="CUL"),0,IF(OR('Excel Calcs'!B4="CUWA",'Excel Calcs'!B4="CUWC"),'Excel Calcs'!N36,'Excel Calcs'!N38)) -> 0 | D18: =IF(FLOOR_CHAN_13_Z_LOC=0,0,'Excel Calcs'!N31) -> 0 | E18: =IF(FLOOR_CHAN_13_Z_LOC=0,0,'Excel Calcs'!N32) -> 0 | F18: =IF(FLOOR_CHAN_13_Z_LOC=0,0,'Excel Calcs'!N33) -> 0 | H18: Flat BTM - Only used for CUWA, or CUWC
B19: FLOOR_CHAN_14 | C19: =IF('Excel Calcs'!B152=0,0,IF('Excel Calcs'!B7>0,'Excel Calcs'!B7-'Excel Calcs'!N40,'Excel Calcs'!N40)) -> 0 | D19: =IF(FLOOR_CHAN_14_Z_LOC=0,0,'Excel Calcs'!N41) -> 0 | E19: =IF(FLOOR_CHAN_14_X_ARRAY_OFFSET=0,0,1.5) -> 0 | F19: 0 | H19: Stiffener Holes
B20: FLOOR_CHAN_15 | C20: =IF('Excel Calcs'!B153=0,0,IF('Excel Calcs'!B7>0,'Excel Calcs'!B7-'Excel Calcs'!N40,'Excel Calcs'!N40)) -> 0 | D20: =IF(FLOOR_CHAN_15_Z_LOC=0,0,'Excel Calcs'!N42) -> 0 | E20: =IF(FLOOR_CHAN_15_X_ARRAY_OFFSET=0,0,1.5) -> 0 | F20: 0
B21: FLOOR_CHAN_16 | C21: =IF('Excel Calcs'!B154=0,0,IF('Excel Calcs'!B7>0,'Excel Calcs'!B7-'Excel Calcs'!N40,'Excel Calcs'!N40)) -> 0 | D21: =IF(FLOOR_CHAN_16_Z_LOC=0,0,'Excel Calcs'!N43) -> 0 | E21: =IF(FLOOR_CHAN_16_X_ARRAY_OFFSET=0,0,1.5) -> 0 | F21: 0
B22: FLOOR_CHAN_17 | C22: =IF('Excel Calcs'!B155=0,0,IF('Excel Calcs'!B7>0,'Excel Calcs'!B7-'Excel Calcs'!N40,'Excel Calcs'!N40)) -> 0 | D22: =IF(FLOOR_CHAN_17_Z_LOC=0,0,'Excel Calcs'!N44) -> 0 | E22: =IF(FLOOR_CHAN_17_X_ARRAY_OFFSET=0,0,1.5) -> 0 | F22: 0
B23: FLOOR_CHAN_18 | C23: =IF(AND('Excel Calcs'!B4="STD",'Excel Calcs'!B7>0),'Excel Calcs'!B7-0.75,IF('Excel Calcs'!B4="STD",0.75,0)) -> 0.75 | D23: =IF(FLOOR_CHAN_18_Z_LOC=0,0,3) -> 3 | E23: =IF(FLOOR_CHAN_18_Z_LOC=0,0,2) -> 2 | F23: =IF(FLOOR_CHAN_18_Z_LOC=0,0,'Excel Calcs'!H4+Reconnect_Thk*2-6) -> 83.99744 | H23: Corner Brace Holes
B24: FLOOR_CHAN_19 | C24: =IF(AND('Excel Calcs'!B10>=2,'Excel Calcs'!B7>0),'Excel Calcs'!B7-0.75,IF(AND('Excel Calcs'!B3>142.5,'Excel Calcs'!B7>0),'Excel Calcs'!B7-0.75,IF(OR('Excel Calcs'!B10>=2,'Excel Calcs'!B3>142.5),0.75,0))) -> 0 | D24: =IF(FLOOR_CHAN_19_Z_LOC=0,0,FLOOR_CHAN_18_X_ARRAY_SPACING+9) -> 0 | E24: =IF(FLOOR_CHAN_19_Z_LOC=0,0,2) -> 0 | F24: =IF(FLOOR_CHAN_19_Z_LOC=0,0,FLOOR_CHAN_18_X_ARRAY_SPACING) -> 0
B25: FLOOR_CHAN_20 | C25: =IF(AND('Excel Calcs'!B10>=3,'Excel Calcs'!B7>0),'Excel Calcs'!B7-0.75,IF(AND('Excel Calcs'!B3>285,'Excel Calcs'!B7>0),'Excel Calcs'!B7-0.75,IF(OR('Excel Calcs'!B10>=3,'Excel Calcs'!B3>285),0.75,0))) -> 0 | D25: =IF(FLOOR_CHAN_20_Z_LOC=0,0,FLOOR_CHAN_18_X_ARRAY_SPACING*2+15) -> 0 | E25: =IF(FLOOR_CHAN_20_Z_LOC=0,0,2) -> 0 | F25: =IF(FLOOR_CHAN_20_Z_LOC=0,0,FLOOR_CHAN_18_X_ARRAY_SPACING) -> 0
B26: FLOOR_CHAN_21 | C26: =IF(AND('Excel Calcs'!B10>3,'Excel Calcs'!B7>0),'Excel Calcs'!B7-0.75,IF(AND('Excel Calcs'!B3>427.5,'Excel Calcs'!B7>0),'Excel Calcs'!B7-0.75,IF(OR('Excel Calcs'!B10>3,'Excel Calcs'!B3>427.5),0.75,0))) -> 0 | D26: =IF(FLOOR_CHAN_21_Z_LOC=0,0,FLOOR_CHAN_18_X_ARRAY_SPACING*3+21) -> 0 | E26: =IF(FLOOR_CHAN_21_Z_LOC=0,0,2) -> 0 | F26: =IF(FLOOR_CHAN_21_Z_LOC=0,0,FLOOR_CHAN_18_X_ARRAY_SPACING) -> 0
B28: Channel Name | C28: Z_LOCATION | D28: X_ARRAY_OFFSET | E28: X_ARRAY_QTY | F28: X_ARRAY_SPACING | G28: ROOF CHANNELS
B29: ROOF_CHAN_1 | C29: =IF(OR('Excel Calcs'!B11="NO",'Excel Calcs'!B4="CUL"),0,'Excel Calcs'!N35) -> 0.75 | D29: =IF(C29=0,0,'Excel Calcs'!N2) -> 1 | E29: =IF(C29=0,0,'Excel Calcs'!N10) -> 2 | F29: =IF(C29=0,0,'Excel Calcs'!N11) -> 4 | H29: Corner Braces
B30: ROOF_CHAN_2 | C30: =IF(OR('Excel Calcs'!B11="NO",'Excel Calcs'!B4="CUL"),0,'Excel Calcs'!N35) -> 0.75 | D30: =IF(C30=0,0,'Excel Calcs'!N3) -> 84.99744 | E30: =IF(C30=0,0,'Excel Calcs'!N10) -> 2 | F30: =IF(C30=0,0,'Excel Calcs'!N11) -> 4
B31: ROOF_CHAN_3 | C31: =IF(ROOF_CHAN_3_X_ARRAY_OFFSET<=0.5,0,'Excel Calcs'!N35) -> 0 | D31: =FLOOR_CHAN_3_X_ARRAY_OFFSET -> 0 | E31: =E8 -> 0 | F31: =IF(D31<=0.5,0,4) -> 0
B32: ROOF_CHAN_4 | C32: =IF(ROOF_CHAN_4_X_ARRAY_OFFSET<=0.5,0,'Excel Calcs'!N35) -> 0 | D32: =FLOOR_CHAN_4_X_ARRAY_OFFSET -> 0 | E32: =E9 -> 0 | F32: =IF(D32<=0.5,0,4) -> 0
B33: ROOF_CHAN_5 | C33: =IF(ROOF_CHAN_5_X_ARRAY_OFFSET<=0.5,0,'Excel Calcs'!N35) -> 0 | D33: =FLOOR_CHAN_5_X_ARRAY_OFFSET -> 0 | E33: =E10 -> 0 | F33: =IF(D33<=0.5,0,4) -> 0
B34: ROOF_CHAN_6 | C34: =IF(ROOF_CHAN_6_X_ARRAY_OFFSET<=0.5,0,'Excel Calcs'!N35) -> 0 | D34: =FLOOR_CHAN_6_X_ARRAY_OFFSET -> 0 | E34: =E11 -> 0 | F34: =IF(D34<=0.5,0,4) -> 0
B35: ROOF_CHAN_7 | C35: =IF(ROOF_CHAN_7_X_ARRAY_OFFSET<=0.5,0,'Excel Calcs'!N35) -> 0 | D35: =FLOOR_CHAN_7_X_ARRAY_OFFSET -> 0 | E35: =E12 -> 0 | F35: =IF(D35<=0.5,0,4) -> 0
B36: ROOF_CHAN_8 | C36: =IF(ROOF_CHAN_8_X_ARRAY_OFFSET<=0.5,0,'Excel Calcs'!N35) -> 0 | D36: =FLOOR_CHAN_8_X_ARRAY_OFFSET -> 0 | E36: =E13 -> 0 | F36: =IF(D36<=0.5,0,4) -> 0
B37: ROOF_CHAN_9 | C37: =IF('Excel Calcs'!B4="CUL",0,'Excel Calcs'!N35) -> 0.75 | D37: =IF(C37=0,0,'Excel Calcs'!N12) -> 3 | E37: =IF(C37=0,0,'Excel Calcs'!N16) -> 11 | F37: =IF(C37=0,0,'Excel Calcs'!N$17) -> 8.399744 | H37: Top (Angle, Channel)
B38: ROOF_CHAN_10 | C38: =IF(FLOOR_CHAN_10_Z_LOC=0,0,IF('Excel Calcs'!B4="CUL",0,'Excel Calcs'!N35)) -> 0 | D38: =IF(C38=0,0,'Excel Calcs'!N13) -> 0 | E38: =IF(C38=0,0,'Excel Calcs'!N16) -> 0 | F38: =IF(C38=0,0,'Excel Calcs'!N$17) -> 0
B39: ROOF_CHAN_11 | C39: =IF(FLOOR_CHAN_11_Z_LOC=0,0,'Excel Calcs'!N35) -> 0 | D39: =D16 -> 0 | E39: =IF(ROOF_CHAN_11_Z_LOC=0,0,'Excel Calcs'!N16) -> 0 | F39: =IF(C39=0,0,'Excel Calcs'!N$17) -> 0
B40: ROOF_CHAN_12 | C40: =IF(FLOOR_CHAN_12_Z_LOC=0,0,'Excel Calcs'!N35) -> 0 | D40: =D17 -> 0 | E40: =IF(ROOF_CHAN_12_Z_LOC=0,0,'Excel Calcs'!N16) -> 0 | F40: =IF(C40=0,0,'Excel Calcs'!N$17) -> 0
B41: ROOF_CHAN_13 | C41: =FLOOR_CHAN_14_Z_LOC -> 0 | D41: =FLOOR_CHAN_14_X_ARRAY_OFFSET -> 0 | E41: =FLOOR_CHAN_14_X_ARRAY_QTY -> 0 | F41: =FLOOR_CHAN_14_X_ARRAY_SPACING -> 0 | H41: Stiffener Holes
B42: ROOF_CHAN_14 | C42: =FLOOR_CHAN_15_Z_LOC -> 0 | D42: =FLOOR_CHAN_15_X_ARRAY_OFFSET -> 0 | E42: =FLOOR_CHAN_15_X_ARRAY_QTY -> 0 | F42: 0
B43: ROOF_CHAN_15 | C43: =FLOOR_CHAN_16_Z_LOC -> 0 | D43: =FLOOR_CHAN_16_X_ARRAY_OFFSET -> 0 | E43: =FLOOR_CHAN_16_X_ARRAY_QTY -> 0 | F43: 0
...

Sheet Material List
A1: Page: 102-006 | K1: Edit Manual | M1: PRODUCT: Solution
A2: Title: Raw Material Part Numbers, Mapics Codes, Calculations And Others | M2: 102-006.xls | Q2: Rel/Rev Date:
M3: Revision Level : | Q3: ECN Number :
B5: Solution Project, Raw material codes and calculations, Sheet or Coil stock, Square Foot
D6: Mat'l Group | E6: Metal Gauge | F6: Metal Thickness Min. | G6: Design Thickness (Ref) | H6: Inventor Thickness Key_PK | I6: Active Product "XT" | J6: Active Product "YC" | K6: Mapics Part Number | L6: Material description | M6: Material Type | N6: York "R" Std | O6: Max Cut Size | P6: Unit of Measure | Q6: Inventor Material Designation | R6: "DXF" Mat'l Data | S6: Hole Size / Texture | T6: Staggered Centers
A7: MAT_LOOKUP | D7: MAT_GRP | E7: MAT_GA | F7: MAT_MINT | G7: MAT_DEST | H7: MAT_KEYT | I7: MAT_XT | J7: MAT_YC | K7: MAT_PNUM | L7: MAT_DESC | M7: MAT_TYPE | N7: MAT_RSTD | O7: MAT_CUT | P7: MAT_UMSR | Q7: MAT_DESG | R7: MAT_DXF | S7: MAT_HLSZ | T7: MAT_STG
C8: Sheet Products, Solid
A9: =CONCATENATE(E9,Q9) -> 8STL GALV | D9: Sheet, G90 | E9: 8 | F9: .156 | G9: .156 | H9: 0.15601 | I9: XT | J9: YC | K9: 005 06145 008 | L9: Galvanized Steel | M9: G90 | N9: R259 w/ note 4 | O9: 48 X 144 | P9: SF | Q9: STL GALV | R9: GLVS157- | S9: N/A | T9: N/A
A10: =CONCATENATE(E10,Q10) -> 10STL GALV | D10: Sheet, G90 | E10: 10 | F10: .125 | G10: .126 | H10: 0.12601 | I10: - | J10: YC | K10: 005 06145 010 | L10: Galvanized Steel | M10: G90 | N10: R259 w/ note 4 | O10: 48 X 144 | P10: SF | Q10: STL GALV | R10: GLVS126- | S10: N/A | T10: N/A
A11: =CONCATENATE(E11,Q11) -> 12STL GALV | D11: Sheet, G90 | E11: 12 | F11: .096 | G11: .097 | H11: 0.09701 | I11: - | J11: YC | K11: 005 06145 012 | L11: Galvanized Steel | M11: G90 | N11: R259 w/ note 4 | O11: 60 X 144 | P11: SF | Q11: STL GALV | R11: GLVS097- | S11: N/A | T11: N/A
A12: =CONCATENATE(E12,Q12) -> 14STL GALV | D12: Sheet, G90 | E12: 14 | F12: .069 | G12: .070 | H12: 0.07001 | I12: - | J12: YC | K12: 005 06145 014 | L12: Galvanized Steel | M12: G90 | N12: R259 w/ note 4 | O12: 60 X 144 | P12: SF | Q12: STL GALV | R12: GLVS070- | S12: N/A | T12: N/A
A13: =CONCATENATE(E13,Q13) -> 16STL GALV | D13: Sheet, G90 | E13: 16 | F13: .055 | G13: .056 | H13: 0.05601 | I13: XT | J13: YC | K13: 005 06145 016 | L13: Galvanized Steel | M13: G90 | N13: R259 w/ note 4 | O13: 60 X 144 | P13: SF | Q13: STL GALV | R13: GLVS056A | S13: N/A | T13: N/A
A14: =CONCATENATE(E14,Q14) -> 18STL GALV | D14: Sheet, G90 | E14: 18 | F14: .044 | G14: .045 | H14: 0.04501 | I14: XT | J14: YC | K14: 005 06145 018 | L14: Galvanized Steel | M14: G90 | N14: R259 w/ note 4 | O14: 60 X 144 | P14: SF | Q14: STL GALV | R14: GLVS045A | S14: N/A | T14: N/A
A15: =CONCATENATE(E15,Q15) -> 20STL GALV | D15: Sheet, G90 | E15: 20 | F15: .033 | G15: .034 | H15: 0.03401 | I15: XT | J15: YC | K15: 005 06145 020 | L15: Galvanized Steel | M15: G90 | N15: R259 w/ note 4 | O15: 60 X 144 | P15: SF | Q15: STL GALV | R15: GLVS034- | S15: N/A | T15: N/A
A16: =CONCATENATE(E16,Q16) -> 22STL GALV | D16: Sheet, G90 | E16: 22 | F16: .028 | G16: .028 | H16: 0.02801 | I16: - | J16: YC | K16: 005 06145 022 | L16: Galvanized Steel | M16: G90 | N16: R259 w/ note 4 | O16: 60 X 144 | P16: SF | Q16: STL GALV | R16: GLVS028- | S16: N/A | T16: N/A
A17: =CONCATENATE(E17,Q17) -> 24STL GALV | D17: Sheet, G90 | E17: 24 | F17: .022 | G17: .022 | H17: 0.02201 | I17: XT | J17: YC | K17: 005 06145 024 | L17: Galvanized Steel | M17: G90 | N17: R259 w/ note 4 | O17: 60 X 144 | P17: SF | Q17: STL GALV | R17: GLVS022- | S17: N/A | T17: N/A
A18: =CONCATENATE(E18,Q18) -> 16STL GALV2 | D18: Roll Form Coil | E18: 16 | F18: .055 | G18: .056 | H18: 0.05605 | I18: - | J18: YC | K18: 001 07591 467 | L18: Channel,Rf,16ga,Glv,4.67w_Flat, YC 2" Housing Channel | M18: G40 | N18: R259 w/ note 4 | O18: 4.67 X Lg | P18: SF | Q18: STL GALV2 | R18: GLVS056C | S18: N/A | T18: N/A
A19: =CONCATENATE(E19,Q19) -> 16STL GALV3 | D19: Roll Form Coil | E19: 16 | F19: .055 | G19: .056 | H19: 0.05606 | I19: - | J19: YC | K19: 001 07591 567 | L19: Channel,Rf,16ga,Glv,5.67w_Flat, YC 3" Housing Channel | M19: G40 | N19: R259 w/ note 4 | O19: 5.67 X Lg | P19: SF | Q19: STL GALV3 | R19: GLVS056D | S19: N/A | T19: N/A
A20: =CONCATENATE(E20,Q20) -> 16STL GALV4 | D20: Roll Form Coil | E20: 16 | F20: .055 | G20: .056 | H20: 0.05607 | I20: - | J20: YC | K20: 001 07591 667 | L20: Channel,Rf,16ga,Glv,6.67w_Flat, YC 4" Housing Channel | M20: G40 | N20: R259 w/ note 4 | O20: 6.67 X Lg | P20: SF | Q20: STL GALV4 | R20: GLVS056E | S20: N/A | T20: N/A
A21: =CONCATENATE(E21,Q21) -> 18STL GALVS | D21: Roll Form Coil | E21: 18 | F21: .044 | G21: .045 | H21: 0.04502 | I21: XT | J21: - | K21: 005 06160 001 | L21: Galvanized Steel, Coil, XT Seam Cap | M21: G90 | N21: R259 w/ note 4 | O21: 2.491 X Lg | P21: SF | Q21: STL GALVS | R21: GLVS045B | S21: N/A | T21: N/A
A22: =CONCATENATE(E22,Q22) -> 16STL GALVR | D22: Roll Form Coil | E22: 16 | F22: .055 | G22: .056 | H22: 0.05602 | I22: XT | J22: - | K22: 005 06161 001 | L22: Galvanized Steel, Coil, XT Raceway | M22: G90 | N22: R259 w/ note 4 | O22: 12.62 X Lg | P22: SF | Q22: STL GALVR | R22: GLVS056B | S22: N/A | T22: N/A
A23: =CONCATENATE(E23,Q23) -> 14STL GALV PPG | D23: Sheet, Pre-Paint | E23: 14 | F23: .069 | G23: .070 | H23: 0.07003 | I23: - | J23: YC | K23: 005 07110 014 | L23: Sheet,Pre-Paint,Gray,14ga | M23: P-Paint | N23: M-310 | O23: 48 x Lg | P23: SF | Q23: STL GALV PPG | R23: GLVPP070A | S23: Gray Paint | T23: N/A
A24: =CONCATENATE(E24,Q24) -> 16STL GALV PPG | D24: Sheet, Pre-Paint | E24: 16 | F24: .055 | G24: .056 | H24: 0.05603 | I24: - | J24: YC | K24: 005 07110 016 | L24: Sheet,Pre-Paint,Gray,16ga | M24: P-Paint | N24: M-310 | O24: 48 x Lg | P24: SF | Q24: STL GALV PPG | R24: GLVPP056A | S24: Gray Paint | T24: N/A
A25: =CONCATENATE(E25,Q25) -> 16STL GALV PPC | D25: Sheet, Pre-Paint | E25: 16 | F25: .055 | G25: .056 | H25: 0.05604 | I25: - | J25: YC | K25: 005 07110 116 | L25: Sheet,Pre-Paint,Champagne,16ga | M25: P-Paint | N25: M-310 | O25: 48 x Lg | P25: SF | Q25: STL GALV PPC | R25: GLVPP056B | S25: Champagne Paint | T25: N/A
A26: =CONCATENATE(E26,Q26) -> 18STL GALV PPW | D26: Sheet, Pre-Paint | E26: 18 | F26: .044 | G26: .045 | H26: 0.04503 | I26: - | J26: YC | K26: 005 07110 117 | L26: Sheet,Pre-Paint,Msftwhite,18ga | M26: P-Paint | N26: M-310 | O26: 48 x Lg | P26: SF | Q26: STL GALV PPW | R26: GLVPP045A | S26: Msftwhite Paint | T26: N/A
A27: =CONCATENATE(E27,Q27) -> 18STL GALV PPC | D27: Sheet, Pre-Paint | E27: 18 | F27: .044 | G27: .045 | H27: 0.04504 | I27: - | J27: YC | K27: 005 07110 118 | L27: Sheet,Pre-Paint,Champagne,18ga | M27: P-Paint | N27: M-310 | O27: 48 x Lg | P27: SF | Q27: STL GALV PPC | R27: GLVPP045B | S27: Champagne Paint | T27: N/A
A28: =CONCATENATE(E28,Q28) -> 10STL HOT ROLL | D28: Sheet, HR | E28: 10 | F28: .127 | G28: .127 | H28: 0.12701 | I28: - | J28: YC | K28: 005 07113 010 | L28: Sheet,Hot-Rolled,10ga | M28: HR | N28: - | O28: 48 X 144 | P28: SF | Q28: STL HOT ROLL | R28: STLHR127A | S28: Hot-Rolled | T28: N/A
A29: =CONCATENATE(E29,Q29) -> 11STL HOT ROLL | D29: Sheet, HR | E29: 11 | F29: .112 | G29: .112 | H29: 0.11201 | I29: - | J29: YC | K29: 005 07113 011 | L29: Sheet,Hot-Rolled,11ga | M29: HR | N29: - | O29: 48 X 96 | P29: SF | Q29: STL HOT ROLL | R29: STLHR112A | S29: Hot-Rolled | T29: N/A
A30: =CONCATENATE(E30,Q30) -> 12STL HOT ROLL | D30: Sheet, HR | E30: 12 | F30: .097 | G30: .097 | H30: 0.09704 | I30: - | J30: YC | K30: 005 07113 012 | L30: Sheet,Hot-Rolled,12ga | M30: HR | N30: - | O30: 48 X 96 | P30: SF | Q30: STL HOT ROLL | R30: STLHR097A | S30: Hot-Rolled | T30: N/A
A31: =CONCATENATE(E31,Q31) -> 14STL HOT ROLL | D31: Sheet, HR | E31: 14 | F31: .068 | G31: .068 | H31: 0.06801 | I31: - | J31: YC | K31: 005 07113 014 | L31: Sheet,Hot-Rolled,14ga | M31: HR | N31: - | O31: 48 X 120 | P31: SF | Q31: STL HOT ROLL | R31: STLHR068A | S31: Hot-Rolled | T31: N/A
A32: =CONCATENATE(E32,Q32) -> 20ALM SHT | D32: Sheet, AL | E32: 20 | F32: .040 | G32: .040 | H32: 0.04001 | I32: - | J32: YC | K32: 008 02570 040 | L32: Sheet,Al,3003h14,.040 | M32: AL | N32: R-777 | O32: 48 x 144 | P32: SF | Q32: ALM SHT | R32: ALUS040A | S32: N/A | T32: N/A
A33: =CONCATENATE(E33,Q33) -> 18ALM SHT | D33: Sheet, AL | E33: 18 | F33: .050 | G33: .050 | H33: 0.05003 | I33: - | J33: YC | K33: 008 02570 050 | L33: Sheet,Al,3003h14,.050 | M33: AL | N33: R-777 | O33: 48 x 144 | P33: SF | Q33: ALM SHT | R33: ALUS050A | S33: N/A | T33: N/A
A34: =CONCATENATE(E34,Q34) -> 16ALM SHT | D34: Sheet, AL | E34: 16 | F34: .063 | G34: .063 | H34: 0.06301 | I34: - | J34: YC | K34: 008 02570 063 | L34: Sheet,Al,3003h14,.063 | M34: AL | N34: R-777 | O34: 48 x 144 | P34: SF | Q34: ALM SHT | R34: ALUS063A | S34: N/A | T34: N/A
A35: =CONCATENATE(E35,Q35) -> 14ALM SHT | D35: Sheet, AL | E35: 14 | F35: .080 | G35: .080 | H35: 0.08001 | I35: - | J35: YC | K35: 008 02570 080 | L35: Sheet,Al,3003h14,.080 | M35: AL | N35: R-777 | O35: 48 x 144 | P35: SF | Q35: ALM SHT | R35: ALUS080A | S35: N/A | T35: N/A
A36: =CONCATENATE(E36,Q36) -> 10ALM SHT | D36: Sheet, AL | E36: 10 | F36: .125 | G36: .125 | H36: 0.12501 | I36: - | J36: YC | K36: 008 02570 125 | L36: Sheet,Al,3003h14,.125 | M36: AL | N36: R-777 | O36: 48 x 144 | P36: SF | Q36: ALM SHT | R36: ALUS125A | S36: N/A | T36: N/A
A37: =CONCATENATE(E37,Q37) -> 8ALM SHT | D37: Sheet, AL | E37: 8 | F37: .190 | G37: .190 | H37: 0.19001 | I37: - | J37: YC | K37: 008 02570 190 | L37: Sheet,Al,3003h14,.190 | M37: AL | N37: R-777 | O37: 48 x 144 | P37: SF | Q37: ALM SHT | R37: ALUS190A | S37: N/A | T37: N/A
A38: =CONCATENATE(E38,Q38) -> 8SST304 | D38: Sheet, SST | E38: 8 | F38: .165 | G38: .165 | H38: 0.16501 | I38: N/A | J38: N/A | K38: 005 06146 008 | L38: Stainless steel | M38: 304 | N38: R52 | O38: 48 X 144 | P38: SF | Q38: SST304 | R38: SSTS165- | S38: N/A | T38: N/A
A39: =CONCATENATE(E39,Q39) -> 10SST304 | D39: Sheet, SST | E39: 10 | F39: .135 | G39: .135 | H39: 0.13501 | I39: XT | J39: YC | K39: 005 06146 010 | L39: Stainless steel | M39: 304 | N39: R52 | O39: 48 X 144 | P39: SF | Q39: SST304 | R39: SSTS135- | S39: N/A | T39: N/A
A40: =CONCATENATE(E40,Q40) -> 12SST304 | D40: Sheet, SST | E40: 12 | F40: .105 | G40: .105 | H40: 0.10501 | I40: XT | J40: YC | K40: 005 06146 012 | L40: Stainless steel | M40: 304 | N40: R52 | O40: 60 X 144 | P40: SF | Q40: SST304 | R40: SSTS105- | S40: N/A | T40: N/A
A41: =CONCATENATE(E41,Q41) -> 14SST304 | D41: Sheet, SST | E41: 14 | F41: .075 | G41: .075 | H41: 0.07501 | I41: XT | J41: YC | K41: 005 06146 014 | L41: Stainless steel | M41: 304 | N41: R52 | O41: 60 X 144 | P41: SF | Q41: SST304 | R41: SSTS075- | S41: N/A | T41: N/A
...

Sheet Steel List
B2: Solution Project, Raw material codes and calculations, Sheet or Coil stock, Square Foot
D3: Mat'l Group | E3: LBS/FT | F3: Web/Wall Thickness | G3: Height | I3: Depth | J3: Flange Thickness/ Radius | K3: Active Product "XT" | L3: Active Product "YC" | M3: Mapics Part Number | N3: Material description | O3: Material Type | P3: York "R" Std | Q3: Max Cut Size | R3: Unit of Measure | S3: Inventor Material Designation | T3: "DXF" Mat'l Data
A4: STL_LOOKUP | D4: STL_GRP | E4: STL_LBFT | F4: STL_WT | G4: STL_H | I4: STL_D | J4: STL_FTR | K4: STL_XT | L4: STL_YC | M4: STL_PNUM | N4: STL_DESC | O4: STL_TYPE | P4: STL_RSTD | Q4: STL_CUT | R4: STL_UMSR | S4: STL_DESG | T4: STL_DXF
C5: Structural Steel, Shapes
A6: =CONCATENATE(RIGHT(D6,LEN(D6)-FIND(" ",D6)),G6,E6) -> Channel20.56 | D6: Steel, Channel | E6: 0.56 | F6: 0.188 | G6: 2 | I6: 1.000 | J6: 0.188 | K6: - | L6: YC | M6: 001-07500-000 | N6: Channel 2 X 1 X .19,R-18 Std | O6: A572 HRS | P6: R18 | Q6: 324 IN length | R6: IN | S6: - | T6: -
A7: =CONCATENATE(RIGHT(D7,LEN(D7)-FIND(" ",D7)),G7,E7) -> Channel34.1 | D7: Steel, Channel | E7: 4.1 | F7: 0.17 | G7: 3 | I7: 1.41 | J7: 0.273 | K7: - | L7: YC | M7: 001-07501-000 | N7: Channel 3 X 4.1 Lb/Ft,R-18 Std | O7: A572 HRS | P7: R18 | Q7: 324 IN length | R7: IN | S7: - | T7: -
A8: =CONCATENATE(RIGHT(D8,LEN(D8)-FIND(" ",D8)),G8,E8) -> Channel35 | D8: Steel, Channel | E8: 5 | F8: 0.258 | G8: 3 | I8: 1.498 | J8: 0.273 | K8: XT | L8: - | M8: 001 08405 003 | N8: 3" x 5.0# Structural Channel | O8: A572 HRS | P8: R18 | Q8: 324 IN length | R8: IN | S8: - | T8: -
A9: =CONCATENATE(RIGHT(D9,LEN(D9)-FIND(" ",D9)),G9,E9) -> Channel45.4 | D9: Steel, Channel | E9: 5.4 | F9: 0.184 | G9: 4 | I9: 1.584 | J9: 0.296 | K9: XT | L9: YC | M9: 001 08405 004 | N9: 4" x 5.4# Structural Channel | O9: A572 HRS | P9: R18 | Q9: 324 IN length | R9: IN | S9: - | T9: -
A10: =CONCATENATE(RIGHT(D10,LEN(D10)-FIND(" ",D10)),G10,E10) -> Channel47.25 | D10: Steel, Channel | E10: 7.25 | F10: 0.321 | G10: 4 | I10: 1.721 | J10: 0.296 | K10: XT | L10: - | M10: 001 08405 104 | N10: 4" x 7.25# Structural Channel | O10: A572 HRS | P10: R18 | Q10: 324 IN length | R10: IN | S10: - | T10: -
A11: =CONCATENATE(RIGHT(D11,LEN(D11)-FIND(" ",D11)),G11,E11) -> Channel56.7 | D11: Steel, Channel | E11: 6.7 | F11: 0.19 | G11: 5 | I11: 1.75 | J11: 0.32 | K11: - | L11: YC | M11: 001 08405 005 | N11: Channel 5 X 6.7 Lb/Ft,R-18 Std | O11: A572 HRS | P11: R18 | Q11: 324 IN length | R11: IN | S11: - | T11: -
A12: =CONCATENATE(RIGHT(D12,LEN(D12)-FIND(" ",D12)),G12,E12) -> Channel68.2 | D12: Steel, Channel | E12: 8.2 | F12: 0.2 | G12: 6 | I12: 1.92 | J12: 0.343 | K12: XT | L12: YC | M12: 001 08405 006 | N12: 6" x 8.2# Structural Channel | O12: A572 HRS | P12: R18 | Q12: 324 IN length | R12: IN | S12: - | T12: -
A13: =CONCATENATE(RIGHT(D13,LEN(D13)-FIND(" ",D13)),G13,E13) -> Channel811.5 | D13: Steel, Channel | E13: 11.5 | F13: 0.22 | G13: 8 | I13: 2.26 | J13: 0.39 | K13: XT | L13: YC | M13: 001 08405 008 | N13: 8" x 11.5# Structural Channel | O13: A572 HRS | P13: R18 | Q13: 324 IN length | R13: IN | S13: - | T13: -
A14: =CONCATENATE(RIGHT(D14,LEN(D14)-FIND(" ",D14)),G14,E14) -> Channel1015.3 | D14: Steel, Channel | E14: 15.3 | F14: 0.24 | G14: 10 | I14: 2.6 | J14: 0.438 | K14: XT | L14: YC | M14: 001 08405 010 | N14: 10" x 15.3# Structural Channel | O14: A572 HRS | P14: R18 | Q14: 324 IN length | R14: IN | S14: - | T14: -
A15: =CONCATENATE(RIGHT(D15,LEN(D15)-FIND(" ",D15)),G15,E15) -> Channel1220.7 | D15: Steel, Channel | E15: 20.7 | F15: 0.282 | G15: 12 | I15: 2.942 | J15: 0.501 | K15: XT | L15: YC | M15: 001 08405 012 | N15: 12" x 20.7# Structural Channel | O15: A572 HRS | P15: R18 | Q15: 324 IN length | R15: IN | S15: - | T15: -
A16: =CONCATENATE(RIGHT(D16,LEN(D16)-FIND(" ",D16)),G16,E16) -> I-Beam35.7 | D16: Steel, I-Beam | E16: 5.7 | F16: 0.17 | G16: 3 | I16: 2.33 | J16: 0.26 | K16: - | L16: YC | M16: 001-07638-000 | N16: I-Beam 3 X 5.7 Lb/Ft, R-18 Std | O16: A36 HRS | P16: R18 | Q16: 324 IN length | R16: IN | S16: - | T16: -
A17: =CONCATENATE(RIGHT(D17,LEN(D17)-FIND(" ",D17)),G17,E17) -> I-Beam47.7 | D17: Steel, I-Beam | E17: 7.7 | F17: 0.19 | G17: 4 | I17: 2.66 | J17: 0.293 | K17: XT | L17: YC | M17: 001-08409-004 | N17: I-Beam 4 X 7.7 Lb/Ft,R-18 Std | O17: A36 HRS | P17: R18 | Q17: 324 IN length | R17: IN | S17: - | T17: -
A18: =CONCATENATE(RIGHT(D18,LEN(D18)-FIND(" ",D18)),G18,E18) -> I-Beam612.5 | D18: Steel, I-Beam | E18: 12.5 | F18: 0.23 | G18: 6 | I18: 3.33 | J18: 0.359 | K18: - | L18: YC | M18: 001-07509-000 | N18: I-Beam 6 X 12.5 Lb/Ft,R-18 Std | O18: A36 HRS | P18: R18 | Q18: 324 IN length | R18: IN | S18: - | T18: -
A19: =CONCATENATE(RIGHT(D19,LEN(D19)-FIND(" ",D19)),G19,E19) -> I-Beam818.4 | D19: Steel, I-Beam | E19: 18.4 | F19: 0.27 | G19: 8 | I19: 4 | J19: 0.425 | K19: - | L19: YC | M19: 001-07510-000 | N19: I-Beam 8 X 18.4 Lb/Ft,R-18 Std | O19: A36 HRS | P19: R18 | Q19: 324 IN length | R19: IN | S19: - | T19: -
A20: =CONCATENATE(RIGHT(D20,LEN(D20)-FIND(" ",D20)),G20,I20,F20) -> Angle0.750.750.125 | D20: Steel, Angle | E20: 0.59 | F20: 0.125 | G20: 0.75 | I20: 0.75 | J20: 0.125 | K20: XT | L20: - | M20: 001 08406 075 | N20: 3/4" x 3/4" x 1/8" Structural Angle | O20: A36 HRS | P20: R18 | Q20: 324 IN length | R20: IN | S20: - | T20: -
A21: =CONCATENATE(RIGHT(D21,LEN(D21)-FIND(" ",D21)),G21,I21,F21) -> Angle110.25 | D21: Steel, Angle | E21: 1.49 | F21: 0.25 | G21: 1 | I21: 1 | J21: 0.125 | K21: XT | L21: - | M21: 001 08406 100 | N21: 1" x 1" x 1/4" Structural Angle | O21: A36 HRS | P21: R18 | Q21: 324 IN length | R21: IN | S21: - | T21: -
A22: =CONCATENATE(RIGHT(D22,LEN(D22)-FIND(" ",D22)),G22,I22,F22) -> Angle1.251.250.25 | D22: Steel, Angle | E22: 1.92 | F22: 0.25 | G22: 1.25 | I22: 1.25 | J22: 0.188 | K22: XT | L22: - | M22: 001 08406 125 | N22: 1-1/4" x 1-1/4" x 1/4" Structural Angle | O22: A36 HRS | P22: R18 | Q22: 324 IN length | R22: IN | S22: - | T22: -
A23: =CONCATENATE(RIGHT(D23,LEN(D23)-FIND(" ",D23)),G23,I23,F23) -> Angle1.51.50.25 | D23: Steel, Angle | E23: 2.34 | F23: 0.25 | G23: 1.5 | I23: 1.5 | J23: 0.188 | K23: XT | L23: - | M23: 001 08406 150 | N23: 1-1/2" x 1-1/2" x 1/4" Structural Angle | O23: A36 HRS | P23: R18 | Q23: 324 IN length | R23: IN | S23: - | T23: -
A24: =CONCATENATE(RIGHT(D24,LEN(D24)-FIND(" ",D24)),G24,I24,F24) -> Angle220.25 | D24: Steel, Angle | E24: 3.19 | F24: 0.25 | G24: 2 | I24: 2 | J24: 0.281 | K24: XT | L24: YC | M24: 001 08406 200 | N24: 2" x 2" x 1/4" Structural Angle | O24: A36 HRS | P24: R18 | Q24: 324 IN length | R24: IN | S24: - | T24: -
A25: =CONCATENATE(RIGHT(D25,LEN(D25)-FIND(" ",D25)),G25,I25,F25) -> AngleCoped220.25 | D25: Steel, AngleCoped | E25: 3.19 | F25: 0.25 | G25: 2 | I25: 2 | J25: 0.281 | K25: XT | L25: - | M25: 001 08407 200 | N25: 2" x 2" x 1/4" Structural Angle, Coped Both Ends | O25: A36 HRS | P25: R18 | Q25: 324 IN length | R25: IN | S25: - | T25: -
A26: =CONCATENATE(RIGHT(D26,LEN(D26)-FIND(" ",D26)),G26,I26,F26) -> Angle220.188 | D26: Steel, Angle | E26: 2.44 | F26: 0.188 | G26: 2 | I26: 2 | J26: 0.281 | K26: - | L26: YC | M26: 001-05057-000 | N26: Angle Blk 2 X 2 X .19 | O26: A36 HRS | P26: R18 | Q26: 325 IN length | R26: IN | S26: - | T26: -
A27: =CONCATENATE(RIGHT(D27,LEN(D27)-FIND(" ",D27)),G27,I27,F27) -> Angle640.375 | D27: Steel, Angle | E27: 12.3 | F27: 0.375 | G27: 6 | I27: 4 | J27: 0.5 | K27: - | L27: YC | M27: 001 07501 064 | N27: Angle Blk 6 x 4 x .38 thk | O27: A36 HRS | P27: R18 | Q27: 326 IN length | R27: IN | S27: - | T27: -
A28: =CONCATENATE(RIGHT(D28,LEN(D28)-FIND(" ",D28)),G28,I28,F28) -> Tubing110.065 | D28: Steel, Tubing | E28: 0.8265 | F28: 0.065 | G28: 1 | I28: 1 | J28: - | K28: - | L28: YC | M28: 001-07517-000 | N28: Tubing 1 X 1 X .065 | O28: A36 | P28: - | Q28: 324 IN length | R28: IN | S28: - | T28: -
A29: =CONCATENATE(RIGHT(D29,LEN(D29)-FIND(" ",D29)),G29,I29,F29) -> Tubing330.12 | D29: Steel, Tubing | E29: 4.58 | F29: 0.12 | G29: 3 | I29: 3 | J29: - | K29: XT | L29: YC | M29: 001-08408-003 | N29: Tubing 3 X 3 X .120 | O29: A36 | P29: - | Q29: 324 IN length | R29: IN | S29: - | T29: -
A30: =CONCATENATE(RIGHT(D30,LEN(D30)-FIND(" ",D30)),G30,I30,F30) -> Tubing440.12 | D30: Steel, Tubing | E30: 6.22 | F30: 0.12 | G30: 4 | I30: 4 | J30: - | K30: - | L30: YC | M30: 001-07519-000 | N30: Tubing 4 X 4 X .120 | O30: A36 | P30: - | Q30: 324 IN length | R30: IN | S30: - | T30: -
A31: =CONCATENATE(RIGHT(D31,LEN(D31)-FIND(" ",D31)),G31,I31,F31) -> Tubing220.12 | D31: Steel, Tubing | E31: 2.94 | F31: 0.12 | G31: 2 | I31: 2 | J31: - | K31: XT | L31: YC | M31: 001-08408-002 | N31: Tubing 2 X 2 X .120 | O31: A36 | P31: - | Q31: 324 IN length | R31: IN | S31: - | T31: -
A32: =CONCATENATE(RIGHT(D32,LEN(D32)-FIND(" ",D32)),G32,I32,F32) -> Tubing1.50.750.12 | D32: Steel, Tubing | E32: 1.64 | F32: 0.12 | G32: 1.5 | I32: 0.75 | J32: - | K32: - | L32: YC | M32: 001 08570 000 | N32: Tubing, Blk 3/4"x1 1/2"x.120 | O32: A36 | P32: - | Q32: 324 IN length | R32: IN | S32: - | T32: -
A33: =CONCATENATE(RIGHT(D33,LEN(D33)-FIND(" ",D33)),I33,F33) -> Flat Bar30.25 | D33: Steel, Flat Bar | E33: 2.975 | F33: 0.25 | G33: - | I33: 3 | J33: - | K33: - | L33: YC | M33: 001-07578-000 | N33: Flat Bar 3 x .25 THK | O33: A36 | P33: - | Q33: 324 IN length | R33: IN | S33: - | T33: -
A34: =CONCATENATE(E34,S34)
A35: =CONCATENATE(E35,S35)
A36: =CONCATENATE(E36,S36) | C36: Aluminum, Extruded, Shapes
A37: =T37 -> ALUT12TB | D37: Alum, Extrude, Track | E37: - | F37: - | G37: - | I37: - | J37: - | K37: XT | L37: - | M37: 008 02326 010 | N37: Track,Fltr,Top/Btm,W/2_Pre | O37: extru. Al. | P37: - | Q37: IN length | R37: IN | S37: ALM TRK 12TB | T37: ALUT12TB
A38: =T38 -> ALUT12M- | D38: Alum, Extrude, Track | E38: - | F38: - | G38: - | I38: - | J38: - | K38: XT | L38: - | M38: 008 02327 010 | N38: Track,Fltr,Mid,W/2_Pre | O38: extru. Al. | P38: - | Q38: IN length | R38: IN | S38: ALM TRK 12M | T38: ALUT12M-
A39: =T39 -> ALUT14TB | D39: Alum, Extrude, Track | E39: - | F39: - | G39: - | I39: - | J39: - | K39: XT | L39: - | M39: 008 02328 010 | N39: Track,Fltr,Top/Btm,W/4_Pre | O39: extru. Al. | P39: - | Q39: IN length | R39: IN | S39: ALM TRK 14TB | T39: ALUT14TB
A40: =T40 -> ALUT14M- | D40: Alum, Extrude, Track | E40: - | F40: - | G40: - | I40: - | J40: - | K40: XT | L40: - | M40: 008 02329 010 | N40: Track,Fltr,Mid,W/4_Pre | O40: extru. Al. | P40: - | Q40: IN length | R40: IN | S40: ALM TRK 14M | T40: ALUT14M-
A41: =T41 -> ALUT42TB | D41: Alum, Extrude, Track | E41: - | F41: - | G41: - | I41: - | J41: - | K41: XT | L41: - | M41: 008 02330 010 | N41: Track,Fltr,Top/Btm,W/2_Pre | O41: extru. Al. | P41: - | Q41: IN length | R41: IN | S41: ALM TRK 42TB | T41: ALUT42TB
...

Sheet Revision List
A1: Revision | B1: Date | C1: Description | D1: By | E1: ECN Number
A2: - | B2: 43523 | C2: NEW, YC, INITIAL RELEASE | D2: W. Oberholzer | E2: 18-9947
A3: A | B3: 43672 | C3: ADDED DATA TAB COLUMN D DROP DOWN VALUES | D3: PS | E3: 19-10292
A4: B | B4: 45502 | C4: UPDATED FLOOR MOUNTING CLEARANCE HOLES | D4: MJG | E4: 24-11527
