Workbook
Name Assembly_Description: Data!$B$29
Name CollarThkO: Data!$B$24
Name Construction: Data!$B$12
Name DamperSize: 'Fan Lookup2'!$AF$4
Name DoorPlacement: Data!$B$16
Name Error: Data!$B$27
Name FAN_A: 'Fan Lookup2'!$E$4
Name Fan_AA: 'Fan Lookup'!$AC$4
Name Fan_AB: 'Fan Lookup'!$AD$4
Name Fan_AC: 'Fan Lookup'!$AE$4
Name Fan_AD: 'Fan Lookup'!$AF$4
Name Fan_AE: 'Fan Lookup'!$AG$4
Name Fan_AF: 'Fan Lookup'!$AH$4
Name Fan_AG: 'Fan Lookup'!$AI$4
Name Fan_AH: 'Fan Lookup'!$AJ$4
Name Fan_AI: 'Fan Lookup'!$AK$4
Name Fan_AJ: 'Fan Lookup'!$AL$4
Name Fan_AU: 'Fan Lookup'!$AW$4
Name FAN_AW: 'Fan Lookup2'!$U$4
Name Fan_AZ: 'Fan Lookup'!$BB$4
Name FAN_B: 'Fan Lookup2'!$I$4
Name Fan_BA: 'Fan Lookup'!$BC$4
Name Fan_BB: 'Fan Lookup'!$BD$4
Name Fan_BC: 'Fan Lookup'!$BE$4
Name Fan_BD: 'Fan Lookup'!$BF$4
Name Fan_BE: 'Fan Lookup'!$BG$4
Name FAN_C: 'Fan Lookup2'!$J$4
Name FAN_CS: 'Fan Lookup2'!$Y$4
Name FAN_D: 'Fan Lookup2'!$O$4
Name FAN_E: 'Fan Lookup2'!$N$4
Name FAN_F: 'Fan Lookup2'!$L$4
Name FAN_FS: 'Fan Lookup2'!$X$4
Name FAN_G: 'Fan Lookup2'!$M$4
Name FAN_H: 'Fan Lookup2'!$Q$4
Name FAN_HD: 'Fan Lookup2'!$T$4
Name FAN_I: 'Fan Lookup2'!$S$4
Name FAN_J: 'Fan Lookup2'!$R$4
Name Fan_K: 'Fan Lookup'!$M$4
Name Fan_L: 'Fan Lookup'!$N$4
Name FAN_LG: 'Fan Lookup2'!$V$4
Name FAN_LG_orig: 'Fan Lookup2'!$Z$4
Name Fan_M: 'Fan Lookup'!$O$4
Name FAN_S: 'Fan Lookup2'!$H$4
Name FAN_SD: 'Fan Lookup2'!$P$4
Name FAN_T: 'Fan Lookup2'!$F$4
Name FAN_TL: 'Fan Lookup2'!$G$4
Name FAN_U: 'Fan Lookup2'!$K$4
Name Fan_V: 'Fan Lookup'!$X$4
Name Fan_W: 'Fan Lookup'!$Y$4
Name FAN_WD: 'Fan Lookup2'!$W$4
Name Fan_Y: 'Fan Lookup'!$AA$4
Name Fan_Z: 'Fan Lookup'!$AB$4
Name FanBlockOffQty: Data!$B$13
Name FanBlockOffThkO: Data!$B$25
Name FanDamperOptn: Data!$B$14
Name FANSARRAY: Data!$B$9
Name FANSIZE: Data!$B$5
Name FanSpacing: Data!$B$10
Name FanSpacingHorz_O: Data!$B$17
Name FanSpacingLeng_O: Data!$B$18

Sheet Sheet1
A1: Parameter | B1: Value | C1: UM | D1: Comments
A2: Seg_L | B2: ='Excel Calc'!B4 -> 80 | C2: in
A3: Seg_W | B3: ='Excel Calc'!B5 -> 160 | C3: in
A4: Seg_L_Mid | B4: ='Excel Calc'!B6 -> 40 | C4: in
A5: Seg_W_Mid | B5: ='Excel Calc'!B7 -> 80 | C5: in
A6: Clr_1 | B6: ='Excel Calc'!B8 -> 0.03125 | C6: in
A7: Clr_2 | B7: ='Excel Calc'!B9 -> 0.0625 | C7: in
A8: Raceway_W | B8: ='Excel Calc'!B11 -> 2.375 | C8: in
A9: FanArrayDoa | B9: ='Excel Calc'!B12 -> 2 | C9: ul
A10: FansWide | B10: ='Excel Calc'!B13 -> 5 | C10: ul
A11: FansArrayDist | B11: ='Excel Calc'!B14 -> 42 | C11: in
A12: FansWideDist | B12: ='Excel Calc'!B15 -> 30.5 | C12: in
A13: Damper_Sup | B13: ='Excel Calc'!B16 -> 10 | C13: in
A14: Fan_1_loc_Z | B14: ='Excel Calc'!B17 -> 19 | C14: in
A15: Fan_1_loc_X | B15: ='Excel Calc'!B18 -> 19 | C15: in
A16: FanArray2x1Sup | B16: ='Excel Calc'!B19 -> 1 | C16: ul
A17: FanArray2x2Sup | B17: ='Excel Calc'!B20 -> 1 | C17: ul
A18: FanArray2x3Sup | B18: ='Excel Calc'!B21 -> 1 | C18: ul
A19: BlockOff_Sup | B19: ='Excel Calc'!B22 -> 0.001 | C19: ul
A20: FAN_A | B20: ='Excel Calc'!R5 -> 24.803 | C20: in
A21: FAN_B | B21: ='Excel Calc'!R6 -> 0.591 | C21: in
A22: FAN_C | B22: ='Excel Calc'!R7 -> 0.12 | C22: in
A23: FAN_D | B23: ='Excel Calc'!R8 -> 0.43 | C23: in
A24: FAN_E | B24: ='Excel Calc'!R9 -> 11.417 | C24: in
A25: FAN_F | B25: ='Excel Calc'!R10 -> 3 | C25: ul
A26: FAN_G | B26: ='Excel Calc'!R11 -> 11.417 | C26: in
A27: FAN_H | B27: ='Excel Calc'!R12 -> 3.173 | C27: in
A28: FAN_I | B28: ='Excel Calc'!R13 -> 3 | C28: in
A29: FAN_J | B29: ='Excel Calc'!R14 -> 1.89 | C29: in
A30: FAN_K | B30: ='Excel Calc'!R15 -> 17.0082 | C30: in
A31: FAN_L | B31: ='Excel Calc'!R16 -> 60 | C31: deg
A32: FAN_M | B32: ='Excel Calc'!R17 -> 6 | C32: ul
A33: FAN_S | B33: ='Excel Calc'!R23 -> 13.807 | C33: in
A34: FAN_T | B34: ='Excel Calc'!R24 -> 19.685 | C34: in
A35: FAN_U | B35: ='Excel Calc'!R25 -> 1.181 | C35: in
A36: FAN_V | B36: ='Excel Calc'!R26 -> 14.91 | C36: in
A37: FAN_W | B37: ='Excel Calc'!R27 -> 18.898 | C37: in
A38: FAN_Y | B38: ='Excel Calc'!R29 -> 0.994 | C38: in
A39: FAN_Z | B39: ='Excel Calc'!R30 -> 11.928 | C39: in
A40: FAN_AB | B40: ='Excel Calc'!R32 -> 2.1868 | C40: in
...

Sheet Data
A1: Input
A2: Parameter | B2: Value | C2: Description | D2: Inputs for MOM | E2: Error Check
A3: IL | B3: 80 | C3: Segment Internal length | E3: ='Excel Calc'!B27 -> Correct Input
A4: IW | B4: 160 | C4: Segment Internal Width | E4: ='Excel Calc'!B28 -> Correct Input
A5: FANSIZE | B5: 450 | C5: EBM Fan Size; 250 to 900 | E5: ='Excel Calc'!B29 -> Correct Input
A6: MTRVOLT | B6: 460 | C6: Motor Voltage | D6: 208, 230, 460 | E6: ='Excel Calc'!B29 -> Correct Input
A7: KW | B7: 3 | C7: Motor KW | E7: ='Excel Calc'!B29 -> Correct Input
A8: FANSWIDE | B8: 5 | C8: Default=1, Fan Array Width- number of fans side-by-side | D8: 1, 2, 3, 4, 5, 6
A9: FANSARRAY | B9: 2 | C9: Default=1, Fan Array DOA | D9: 1, 2
A10: FanSpacing | B10: 2 | C10: Default=0, Options 0= .6 wheel dia. spacing, 1= 1 wheel dia. spacing, 2= evenly spaced | D10: 0, 1, 2
A11: MaterialStyle | B11: SST304 | C11: Default= STL GALV Any valid material style. Ie: STL GALV, SST304 | D11: STL GALV, SST304
A12: Construction | B12: Baseline | C12: Construction type - TBD
A13: FanBlockOffQty | B13: 0 | C13: Default=0, Qty of fan block off plates | E13: ='Excel Calc'!B30 -> Correct Input
A14: FanDamperOptn | B14: BD | C14: BD, NO (back-draft, none) | D14: NO, BD | E14: ='Excel Calc'!B31 -> Correct Input
A15: HT | B15: 2 | C15: Housing thickness, Default = 2. Options = 2, 3, 4 | D15: 2, 3, 4
A16: DoorPlacement | B16: None | C16: Default=None, Options = None, Side, End, Both (Both= Side and End) | D16: None, Side, End, Both
A17: FanSpacingHorz_O | B17: 0 | C17: Override spacing between fans - Horizontally, wheel to wheel (not center to center)
A18: FanSpacingLeng_O | B18: 0 | C18: Override spacing between fans - Along Seg Length, wheel to wheel (not center to center)
A19: FanToLinerHorz_O | B19: 0 | C19: Override spacing from side liner to fan wheel (not to fan center)
A20: FanToLinerLeng_O | B20: 0 | C20: Override spacing from Segment start to fan wheel (not to fan center)
A21: PanThkO | B21: 0 | C21: Override panel thickness (Typ. 16 ga.) - Horz Separation panels
A22: LenSepPanThkO | B22: 0 | C22: Override panel thickness (Typ. 16 ga.) - Along Seg Length Separation panels
A23: OpeningChannelThkO | B23: 0 | C23: Override channel thickness
A24: CollarThkO | B24: 0 | C24: Override collar thickness. Mounts fans to ladder
A25: FanBlockOffThkO | B25: 0 | C25: Override Fan blockoff thickness (Typ. 16 ga.)
A27: Error | B27: =Sheet1!B343+'Excel Calc'!B32 -> 0
A29: ASSEMBLY_DESCRIPTION | B29: =CONCATENATE("FAN ASSEMBLY, EBM VERTICAL SHAFTED, ",FANSIZE,", ",IL,"Lx",IW,"W") -> FAN ASSEMBLY, EBM VERTICAL SHAFTED, 450, 80Lx160W

Sheet Excel Calc
A2: Parameter | B2: Value | E2: Parameter | F2: Value | I2: Parameter | J2: Value | M2: Parameter | N2: Value | Q2: Parameter | R2: Value | U2: Parameter | V2: Value | Y2: Parameter | Z2: Value
A3: General | E3: Ladder Rail | I3: Ladder Support | M3: Separator Panel | Q3: Fan | U3: Fan Collar | Y3: Damper
A4: Segment_L | B4: =IL -> 80 | E4: Lad_Rail_Thk_Ga | F4: =IF(OpeningChannelThkO<>0,OpeningChannelThkO,12) -> 12 | I4: Lad_Sup_Thk_Ga | J4: =IF(OpeningChannelThkO<>0,OpeningChannelThkO,12) -> 12 | M4: Sep_Pnl1_Thk_Ga | N4: =IF(PanThkO<>0,PanThkO,16) -> 16 | Q4: Fan_WD | R4: =FAN_WD -> 19.88 | U4: Collar_Thk_Ga | V4: =IF(CollarThkO<>0,CollarThkO,10) -> 10 | Y4: Damper_Thk | Z4: 0.125
A5: Segment_W | B5: =IW -> 160 | E5: Lad_Rail_Thk | F5: =VLOOKUP(CONCATENATE(F4,MaterialStyle),Material_List_Table,MATCH(MAT_KEYT,Material_List_Column_Names,0),FALSE) -> 0.10501 | I5: Lad_Sup_Thk | J5: =VLOOKUP(CONCATENATE(J4,MaterialStyle),Material_List_Table,MATCH(MAT_KEYT,Material_List_Column_Names,0),FALSE) -> 0.10501 | M5: Sep_Pnl_Thk | N5: =VLOOKUP(CONCATENATE(N4,MaterialStyle),Material_List_Table,MATCH(MAT_KEYT,Material_List_Column_Names,0),FALSE) -> 0.06001 | Q5: FAN_A | R5: =FAN_A -> 24.803 | U5: Collar_Thk | V5: =VLOOKUP(CONCATENATE(V4,MaterialStyle),Material_List_Table,MATCH(MAT_KEYT,Material_List_Column_Names,0),FALSE) -> 0.13501 | Y5: Damper_Length_No_Flg | Z5: =DamperSize -> 24.25
A6: Seg_L_Mid | B6: =B4/2 -> 40 | E6: Lad_Rail_Start | F6: =B18-(J8/2)-J6 -> 2.5 | I6: Lad_End_Sup_Width | J6: 4.5 | M6: Sep_Pnl2_Thk_Ga | N6: =IF(LenSepPanThkO<>0,LenSepPanThkO,16) -> 16 | Q6: FAN_B | R6: =FAN_B -> 0.591 | U6: Collar_Rivet_HL_Dia | V6: 0.54 | Y6: Damper_Width_No_Flg | Z6: =DamperSize -> 24.25
A7: Seg_W_Mid | B7: =B5/2 -> 80 | E7: Lad_Rail_Width1 | F7: 4.5 | I7: Lad_Mid_Sup_Width | J7: =B15-Z9+2*Z7 -> 6.5 | M7: Sep_Pnl_Thk2 | N7: =VLOOKUP(CONCATENATE(N6,MaterialStyle),Material_List_Table,MATCH(MAT_KEYT,Material_List_Column_Names,0),FALSE) -> 0.06001 | Q7: FAN_C | R7: =FAN_C -> 0.12 | U7: Collar_H | V7: =FAN_A-2*(FAN_C+B8)-2*(V5) -> 24.23048 | Y7: Damper_Flg | Z7: 1.5
A8: Clearance_1 | B8: 0.03125 | E8: Lad_Rail_Width2 | F8: =B14/2-V12/2+Z7 -> 9 | I8: Lad_Sup_Length | J8: =V12-2*F11 -> 24 | M8: Sep_Pnl_Height | N8: =B16+V10+FAN_S+FAN_C -> 24.927 | Q8: FAN_D | R8: =FAN_D -> 0.43 | U8: Collar_H_Round | V8: =ROUND(V7,0) -> 24 | Y8: Damper_Length | Z8: =Z5-2*Z4+2*Z7 -> 27
A9: Clearance_2 | B9: =B8*2 -> 0.0625 | E9: Lad_Rail_Length | F9: =J11+2*J6 -> 155 | I9: Lad_Sup_Flg1 | J9: 2 | M9: Sep_Pnl1_Length | N9: =(J8+2*F7)+IF(FANSARRAY=2,J8+2*F8,0) -> 75 | Q9: FAN_E | R9: =FAN_E -> 11.417 | U9: Collar_Btm_Flg | V9: =IF(OR(KW=4.5,KW=8),V7/2-(FAN_E-V6),V7/2-(IF(FAN_CS<>4,FAN_E,R73)-V6)-IF(FANSIZE+0=630,0.1,-0.25)-IF(FANSIZE+0=355,0.1,0)) -> 1.48824 | Y9: Damper_Width | Z9: =Z6-2*Z4+2*Z7 -> 27
A10: BendRadius | B10: 0.00028 | E10: Lad_Rail_Flg1 | F10: 2 | I10: Lad_Sup_Flg2 | J10: 0.625 | M10: Sep_Pnl2_Length | N10: =IF(FANSWIDE=1,J8+2*J6,(B15/2)+(N13/2)-N5+(J8/2)+J6-N13+N5) -> 31.25 | Q10: FAN_F | R10: =FAN_F -> 3 | U10: Collar_Depth | V10: 1 | Y10: Damper_Mtg_Hole_Edge | Z10: 0.75
A11: Raceway_W | B11: 2.375 | E11: Lad_Rail_Flg2 | F11: 1.5 | I11: Lad_End_Sup_Spac | J11: =IF(FANSWIDE=1,V12-3,FANSWIDE*(V12-3)+J7*(FANSWIDE-1)) -> 146 | M11: Sep_Pnl3_Length | N11: =B15-N5 -> 30.43999 | Q11: FAN_G | R11: =FAN_G -> 11.417 | U11: Collar_Top_Flg | V11: =1.5+(V8-V7)/2 -> 1.38476 | Y11: Damper_Depth | Z11: =10 -> 10
A12: FanArrayDoa | B12: =FANSARRAY -> 2 | E12: Lad_Rail_Flg3 | F12: 0.625 | I12: Lad_Sup_Hole_Dia_1 | J12: ='Hole Sizes'!E18 -> 0.188 | M12: Sep_Pnl4_Length | N12: =(B15/2)+(N13/2)-N5+(J8/2)+J6 -> 32.18999 | Q12: FAN_H | R12: =FAN_H -> 3.173 | U12: Collar_W | V12: =V7+2*V11 -> 27 | Y12: Damper_Hole_Dia_1 | Z12: ='Hole Sizes'!E28 -> 0.250
A13: FansWide | B13: =FANSWIDE -> 5 | E13: Lad_Rail_Hole_Dia_1 | F13: 0.313 | I13: Lad_Sup_Hole_Cut_Out | J13: 0.562 | M13: Sep_Pnl1_Flg | N13: 1 | Q13: FAN_I | R13: =FAN_I -> 3 | U13: Collar_Hole_Dia_1 | V13: =FAN_D -> 0.43 | Y13: Damper_Hole1_X_loc_Max | Z13: 3
A14: FansArrayDist | B14: =K90 -> 42 | E14: Lad_Rail_Hole_Cut_Out | F14: 0.562 | I14: Lad_Sup_Hole_Max_Spc | J14: 4 | M14: Sep_Pnl2_Flg | N14: =2*F12+B10+N5 -> 1.31029 | Q14: FAN_J | R14: =FAN_J -> 1.89 | U14: Collar_Hole_Dia_2 | V14: ='Hole Sizes'!B9 -> 0.375 | Y14: Damper_Hole1_Y_loc | Z14: 0.675
A15: FansWideDist | B15: =K89 -> 30.5 | C15: =J54+K66 -> 30.75 | E15: Lad_Rail_Hole_Dia_2 | F15: 0.312 | I15: Lad_End_Hole1_X_loc | J15: 1 | M15: Sep_Pnl_Hole_Dia_1 | N15: 0.312 | Q15: FAN_K | R15: =Fan_K -> 17.0082 | U15: Collar_Hole1_to_Edge | V15: 0.562 | Y15: Damper_Hole1_X_Spac_Calc | Z15: =(Z8-2*Z13)/2 -> 10.5
A16: Damper_Sup | B16: =IF(FanDamperOptn="BD",Z11,0) -> 10 | E16: Lad_Rail_Hole_Dia_3 | F16: 0.75 | I16: Lad_Sup_Hole1_Y_loc | J16: 1 | M16: Sep_Pnl_Hole_Dia_2 | N16: ='Hole Sizes'!E18 -> 0.188 | Q16: FAN_L | R16: =Fan_L -> 60 | U16: Collar_Hole_Max_Spac | V16: 18 | Y16: Damper_Hole1_X_Spac | Z16: =Z15 -> 10.5
A17: Fan_1_loc_Z | B17: =ROUNDUP(M82,0) -> 19 | E17: Lad_Rail_Hole_Dia_4 | F17: ='Hole Sizes'!E18 -> 0.188 | I17: Lad_Sup_Hole1_X1_Spac | J17: 2.5 | M17: Sep_Pnl1_Hole1_X_loc | N17: 0.5 | Q17: FAN_M | R17: =Fan_M -> 6 | U17: Collar_Hole1_Qty | V17: =ROUNDUP((V12-2*V15)/V16,0)+1 -> 3 | Y17: Damper_Hole1_X_loc | Z17: =(Z8-((Z18-1)*Z16))/2 -> 3
A18: Fan_1_loc_X | B18: =B7-IF(FANSWIDE=1,0.0000001,(B15*(FANSWIDE-1))/2) -> 19 | E18: Lad_Rail_Chf_Dist | F18: 1.25 | I18: Lad_Sup_Hole1_X1_Qty | J18: 2 | M18: Sep_Pnl1_Hole1_Z_loc | N18: 0.375 | Q18: FAN_N | R18: 0 | U18: Collar_Hole1_Spac | V18: =(V12-2*V15)/(V17-1) -> 12.938 | Y18: Damper_Hole1_X_Qty | Z18: =((Z8-2*Z13)/Z15)+1 -> 3
A19: FanArray2x1Sup | B19: =IF(FANSARRAY>=2,1,0) -> 1 | E19: Lad_Rail_Hole1_X_loc | F19: =0.4375+F11 -> 1.9375 | I19: Lad_Sup_Hole1_X2_Spac | J19: =IF(((J7-2*J15)/(J20-1))<1,1,(J7-2*J15)/(J20-1)) -> 4.5 | M19: Sep_Pnl1_Hole1_Z1_Spac | N19: 3.375 | Q19: FAN_O | R19: 0 | U19: Collar_Flg_Clr | V19: =V5-B8 -> 0.10376 | Y19: Damper_Blade_Count | Z19: =IF(FANSIZE+0=310,3,ROUND((Z9-1.9*2)/4.38,0)-1) -> 4
A20: FanArray2x2Sup | B20: =IF(AND(FANSWIDE>1,FANSARRAY>1),1,0) -> 1 | E20: Lad_Rail_Hole1_Z_loc | F20: 1.5 | I20: Lad_Sup_Hole1_X2_Qty | J20: =IF(ROUNDUP((J7-2*J15)/J14,0)<2,2,ROUNDUP((J7-2*J15)/J14,0)) -> 2 | M20: Sep_Pnl1_Hole1_X1_Spac | N20: 3.25 | Q20: FAN_P | R20: 0 | U20: Collar_Hole2_X_loc | V20: 3
A21: FanArray2x3Sup | B21: =IF(AND(FANSWIDE>2,FANSARRAY>1),1,0) -> 1 | E21: Lad_Rail_Hole1_Z_Spac | F21: =(F9-(2*F20))/(F23-1) -> 16.888889 | I21: Lad_Sup_Hole2_X_loc | J21: =Z7-Z14 -> 0.825 | M21: Sep_Pnl1_Hole1_Z2_Spac | N21: =F8-F11/2 -> 8.25 | Q21: FAN_Q | R21: 0 | U21: Collar_Hole2_Y_loc | V21: 0.675
A22: BlockOff_Sup | B22: =IF(FanBlockOffQty=0,0.001,FanBlockOffQty) -> 0.001 | E22: Lad_Rail_Hole1_Z1_Spac | F22: =0.4375+F12 -> 1.0625 | I22: Lad_Sup_Hole2_Z_loc | J22: =Z17-Z7 -> 1.5 | M22: Sep_Pnl1_Hole2_Z_loc | N22: 1.5 | Q22: FAN_R | R22: 0 | U22: Collar_Hole2_X_Spac | V22: =Z16 -> 10.5
E23: Lad_Rail_Hole1_Z_Qty | F23: =ROUNDUP((F9-(2*F20))/F24,0)+1 -> 10 | I23: Lad_Sup_Hole2_Z_Spac | J23: =Z16 -> 10.5 | M23: Sep_Pnl1_Hole2_Y_loc | N23: =N8-4 -> 20.927 | Q23: FAN_S | R23: =FAN_S -> 13.807 | U23: Collar_Hole2_X_Qty | V23: =Z18 -> 3
E24: Lad_Rail_Hole1_Max_Spac | F24: 18 | I24: Lad_Sup_Hole2_Z_Qty | J24: =Z18 -> 3 | M24: Sep_Pnl1_Hole2_Y_Spac | N24: 1.5 | Q24: FAN_T | R24: =FAN_T -> 19.685 | U24: COLLAR_CHAMF_TO_HOLE | V24: =V6+0.25 -> 0.79
A25: Parameter | B25: Value | E25: Lad_Rail_Hole2_X_loc | F25: =B18-Z16 -> 8.5 | I25: Lad_Sup_Hole3_X_loc | J25: 1.5 | M25: Sep_Pnl1_Hole4_Z_loc | N25: 0.0001 | Q25: FAN_U | R25: =FAN_U -> 1.181 | U25: FAN_HD_W_DIA | V25: =IF(R64<0.7,R64,1.181) -> 0.64
A26: Error Check | E26: Lad_Rail_Hole2_Z_loc | F26: =Z14 -> 0.675 | I26: Lad_Sup_Hole3_Z1_loc | J26: =IF((((N23-0.5)/TAN(RADIANS(50)))-F12-F8+0.5)<0.5,0.5,(((N23-0.5)/TAN(RADIANS(50)))-F12-F8+0.5)) -> 8.0152882 | M26: Sep_Pnl1_Hole4_Y_loc | N26: 1.5 | Q26: FAN_V | R26: =Fan_V -> 14.91 | U26: FAN_CLR_NOTCH | V26: =V25+0.25 -> 0.89
A27: Segment Length | B27: =IF(C27=1,"Check Input",IF(B4>=(ROUNDUP(L82,0)+B120)*2+(ROUNDUP(L84,0)+B121)*(FANSARRAY-1),"Correct Input","Invalid Input")) -> Correct Input | C27: =IFERROR(F43,1) -> 66 | E27: Lad_Rail_Hole2_X1_Spac | F27: =Z16 -> 10.5 | I27: Lad_Sup_Hole3_Z2_loc | J27: =J26+N14 -> 9.3255782 | M27: Sep_Pnl1_Hole4_Y_Spac | N27: =(N8-2*N26)/(N28-1) -> 10.9635 | Q27: FAN_W | R27: =Fan_W -> 18.898 | U27: Notch_Depth | V27: =V5+0.12 -> 0.25501
A28: Segment Width | B28: =IF(B15=1,"Check Input",IF(B5>=(ROUNDUP(L81,0)+B122)*2+(ROUNDUP(L83,0)+B123)*(FANSWIDE-1),"Correct Input","Invalid Input")) -> Correct Input | C28: =IFERROR(J11,1) -> 146 | E28: Lad_Rail_Hole2_X1_Qty | F28: =Z18 -> 3 | I28: Lad_Sup_Hole3_Z_Spac | J28: 1.5 | M28: Sep_Pnl1_Hole4_Y_Qty | N28: 3 | Q28: FAN_X | R28: 0
A29: Motor Volt KW | B29: =IF(AND(CONCATENATE(FANSIZE+0,"_",MTRVOLT,"_",KW)='001-013'!A15,C29<>1),"Correct Input","Invalid Input") -> Correct Input | C29: =IFERROR('001-013'!S15,1) -> EG1R-480-450-48 | E29: Lad_Rail_Hole2_X2_Spac | F29: =B15 -> 30.5 | M29: Sep_Pnl1_Cutout_Width | N29: =IF(AND(FANSWIDE>1,FANSARRAY>1),N14+0.5,0.001) -> 1.81029 | Q29: FAN_Y | R29: =Fan_Y -> 0.994
A30: Block Off Qty | B30: =IF(OR(AND(FANSWIDE*FANSARRAY>=FanBlockOffQty,FanDamperOptn="NO"),(AND(FanBlockOffQty=0,FanDamperOptn="BD"))),"Correct Input","Invalid Input") -> Correct Input | E30: Lad_Rail_Hole2_X2_Qty | F30: =FANSWIDE -> 5 | M30: Sep_Pnl2_Start_Dist | N30: =IF(FANSWIDE=1,0.001,0.001) -> 0.001 | Q30: FAN_Z | R30: =Fan_Z -> 11.928
A31: DamperOption | B31: =IF(OR(AND(FanDamperOptn="BD",FanBlockOffQty=0),(AND(FanDamperOptn="NO",FanBlockOffQty>=0))),"Correct Input","Invalid Input") -> Correct Input | E31: Lad_Rail_Hole3_X_loc | F31: =B18-(V12/2)+Z7-J15 -> 6 | M31: Sep_Pnl3_Start_Dist | N31: =N5 -> 0.06001 | Q31: FAN_AA | R31: 0
B32: =COUNTIF(B27:B31,"Invalid Input") -> 0 | E32: Lad_Rail_Hole3_Y_loc | F32: 1 | I32: Parameter | J32: Value | M32: Sep_Pnl2_Hole1_X1_loc | N32: =1.5 -> 1.5 | Q32: FAN_AB | R32: =Fan_AB -> 2.1868
A33: Parameter | B33: Value | E33: Lad_Rail_Hole3_X1_Spc | F33: =J17 -> 2.5 | I33: BlankOff | M33: Sep_Pnl2_Hole1_X2_loc | N33: =N32+N30 -> 1.501 | Q33: FAN_AC | R33: =Fan_AC -> 0.079
A34: Separator Support Bkt | E34: Lad_Rail_Hole3_X2_Spc | F34: =J11+J6 -> 150.5 | I34: BlankOff_Thk_Ga | J34: =IF(FanBlockOffThkO<>0,FanBlockOffThkO,16) -> 16 | M34: Sep_Pnl2_Hole3_X_loc | N34: =N17-N7 -> 0.43999 | Q34: FAN_AD | R34: =Fan_AD -> 4.3736
A35: Sep_Sup_Bkt_Thk_Ga | B35: 12 | E35: Lad_Rail_Hole4_X_loc | F35: =IF(FANSWIDE=1,0.001,B18+(Z9/2)-Z7+J15) -> 32 | I35: BlankOff_Thk | J35: =VLOOKUP(CONCATENATE(J34,MaterialStyle),Material_List_Table,MATCH(MAT_KEYT,Material_List_Column_Names,0),FALSE) -> 0.06001 | M35: Sep_Pnl2_Hole3_Z1_loc | N35: =F12+F42 -> 1 | Q35: FAN_AE | R35: =Fan_AE -> 4.97
A36: Sep_Sup_Bkt_Thk | B36: =VLOOKUP(CONCATENATE(B35,MaterialStyle),Material_List_Table,MATCH(MAT_KEYT,Material_List_Column_Names,0),FALSE) -> 0.10501 | E36: Lad_Rail_Hole4_Y_loc | F36: 1 | I36: BlankOff_Width | J36: =J8-2*B8 -> 23.9375 | M36: Sep_Pnl2_Hole3_Z2_loc | N36: =F12-F42 -> 0.25 | Q36: FAN_AF | R36: =Fan_AF -> 0.27832
A37: Sep_Sup_Bkt_Width1 | B37: 2.5 | E37: Lad_Rail_Hole4_X_Spc | F37: =J19 -> 4.5 | I37: BlankOff_Length | J37: =J8-2*B8 -> 23.9375 | M37: Sep_Pnl2_Hole3_X_Spac | N37: =N10-N34-N34-N19 -> 26.99502 | Q37: FAN_AG | R37: 0
A38: Sep_Sup_Bkt_Width | B38: =2-2*(B36+B10) -> 1.78942 | E38: Lad_Rail_Hole4_X_Qty | F38: =J20 -> 2 | I38: BlankOff_Flg1 | J38: =F14*2+J35+J5 -> 1.28902 | M38: Sep_Pnl3_Hole3_X_Spac | N38: =N11-N34-N34-N19 -> 26.18501 | Q38: FAN_AH | R38: =Fan_AH -> 1.5904
A39: Sep_Sup_Bkt_Length | B39: =(N23-0.5)/SIN(RADIANS(B52)) -> 26.665555 | E39: Lad_Rail_Hole4_X2_Qty | F39: =IF(FANSWIDE=1,1,FANSWIDE-1) -> 4 | I39: BlankOff_Qty | J39: =IF(FanBlockOffQty=0,1,FanBlockOffQty) -> 1 | M39: Sep_Pnl4_Hole3_X_Spac | N39: =N12-N34-N34-N19 -> 27.93501 | Q39: FAN_AI | R39: 0
A40: Sep_Sup_Bkt_Flg1 | B40: 1 | E40: Lad_Rail_Hole5_X_loc | F40: =B18+(B15/2) -> 34.25 | I40: BlankOff_Hole1_Z_loc | J40: =J22-B8 -> 1.46875 | M40: Sep_Pnl1_Support_Height | N40: =ROUNDDOWN(IF(N23-2<8,N23-2,8),0) -> 8 | Q40: FAN_AJ | R40: =Fan_AJ -> 12.3256
A41: Sep_Sup_Bkt_Flg2 | B41: 2.5 | E41: Lad_Rail_Hole5_Z1_loc | F41: 0.75 | I41: BlackOff_Hole1_Y_loc | J41: =F14+J5 -> 0.66701 | Q41: FAN_AK | R41: 0
...

Sheet Fan Lookup
A1: 1 | B1: 2 | C1: 3 | D1: 4 | E1: 5 | F1: 6 | G1: 7 | H1: 8 | I1: 9 | J1: 10 | K1: 11 | L1: 12 | M1: 13 | N1: 14 | O1: 15 | P1: 16 | Q1: 17 | R1: 18 | S1: 19 | T1: 20 | U1: 21 | V1: 22 | W1: 23 | X1: 24 | Y1: 25 | Z1: 26 | AA1: 27 | AB1: 28 | AC1: 29 | AD1: 30 | AE1: 31 | AF1: 32 | AG1: 33 | AH1: 34 | AI1: 35 | AJ1: 36 | AK1: 37 | AL1: 38 | AM1: 39 | AN1: 40 | AO1: 41 | AP1: 42 | AQ1: 43 | AR1: 44 | AS1: 45 | AT1: 46 | AU1: 47 | AV1: 48 | AW1: 49 | AX1: 50 | AY1: 51 | AZ1: 52 | BA1: 53 | BB1: 54 | BC1: 55 | BD1: 56 | BE1: 57 | BF1: 58 | BG1: 59 | BH1: 60 | BI1: 61 | BJ1: 62 | BK1: 63 | BL1: 64 | BM1: 65 | BN1: 66 | BO1: 67 | BP1: 68 | BQ1: 69 | BR1: 70
A2: Fan | B2: wheel dia | C2: inlet H/W | D2: inlet Flange | E2: inlet Thk | F2: inlet Mnt Hole | G2: Hole to Edge | H2: Hole Qty | I2: Hole Spacing | J2: Frame Hrdwr to Side | K2: Frame Hrdwr to Top | L2: Frame Hrdwr Spacing | M2: Wheel Hrdwr Bolt Circ | N2: Wheel Hrdwr Angle | O2: Wheel Hrdwr Qty | P2: NOT USED | Q2: Oval Frame W | R2: Oval Frame H | S2: Oval Frame Cntr-Side1 | T2: Oval Frame Cntr-Side2 | U2: Oval Frame Length | V2: Mtr Pnl H/W | W2: Mtr Pnl Flange | X2: inlet pnl opening | Y2: Funnel Mnt Face dia. | Z2: Funnel Angle | AA2: Funnel Radius 1 | AB2: Funnel Radius2 dia. | AC2: Funnel Radius 2 | AD2: Funnel W | AE2: Funnel Thk | AF2: Wheel Start | AG2: Wheel W | AH2: Wheel Rim W | AI2: Wheel Rim R1 | AJ2: Wheel Funnel R2 | AK2: Wheel Funnel Angle | AL2: Wheel Funnel dia. | AM2: Wheel Rim dia. | AN2: Mtr Hub to Panel | AO2: Mtr Hub dia. | AP2: NOT USED | AQ2: Mtr Hub Chamfer | AR2: Mtr Hub R1 | AS2: Mtr Step to Pnl | AT2: Mtr Step R1 | AU2: Mtr Step dia. 1 | AV2: Mtr Step dia. 2 | AW2: Mtr Rear to Panel | AX2: Mtr Rear Dia. 1 | AY2: Mtr Rear Dia. 2 | AZ2: Mtr Rear Dia. 3 | BA2: Mtr Rear R1 | BB2: Wh. Blade L | BC2: Wh. Blade Arc H | BD2: Wh. Blade Angle | BE2: Wh. Blade Ref. Dia. 1 | BF2: Wh. Blade Ref. Dia. 2 | BG2: MIN btm of unit to fan inlet panel | BI2: collar Depth | BJ2: inlet panel to dwnstrm end of fan/mtr | BK2: XT Total Asy L | BL2: YC Total Asy L | BM2: Final XT L | BN2: Final YC L | BO2: Final L without isolated wall | BP2: Final L without isolated wall + screen | BQ2: XT Vert L | BR2: YC Vert L
A3: Size | B3: WD | C3: A | D3: B | E3: C | F3: D | G3: E | H3: F | I3: G | J3: H | K3: I | L3: J | M3: K | N3: L | O3: M | P3: N | Q3: O | R3: P | S3: Q | T3: R | U3: S | V3: T | W3: U | X3: V | Y3: W | Z3: X | AA3: Y | AB3: Z | AC3: AA | AD3: AB | AE3: AC | AF3: AD | AG3: AE | AH3: AF | AI3: AG | AJ3: AH | AK3: AI | AL3: AJ | AM3: AK | AN3: AL | AO3: AM | AP3: AN | AQ3: AO | AR3: AP | AS3: AQ | AT3: AR | AU3: AS | AV3: AT | AW3: AU | AX3: AV | AY3: AW | AZ3: AX | BA3: AY | BB3: AZ | BC3: BA | BD3: BB | BE3: BC | BF3: BD | BG3: BE
A4: =FANSIZE -> 450 | M4: =VLOOKUP($A$4,$A$5:$BR$24,M1,FALSE) -> 17.0082 | N4: =VLOOKUP($A$4,$A$5:$BR$24,N1,FALSE) -> 60 | O4: =VLOOKUP($A$4,$A$5:$BR$24,O1,FALSE) -> 6 | P4: =VLOOKUP($A$4,$A$5:$BR$24,P1,FALSE) -> 0 | Q4: =VLOOKUP($A$4,$A$5:$BR$24,Q1,FALSE) -> 2.48 | R4: =VLOOKUP($A$4,$A$5:$BR$24,R1,FALSE) -> 1.414 | S4: =VLOOKUP($A$4,$A$5:$BR$24,S1,FALSE) -> 3.14 | T4: =VLOOKUP($A$4,$A$5:$BR$24,T1,FALSE) -> 4.912 | ... BG4: =VLOOKUP($A$4,$A$5:$BR$24,BG1,FALSE) -> 7.6950354
A5: 250 | B5: 11.18 | C5: 17.717 | D5: 0 | E5: 0.1 | F5: 0.281 | G5: 0.984 | M5: =Y5*0.9 -> 10.557 | N5: 90 | O5: 4 | U5: 8.122 | X5: =B5*0.75 -> 8.385 | Y5: 11.73 | AA5: =B5*0.05 -> 0.559 | AB5: =B5*0.6 -> 6.708 | AC5: =B5*0.11 -> 1.2298 | AD5: =B5*0.11 -> 1.2298 | AE5: 0.059 | AF5: =$B5*0.22 -> 2.4596 | AG5: =$B5*0.25 -> 2.795 | AH5: =$B5*0.014 -> 0.15652 | AI5: =$B5*0.006 -> 0.06708 | AJ5: =B5*0.08 -> 0.8944 | AK5: 65 | AL5: =B5*0.62 -> 6.9316 | AW5: 2.224 | BB5: =$B5*0.39 -> 4.3602 | BC5: =BC7-0.03 -> 0.618 | BD5: =$B5*1.4 -> 15.652 | BE5: =$B5*0.55 -> 6.149 | BF5: =$B5*0.91 -> 10.1738 | BG5: 5.59 | BI5: 1.403 | BJ5: =BI5+E5+U5+AW5 -> 11.849 | BK5: =10+BJ5+2.5+2.34+0.5 -> 27.189 | BL5: =10+BJ5+2+1.528 -> 25.377 | BM5: =ROUNDUP(BK5,0) -> 28 | BN5: =ROUNDUP(BL5,0) -> 26 | BO5: =ROUNDUP(10+BJ5+1,0) -> 23 | BP5: =BO5+2 -> 25 | BQ5: =ROUNDUP(10.476*2+C5+1.5*2,0) -> 42 | BR5: =ROUNDUP((4.049+1)*2+C5,0) -> 28
A6: 25 | B6: =5.709*2 -> 11.418 | C6: 18.701 | D6: 0 | E6: 0.1 | M6: =5.059*2 -> 10.118 | N6: 60 | O6: 6 | U6: 9.402 | X6: =4.528*2 -> 9.056 | Y6: =5.453*2 -> 10.906 | AA6: =B6*0.05 -> 0.5709 | AB6: =B6*0.6 -> 6.8508 | AC6: =B6*0.11 -> 1.25598 | AD6: =B6*0.11 -> 1.25598 | AE6: 0.059 | AF6: =$B6*0.22 -> 2.51196 | AG6: =$B6*0.25 -> 2.8545 | AH6: =$B6*0.014 -> 0.159852 | AI6: =B6*0.006 -> 0.068508 | AJ6: =B6*0.08 -> 0.91344 | AK6: 65 | AL6: =B6*0.62 -> 7.07916 | AW6: 1.181 | BB6: =$B6*0.39 -> 4.45302 | BC6: =BC7-0.03 -> 0.618 | BD6: =$B6*1.4 -> 15.9852 | BE6: =$B6*0.55 -> 6.2799 | BF6: =$B6*0.91 -> 10.39038 | BG6: 5.59 | BI6: 1.403 | BJ6: =BI6+E6+U6+AW6 -> 12.086 | BK6: =10+BJ6+2.5+2.34+0.5 -> 27.426 | BL6: =10+BJ6+2+1.528 -> 25.614 | BM6: =ROUNDUP(BK6,0) -> 28 | BN6: =ROUNDUP(BL6,0) -> 26 | BO6: =ROUNDUP(10+BJ6+1,0) -> 24 | BP6: =BO6+2 -> 26 | BQ6: =ROUNDUP(10.476*2+C6+1.5*2,0) -> 43 | BR6: =ROUNDUP((4.049+1)*2+C6,0) -> 29
A7: 280 | B7: 12.56 | C7: 18.701 | D7: 0 | E7: 0.1 | M7: =Y7*0.9 -> 11.5155 | N7: 90 | O7: 4 | U7: 9.402 | X7: =B7*0.75 -> 9.42 | Y7: 12.795 | AA7: =B7*0.05 -> 0.628 | AB7: =B7*0.6 -> 7.536 | AC7: =B7*0.11 -> 1.3816 | AD7: =B7*0.11 -> 1.3816 | AE7: 0.059 | AF7: =$B7*0.22 -> 2.7632 | AG7: =$B7*0.25 -> 3.14 | AH7: =$B7*0.014 -> 0.17584 | AI7: =B7*0.006 -> 0.07536 | AJ7: =B7*0.08 -> 1.0048 | AK7: 65 | AL7: =B7*0.62 -> 7.7872 | AW7: 1.181 | BB7: =$B7*0.39 -> 4.8984 | BC7: =BC8-0.03 -> 0.648 | BD7: =$B7*1.4 -> 17.584 | BE7: =$B7*0.55 -> 6.908 | BF7: =$B7*0.91 -> 11.4296 | BG7: 5.59 | BI7: 1.403 | BJ7: =BI7+E7+U7+AW7 -> 12.086 | BK7: =10+BJ7+2.5+2.34+0.5 -> 27.426 | BL7: =10+BJ7+2+1.528 -> 25.614 | BM7: =ROUNDUP(BK7,0) -> 28 | BN7: =ROUNDUP(BL7,0) -> 26 | BO7: =ROUNDUP(10+BJ7+1,0) -> 24 | BP7: =BO7+2 -> 26 | BQ7: =ROUNDUP(10.476*2+C7+1.5*2,0) -> 43 | BR7: =ROUNDUP((4.049+1)*2+C7,0) -> 29
A8: 310 | B8: 14.17 | C8: 19.685 | D8: 0.591 | E8: 0.118 | F8: 0.433 | G8: 0.984 | H8: 2 | I8: 17.717 | J8: 2.215 | K8: 3.551 | L8: 1.89 | M8: =Y8*0.9 -> 12.402 | N8: 90 | O8: 4 | Q8: 2.48 | R8: 1.414 | U8: 10.177 | V8: 16.535 | W8: 1.181 | X8: =B8*0.75 -> 10.6275 | Y8: 13.78 | AA8: =B8*0.05 -> 0.7085 | AB8: =B8*0.6 -> 8.502 | AC8: =B8*0.11 -> 1.5587 | AD8: =B8*0.11 -> 1.5587 | AE8: 0.059 | AF8: =$B8*0.22 -> 3.1174 | AG8: =$B8*0.25 -> 3.5425 | AH8: =$B8*0.014 -> 0.19838 | AI8: =B8*0.006 -> 0.08502 | AJ8: =B8*0.08 -> 1.1336 | AK8: 65 | AL8: =B8*0.62 -> 8.7854 | AM8: 14.173 | AN8: 5.669 | AO8: 5.435 | AQ8: 0.887 | AR8: 0.354 | AS8: 0.969 | AT8: 0.039 | AU8: 5.956 | AV8: =4.721*2 -> 9.442 | AW8: 2.736 | AX8: =4.429*2 -> 8.858 | AY8: 9.128 | AZ8: 9.173 | BA8: 0.45 | BB8: =$B8*0.39 -> 5.5263 | BC8: =BC10-0.03 -> 0.678 | BD8: =$B8*1.4 -> 19.838 | BE8: =$B8*0.55 -> 7.7935 | BF8: =$B8*0.91 -> 12.8947 | BG8: 5.59 | BI8: 1.403 | BJ8: =BI8+E8+U8+AW8 -> 14.434 | BK8: =10+BJ8+2.5+2.34+0.5 -> 29.774 | BL8: =10+BJ8+2+1.528 -> 27.962 | BM8: =ROUNDUP(BK8,0) -> 30 | BN8: =ROUNDUP(BL8,0) -> 28 | BO8: =ROUNDUP(10+BJ8+1,0) -> 26 | BP8: =BO8+2 -> 28 | BQ8: =ROUNDUP(10.476*2+C8+1.5*2,0) -> 44 | BR8: =ROUNDUP((4.049+1)*2+C8,0) -> 30
A9: 31 | B9: =7.087*2 -> 14.174 | C9: 19.685 | D9: 0.591 | E9: 0.118 | F9: 0.433 | G9: 0.984 | H9: 2 | I9: 17.717 | J9: 2.215 | K9: 3.551 | L9: 1.89 | M9: =6.24*2 -> 12.48 | N9: 90 | O9: 8 | Q9: 2.48 | R9: 1.414 | U9: 10.177 | V9: 16.535 | W9: 1.181 | X9: =5.709*2 -> 11.418 | Y9: =6.752*2 -> 13.504 | AA9: =B9*0.05 -> 0.7087 | AB9: =B9*0.6 -> 8.5044 | AC9: =B9*0.11 -> 1.55914 | AD9: =B9*0.11 -> 1.55914 | AE9: 0.059 | AF9: =$B9*0.22 -> 3.11828 | AG9: =$B9*0.25 -> 3.5435 | AH9: =$B9*0.014 -> 0.198436 | AI9: =B9*0.006 -> 0.085044 | AJ9: =B9*0.08 -> 1.13392 | AK9: 65 | AL9: =B9*0.62 -> 8.78788 | AM9: 14.173 | AN9: 5.669 | AO9: 5.435 | AQ9: 0.887 | AR9: 0.354 | AS9: 0.969 | AT9: 0.039 | AU9: 5.956 | AV9: =4.721*2 -> 9.442 | AX9: =4.429*2 -> 8.858 | AY9: 9.128 | AZ9: 9.173 | BA9: 0.45 | BB9: =$B9*0.39 -> 5.52786 | BC9: =BC8 -> 0.678 | BD9: =$B9*1.4 -> 19.8436 | BE9: =$B9*0.55 -> 7.7957 | BF9: =$B9*0.91 -> 12.89834 | BG9: 5.59 | BI9: 1.403 | BJ9: =BI9+E9+U9+AW9 -> 11.698 | BK9: =10+BJ9+2.5+2.34+0.5 -> 27.038 | BL9: =10+BJ9+2+1.528 -> 25.226 | BM9: =ROUNDUP(BK9,0) -> 28 | BN9: =ROUNDUP(BL9,0) -> 26 | BO9: =ROUNDUP(10+BJ9+1,0) -> 23 | BP9: =BO9+2 -> 25 | BQ9: =ROUNDUP(10.476*2+C9+1.5*2,0) -> 44 | BR9: =ROUNDUP((4.049+1)*2+C9,0) -> 30
A10: 355 | B10: 15.91 | C10: 19.685 | D10: 0.591 | E10: 0.108 | M10: =Y10*0.9 -> 13.1103 | N10: 90 | O10: 4 | U10: 11.196 | X10: =B10*0.75 -> 11.9325 | Y10: 14.567 | AA10: =B10*0.05 -> 0.7955 | AB10: =B10*0.6 -> 9.546 | AC10: =B10*0.11 -> 1.7501 | AD10: =B10*0.11 -> 1.7501 | AE10: 0.059 | AF10: =$B10*0.22 -> 3.5002 | AG10: =$B10*0.25 -> 3.9775 | AH10: =$B10*0.014 -> 0.22274 | AI10: =B10*0.006 -> 0.09546 | AJ10: =B10*0.08 -> 1.2728 | AK10: 65 | AL10: =B10*0.62 -> 9.8642 | AW10: 2.832 | BB10: =$B10*0.39 -> 6.2049 | BC10: =BC12-0.03 -> 0.708 | BD10: =$B10*1.4 -> 22.274 | BE10: =$B10*0.55 -> 8.7505 | BF10: =$B10*0.91 -> 14.4781 | BG10: 6.513878 | BI10: 1.403 | BJ10: =BI10+E10+U10+AW10 -> 15.539 | BK10: =10+BJ10+2.5+2.34+0.5 -> 30.879 | BL10: =10+BJ10+2+1.528 -> 29.067 | BM10: =ROUNDUP(BK10,0) -> 31 | BN10: =ROUNDUP(BL10,0) -> 30 | BO10: =ROUNDUP(10+BJ10+1,0) -> 27 | BP10: =BO10+2 -> 29 | BQ10: =ROUNDUP(10.476*2+C10+1.5*2,0) -> 44 | BR10: =ROUNDUP((4.049+1)*2+C10,0) -> 30
A11: 35 | B11: =7.992*2 -> 15.984 | C11: 19.685 | D11: 0.591 | E11: 0.108 | M11: =6.929*2 -> 13.858 | N11: 90 | O11: 8 | U11: 11.196 | X11: =6.496*2 -> 12.992 | Y11: =7.441*2 -> 14.882 | AA11: =B11*0.05 -> 0.7992 | AB11: =B11*0.6 -> 9.5904 | AC11: =B11*0.11 -> 1.75824 | AD11: =B11*0.11 -> 1.75824 | AE11: 0.059 | AF11: =$B11*0.22 -> 3.51648 | AG11: =$B11*0.25 -> 3.996 | AH11: =$B11*0.014 -> 0.223776 | AI11: =B11*0.006 -> 0.095904 | AJ11: =B11*0.08 -> 1.27872 | AK11: 65 | AL11: =B11*0.62 -> 9.91008 | AW11: 2.832 | BB11: =$B11*0.39 -> 6.23376 | BC11: =BC14-0.03 -> 0.738 | BD11: =$B11*1.4 -> 22.3776 | BE11: =$B11*0.55 -> 8.7912 | BF11: =$B11*0.91 -> 14.54544 | BG11: 6.513878 | BI11: 1.403 | BJ11: =BI11+E11+U11+AW11 -> 15.539 | BK11: =10+BJ11+2.5+2.34+0.5 -> 30.879 | BL11: =10+BJ11+2+1.528 -> 29.067 | BM11: =ROUNDUP(BK11,0) -> 31 | BN11: =ROUNDUP(BL11,0) -> 30 | BO11: =ROUNDUP(10+BJ11+1,0) -> 27 | BP11: =BO11+2 -> 29 | BQ11: =ROUNDUP(10.476*2+C11+1.5*2,0) -> 44 | BR11: =ROUNDUP((4.049+1)*2+C11,0) -> 30
A12: 400 | B12: 17.91 | C12: 21.685 | D12: 0.591 | E12: 0.108 | M12: =Y12*0.9 -> 14.634 | N12: 60 | O12: 6 | U12: 12.64 | X12: =B12*0.75 -> 13.4325 | Y12: 16.26 | AA12: =B12*0.05 -> 0.8955 | AB12: =B12*0.6 -> 10.746 | AC12: =B12*0.11 -> 1.9701 | AD12: =B12*0.11 -> 1.9701 | AE12: 0.059 | AF12: =$B12*0.22 -> 3.9402 | AG12: =$B12*0.25 -> 4.4775 | AH12: =$B12*0.014 -> 0.25074 | AI12: =B12*0.006 -> 0.10746 | AJ12: =B12*0.08 -> 1.4328 | AK12: 65 | AL12: =B12*0.62 -> 11.1042 | AW12: 2.667 | BB12: =$B12*0.39 -> 6.9849 | BC12: =BC14-0.03 -> 0.738 | BD12: =$B12*1.4 -> 25.074 | BE12: =$B12*0.55 -> 9.8505 | BF12: =$B12*0.91 -> 16.2981 | BG12: 7.2855315 | BI12: 1.403 | BJ12: =BI12+E12+U12+AW12 -> 16.818 | BK12: =10+BJ12+2.5+2.34+0.5 -> 32.158 | BL12: =10+BJ12+2+1.528 -> 30.346 | BM12: =ROUNDUP(BK12,0) -> 33 | BN12: =ROUNDUP(BL12,0) -> 31 | BO12: =ROUNDUP(10+BJ12+1,0) -> 28 | BP12: =BO12+2 -> 30 | BQ12: =ROUNDUP(10.476*2+C12+1.5*2,0) -> 46 | BR12: =ROUNDUP((4.049+1)*2+C12,0) -> 32
A13: 40 | B13: =8.985*2 -> 17.97 | C13: 21.685 | D13: 0.591 | E13: 0.108 | M13: =7.717*2 -> 15.434 | N13: 90 | O13: 8 | U13: 12.64 | X13: =7.283*2 -> 14.566 | Y13: =8.228*2 -> 16.456 | AA13: =B13*0.05 -> 0.8985 | AB13: =B13*0.6 -> 10.782 | AC13: =B13*0.11 -> 1.9767 | AD13: =B13*0.11 -> 1.9767 | AE13: 0.059 | AF13: =$B13*0.22 -> 3.9534 | AG13: =$B13*0.25 -> 4.4925 | AH13: =$B13*0.014 -> 0.25158 | AI13: =B13*0.006 -> 0.10782 | AJ13: =B13*0.08 -> 1.4376 | AK13: 65 | AL13: =B13*0.62 -> 11.1414 | AW13: 2.667 | BB13: =$B13*0.39 -> 7.0083 | BC13: =BC16-0.03 -> 0.768 | BD13: =$B13*1.4 -> 25.158 | BE13: =$B13*0.55 -> 9.8835 | BF13: =$B13*0.91 -> 16.3527 | BG13: 7.2855315 | BI13: 1.403 | BJ13: =BI13+E13+U13+AW13 -> 16.818 | BK13: =10+BJ13+2.5+2.34+0.5 -> 32.158 | BL13: =10+BJ13+2+1.528 -> 30.346 | BM13: =ROUNDUP(BK13,0) -> 33 | BN13: =ROUNDUP(BL13,0) -> 31 | BO13: =ROUNDUP(10+BJ13+1,0) -> 28 | BP13: =BO13+2 -> 30 | BQ13: =ROUNDUP(10.476*2+C13+1.5*2,0) -> 46 | BR13: =ROUNDUP((4.049+1)*2+C13,0) -> 32
A14: 450 | B14: 19.88 | C14: 24.803 | D14: 0.591 | E14: 0.12 | F14: 0.433 | G14: 0.984 | H14: 3 | I14: 11.417 | J14: 3.967 | K14: 3.14 | L14: 1.89 | M14: =Y14*0.9 -> 17.0082 | N14: 60 | O14: 6 | Q14: 2.48 | R14: 1.414 | S14: 3.14 | T14: 4.912 | U14: 14.083 | V14: 20.524 | W14: 1.181 | X14: =B14*0.75 -> 14.91 | Y14: 18.898 | Z14: 6.63 | AA14: =B14*0.05 -> 0.994 | AB14: =B14*0.6 -> 11.928 | AC14: =B14*0.11 -> 2.1868 | AD14: =B14*0.11 -> 2.1868 | AE14: 0.079 | AF14: =$B14*0.22 -> 4.3736 | AG14: =$B14*0.25 -> 4.97 | AH14: =$B14*0.014 -> 0.27832 | AI14: =B14*0.006 -> 0.11928 | AJ14: =B14*0.08 -> 1.5904 | AK14: 65 | AL14: =B14*0.62 -> 12.3256 | AM14: 19.882 | AN14: 7.303 | AO14: 7.394 | AQ14: 1.135 | AR14: 0.472 | AS14: 2.132 | AT14: 0.393 | AU14: 9.211 | AV14: 12 | AW14: 4.376 | AX14: 10.341 | AY14: 10.706 | AZ14: 11.08 | BA14: 0.301 | BB14: =$B14*0.39 -> 7.7532 | BC14: 0.768 | BD14: =$B14*1.4 -> 27.832 | BE14: =$B14*0.55 -> 10.934 | BF14: =$B14*0.91 -> 18.0908 | BG14: 7.6950354 | BI14: 1.403 | BJ14: =BI14+E14+U14+AW14 -> 19.982 | BK14: =10+BJ14+2.5+2.34+0.5 -> 35.322 | BL14: =10+BJ14+2+1.528 -> 33.51 | BM14: =ROUNDUP(BK14,0) -> 36 | BN14: =ROUNDUP(BL14,0) -> 34 | BO14: =ROUNDUP(10+BJ14+1,0) -> 31 | BP14: =BO14+2 -> 33 | BQ14: =ROUNDUP(10.476*2+C14+1.5*2,0) -> 49 | BR14: =ROUNDUP((4.049+1)*2+C14,0) -> 35
A15: 45 | B15: =10.127*2 -> 20.254 | C15: 24.803 | D15: 0.591 | E15: 0.12 | F15: 0.433 | G15: 0.984 | H15: 3 | I15: 11.417 | J15: 3.967 | K15: 3.14 | L15: 1.89 | M15: =8.622*2 -> 17.244 | N15: 90 | O15: 8 | Q15: 2.48 | R15: 1.414 | S15: 3.14 | T15: 4.912 | U15: 14.083 | V15: 20.524 | W15: 1.181 | X15: =7.972*2 -> 15.944 | Y15: =9.134*2 -> 18.268 | Z15: 6.63 | AA15: =B15*0.05 -> 1.0127 | AB15: =B15*0.6 -> 12.1524 | AC15: =B15*0.11 -> 2.22794 | AD15: =B15*0.11 -> 2.22794 | AE15: 0.079 | AF15: =$B15*0.22 -> 4.45588 | AG15: =$B15*0.25 -> 5.0635 | AH15: =$B15*0.014 -> 0.283556 | AI15: =B15*0.006 -> 0.121524 | AJ15: =B15*0.08 -> 1.62032 | AK15: 65 | AL15: =B15*0.62 -> 12.55748 | AM15: 19.882 | AN15: 7.303 | AO15: 7.394 | AQ15: 1.135 | AR15: 0.472 | AS15: 2.132 | AT15: 0.393 | AU15: 9.211 | AV15: 12 | AW15: 4.376 | AX15: 10.341 | AY15: 10.706 | AZ15: 11.08 | BA15: 0.301 | BB15: =$B15*0.39 -> 7.89906 | BC15: 0.768 | BD15: =$B15*1.4 -> 28.3556 | BE15: =$B15*0.55 -> 11.1397 | BF15: =$B15*0.91 -> 18.43114 | BG15: 7.6950354 | BI15: 1.403 | BJ15: =BI15+E15+U15+AW15 -> 19.982 | BK15: =10+BJ15+2.5+2.34+0.5 -> 35.322 | BL15: =10+BJ15+2+1.528 -> 33.51 | BM15: =ROUNDUP(BK15,0) -> 36 | BN15: =ROUNDUP(BL15,0) -> 34 | BO15: =ROUNDUP(10+BJ15+1,0) -> 31 | BP15: =BO15+2 -> 33 | BQ15: =ROUNDUP(10.476*2+C15+1.5*2,0) -> 49 | BR15: =ROUNDUP((4.049+1)*2+C15,0) -> 35
A16: 500 | B16: 22.28 | C16: 26.76 | D16: 0.625 | E16: 0.118 | M16: =Y16*0.9 -> 16.6536 | N16: 60 | O16: 6 | U16: 15.571 | X16: =B16*0.7 -> 15.596 | Y16: 18.504 | AA16: =B16*0.05 -> 1.114 | AB16: =B16*0.6 -> 13.368 | AC16: =B16*0.11 -> 2.4508 | AD16: =B16*0.11 -> 2.4508 | AE16: 0.079 | AF16: =$B16*0.22 -> 4.9016 | AG16: =$B16*0.25 -> 5.57 | AH16: =$B16*0.014 -> 0.31192 | AI16: =B16*0.006 -> 0.13368 | AJ16: =B16*0.08 -> 1.7824 | AK16: 65 | AL16: =B16*0.62 -> 13.8136 | AW16: 4.374 | BB16: =$B16*0.39 -> 8.6892 | BC16: =BC14+0.03 -> 0.798 | BD16: =$B16*1.4 -> 31.192 | BE16: =$B16*0.55 -> 12.254 | BF16: =$B16*0.91 -> 20.2748 | BG16: 8.6850394 | BI16: 1.403 | BJ16: =BI16+E16+U16+AW16 -> 21.466 | BK16: =10+BJ16+2.5+2.34+0.5 -> 36.806 | BL16: =10+BJ16+2+1.528 -> 34.994 | BM16: =ROUNDUP(BK16,0) -> 37 | BN16: =ROUNDUP(BL16,0) -> 35 | BO16: =ROUNDUP(10+BJ16+1,0) -> 33 | BP16: =BO16+2 -> 35 | BQ16: =ROUNDUP(10.476*2+C16+1.5*2,0) -> 51 | BR16: =ROUNDUP((4.049+1)*2+C16,0) -> 37
A17: 50 | B17: =11.382*2 -> 22.764 | C17: 26.76 | D17: 0.625 | E17: 0.118 | M17: =9.606*2 -> 19.212 | N17: 90 | O17: 4 | U17: 15.571 | X17: =9.055*2 -> 18.11 | Y17: =10.118*2 -> 20.236 | AA17: =B17*0.05 -> 1.1382 | AB17: =B17*0.6 -> 13.6584 | AC17: =B17*0.11 -> 2.50404 | AD17: =B17*0.11 -> 2.50404 | AE17: 0.079 | AF17: =$B17*0.22 -> 5.00808 | AG17: =$B17*0.25 -> 5.691 | AH17: =$B17*0.014 -> 0.318696 | AI17: =B17*0.006 -> 0.136584 | AJ17: =B17*0.08 -> 1.82112 | AK17: 65 | AL17: =B17*0.62 -> 14.11368 | AW17: 4.374 | BB17: =$B17*0.39 -> 8.87796 | BC17: =BC15+0.03 -> 0.798 | BD17: =$B17*1.4 -> 31.8696 | BE17: =$B17*0.55 -> 12.5202 | BF17: =$B17*0.91 -> 20.71524 | BG17: 8.6850394 | BI17: 1.403 | BJ17: =BI17+E17+U17+AW17 -> 21.466 | BK17: =10+BJ17+2.5+2.34+0.5 -> 36.806 | BL17: =10+BJ17+2+1.528 -> 34.994 | BM17: =ROUNDUP(BK17,0) -> 37 | BN17: =ROUNDUP(BL17,0) -> 35 | BO17: =ROUNDUP(10+BJ17+1,0) -> 33 | BP17: =BO17+2 -> 35 | BQ17: =ROUNDUP(10.476*2+C17+1.5*2,0) -> 51 | BR17: =ROUNDUP((4.049+1)*2+C17,0) -> 37
A18: 560 | B18: 25.04 | C18: 31.496 | D18: 0.591 | E18: 0.108 | F18: 0.433 | G18: 0.984 | H18: 3 | I18: 14.764 | J18: 5.157 | K18: 4.33 | L18: 1.89 | M18: =Y18*0.9 -> 18.252 | N18: 60 | O18: 6 | Q18: 2.48 | R18: 1.414 | S18: 3.14 | T18: 4.912 | U18: 17.911 | V18: 24.803 | W18: 1.181 | X18: =B18*0.7 -> 17.528 | Y18: 20.28 | Z18: 6.63 | AA18: =B18*0.05 -> 1.252 | AB18: =B18*0.6 -> 15.024 | AC18: =B18*0.11 -> 2.7544 | AD18: =B18*0.11 -> 2.7544 | AE18: 0.079 | AF18: =$B18*0.22 -> 5.5088 | AG18: =$B18*0.25 -> 6.26 | AH18: =$B18*0.014 -> 0.35056 | AI18: =B18*0.006 -> 0.15024 | AJ18: =B18*0.08 -> 2.0032 | AK18: 65 | AL18: =B18*0.62 -> 15.5248 | AM18: 25.039 | AN18: 8.681 | AO18: 7.394 | AQ18: 1.135 | AR18: 0.472 | AS18: 2.006 | AT18: 0.197 | AU18: 9.225 | AV18: =6.353*2 -> 12.706 | AW18: 4.383 | AX18: 10.341 | AY18: 10.706 | AZ18: 11.08 | BA18: 0.301 | BB18: =$B18*0.39 -> 9.7656 | BC18: =BC16+0.03 -> 0.828 | BD18: =$B18*1.4 -> 35.056 | BE18: =$B18*0.55 -> 13.772 | BF18: =$B18*0.91 -> 22.7864 | BG18: 8.6792441 | BI18: 1.403 | BJ18: =BI18+E18+U18+AW18 -> 23.805 | BK18: =10+BJ18+2.5+2.34+0.5 -> 39.145 | BL18: =10+BJ18+2+1.528 -> 37.333 | BM18: =ROUNDUP(BK18,0) -> 40 | BN18: =ROUNDUP(BL18,0) -> 38 | BO18: =ROUNDUP(10+BJ18+1,0) -> 35 | BP18: =BO18+2 -> 37 | BQ18: =ROUNDUP(10.476*2+C18+1.5*2,0) -> 56 | BR18: =ROUNDUP((4.049+1)*2+C18,0) -> 42
A19: 56 | B19: =12.653*2 -> 25.306 | C19: 31.496 | D19: 0.591 | E19: 0.108 | F19: 0.433 | G19: 0.984 | H19: 3 | I19: 14.764 | J19: 5.157 | K19: 4.33 | L19: 1.89 | M19: =10.591*2 -> 21.182 | N19: 90 | O19: 8 | Q19: 2.48 | R19: 1.414 | S19: 3.14 | T19: 4.912 | U19: 17.911 | V19: 24.803 | W19: 1.181 | X19: =10.138*2 -> 20.276 | Y19: =11.102*2 -> 22.204 | Z19: 6.63 | AA19: =B19*0.05 -> 1.2653 | AB19: =B19*0.6 -> 15.1836 | AC19: =B19*0.11 -> 2.78366 | AD19: =B19*0.11 -> 2.78366 | AE19: 0.079 | AF19: =$B19*0.22 -> 5.56732 | AG19: =$B19*0.25 -> 6.3265 | AH19: =$B19*0.014 -> 0.354284 | AI19: =B19*0.006 -> 0.151836 | AJ19: =B19*0.08 -> 2.02448 | AK19: 65 | AL19: =B19*0.62 -> 15.68972 | AM19: 25.039 | AN19: 8.681 | AO19: 7.394 | AQ19: 1.135 | AR19: 0.472 | AS19: 2.006 | AT19: 0.197 | AU19: 9.225 | AV19: =6.353*2 -> 12.706 | AW19: 4.383 | AX19: 10.341 | AY19: 10.706 | AZ19: 11.08 | BA19: 0.301 | BB19: =$B19*0.39 -> 9.86934 | BC19: =BC17+0.03 -> 0.828 | BD19: =$B19*1.4 -> 35.4284 | BE19: =$B19*0.55 -> 13.9183 | BF19: =$B19*0.91 -> 23.02846 | BG19: 8.6792441 | BI19: 1.403 | BJ19: =BI19+E19+U19+AW19 -> 23.805 | BK19: =10+BJ19+2.5+2.34+0.5 -> 39.145 | BL19: =10+BJ19+2+1.528 -> 37.333 | BM19: =ROUNDUP(BK19,0) -> 40 | BN19: =ROUNDUP(BL19,0) -> 38 | BO19: =ROUNDUP(10+BJ19+1,0) -> 35 | BP19: =BO19+2 -> 37 | BQ19: =ROUNDUP(10.476*2+C19+1.5*2,0) -> 56 | BR19: =ROUNDUP((4.049+1)*2+C19,0) -> 42
A20: 630 | B20: 28.19 | C20: 31.496 | D20: 0.787 | E20: 0.118 | F20: 0.433 | G20: 1.969 | M20: =Y20*0.9 -> 22.4649 | N20: 60 | O20: 6 | U20: 22.323 | X20: =B20*0.75 -> 21.1425 | Y20: 24.961 | AA20: =B20*0.05 -> 1.4095 | AB20: =B20*0.6 -> 16.914 | AC20: =B20*0.11 -> 3.1009 | AD20: =B20*0.11 -> 3.1009 | AE20: 0.079 | AF20: =$B20*0.22 -> 6.2018 | AG20: =$B20*0.25 -> 7.0475 | AH20: =$B20*0.014 -> 0.39466 | AI20: =B20*0.006 -> 0.16914 | AJ20: =B20*0.08 -> 2.2552 | AK20: 65 | AL20: =B20*0.62 -> 17.4778 | AW20: 5.236 | BB20: =$B20*0.39 -> 10.9941 | BC20: =BC18+0.03 -> 0.858 | BD20: =$B20*1.4 -> 39.466 | BE20: =$B20*0.55 -> 15.5045 | BF20: =$B20*0.91 -> 25.6529 | BG20: 12.22265 | BI20: 1.403 | BJ20: =BI20+E20+U20+AW20 -> 29.08 | BK20: =10+BJ20+2.5+2.34+0.5 -> 44.42 | BL20: =10+BJ20+2+1.528 -> 42.608 | BM20: =ROUNDUP(BK20,0) -> 45 | BN20: =ROUNDUP(BL20,0) -> 43 | BO20: =ROUNDUP(10+BJ20+1,0) -> 41 | BP20: =BO20+2 -> 43 | BQ20: =ROUNDUP(10.476*2+C20+1.5*2,0) -> 56 | BR20: =ROUNDUP((4.049+1)*2+C20,0) -> 42
A21: 63 | B21: =14.162*2 -> 28.324 | C21: 31.496 | D21: 0.787 | E21: 0.118 | F21: 0.433 | G21: 1.969 | M21: =11.811*2 -> 23.622 | N21: 90 | O21: 12 | U21: 22.323 | X21: =11.417*2 -> 22.834 | Y21: =12.48*2 -> 24.96 | AA21: =B21*0.05 -> 1.4162 | AB21: =B21*0.6 -> 16.9944 | AC21: =B21*0.11 -> 3.11564 | AD21: =B21*0.11 -> 3.11564 | AE21: 0.079 | AF21: =$B21*0.22 -> 6.23128 | AG21: =$B21*0.25 -> 7.081 | AH21: =$B21*0.014 -> 0.396536 | AI21: =B21*0.006 -> 0.169944 | AJ21: =B21*0.08 -> 2.26592 | AK21: 65 | AL21: =B21*0.62 -> 17.56088 | AW21: 5.236 | BB21: =$B21*0.39 -> 11.04636 | BC21: =BC19+0.03 -> 0.858 | BD21: =$B21*1.4 -> 39.6536 | BE21: =$B21*0.55 -> 15.5782 | BF21: =$B21*0.91 -> 25.77484 | BG21: 12.22265 | BI21: 1.403 | BJ21: =BI21+E21+U21+AW21 -> 29.08 | BK21: =10+BJ21+2.5+2.34+0.5 -> 44.42 | BL21: =10+BJ21+2+1.528 -> 42.608 | BM21: =ROUNDUP(BK21,0) -> 45 | BN21: =ROUNDUP(BL21,0) -> 43 | BO21: =ROUNDUP(10+BJ21+1,0) -> 41 | BP21: =BO21+2 -> 43 | BQ21: =ROUNDUP(10.476*2+C21+1.5*2,0) -> 56 | BR21: =ROUNDUP((4.049+1)*2+C21,0) -> 42
A22: 710 | B22: 31.73 | C22: 37.795 | D22: 2 | E22: 0.118 | M22: =Y22*0.9 -> 25.5114 | N22: 60 | O22: 6 | U22: 24.272 | X22: =B22*0.75 -> 23.7975 | Y22: 28.346 | AA22: =B22*0.05 -> 1.5865 | AB22: =B22*0.6 -> 19.038 | AC22: =B22*0.11 -> 3.4903 | AD22: =B22*0.11 -> 3.4903 | AE22: 0.079 | AF22: =$B22*0.22 -> 6.9806 | AG22: =$B22*0.25 -> 7.9325 | AH22: =$B22*0.014 -> 0.44422 | AI22: =B22*0.006 -> 0.19038 | AJ22: =B22*0.08 -> 2.5384 | AK22: 65 | AL22: =B22*0.62 -> 19.6726 | AW22: 5.177 | BB22: =$B22*0.39 -> 12.3747 | BC22: =BC20+0.03 -> 0.888 | BD22: =$B22*1.4 -> 44.422 | BE22: =$B22*0.55 -> 17.4515 | BF22: =$B22*0.91 -> 28.8743 | BG22: 11.435256 | BI22: 2 | BJ22: =BI22+E22+U22+AW22 -> 31.567 | BK22: =10+BJ22+2.5+2.34+0.5 -> 46.907 | BL22: =10+BJ22+2+1.528 -> 45.095 | BM22: =ROUNDUP(BK22,0) -> 47 | BN22: =ROUNDUP(BL22,0) -> 46 | BO22: =ROUNDUP(10+BJ22+1,0) -> 43 | BP22: =BO22+2 -> 45 | BQ22: =ROUNDUP(10.476*2+C22+1.5*2,0) -> 62 | BR22: =ROUNDUP((4.049+1)*2+C22,0) -> 48
A23: 800 | B23: 35.79 | C23: 37.795 | D23: 1.083 | E23: 0.118 | F23: 0.433 | G23: 1.575 | M23: =Y23*0.9 -> 25.5114 | N23: 60 | O23: 6 | U23: 25.709 | X23: =B23*0.7 -> 25.053 | Y23: 28.346 | AA23: =B23*0.05 -> 1.7895 | AB23: =B23*0.6 -> 21.474 | AC23: =B23*0.11 -> 3.9369 | AD23: =B23*0.11 -> 3.9369 | AE23: 0.079 | AF23: =$B23*0.22 -> 7.8738 | AG23: =$B23*0.25 -> 8.9475 | AH23: =$B23*0.014 -> 0.50106 | AI23: =B23*0.006 -> 0.21474 | AJ23: =B23*0.08 -> 2.8632 | AK23: 65 | AL23: =B23*0.62 -> 22.1898 | AW23: 4.685 | BB23: =$B23*0.39 -> 13.9581 | BC23: =BC22+0.03 -> 0.918 | BD23: =$B23*1.4 -> 50.106 | BE23: =$B23*0.55 -> 19.6845 | BF23: =$B23*0.91 -> 32.5689 | BG23: 14.978563 | BI23: 1.403 | BJ23: =BI23+E23+U23+AW23 -> 31.915 | BK23: =10+BJ23+2.5+2.34+0.5 -> 47.255 | BL23: =10+BJ23+2+1.528 -> 45.443 | BM23: =ROUNDUP(BK23,0) -> 48 | BN23: =ROUNDUP(BL23,0) -> 46 | BO23: =ROUNDUP(10+BJ23+1,0) -> 43 | BP23: =BO23+2 -> 45 | BQ23: =ROUNDUP(10.476*2+C23+1.5*2,0) -> 62 | BR23: =ROUNDUP((4.049+1)*2+C23,0) -> 48
A24: 900 | B24: 39.61 | C24: 46.457 | D24: 1.299 | E24: 0.118 | M24: =Y24*0.9 -> 31.8897 | N24: 60 | O24: 6 | U24: 24.016 | X24: =B24*0.75 -> 29.7075 | Y24: 35.433 | AA24: =B24*0.05 -> 1.9805 | AB24: =B24*0.6 -> 23.766 | AC24: =B24*0.11 -> 4.3571 | AD24: =B24*0.11 -> 4.3571 | AE24: 0.079 | AF24: =$B24*0.22 -> 8.7142 | AG24: =$B24*0.25 -> 9.9025 | AH24: =$B24*0.014 -> 0.55454 | AI24: =B24*0.006 -> 0.23766 | AJ24: =B24*0.08 -> 3.1688 | AK24: 65 | AL24: =B24*0.62 -> 24.5582 | AW24: 4.882 | BB24: =$B24*0.39 -> 15.4479 | BC24: =BC23+0.03 -> 0.948 | BD24: =$B24*1.4 -> 55.454 | BE24: =$B24*0.55 -> 21.7855 | BF24: =$B24*0.91 -> 36.0451 | BG24: 14.584571 | BI24: 1.403 | BJ24: =BI24+E24+U24+AW24 -> 30.419 | BK24: =10+BJ24+2.5+2.34+0.5 -> 45.759 | BL24: =10+BJ24+2+1.528 -> 43.947 | BM24: =ROUNDUP(BK24,0) -> 46 | BN24: =ROUNDUP(BL24,0) -> 44 | BO24: =ROUNDUP(10+BJ24+1,0) -> 42 | BP24: =BO24+2 -> 44 | BQ24: =ROUNDUP(10.476*2+C24+1.5*2,0) -> 71 | BR24: =ROUNDUP((4.049+1)*2+C24,0) -> 57
M26: estimated values | P26: Darkened areas not used anymore
B39: 25,250,280,31,310,35,355,40,400,45,450,50,500,56,560,63,630,710,800,900

Sheet Fan Lookup2
D1: 1 | E1: 2 | F1: 3 | G1: 4 | H1: 5 | I1: 6 | J1: 7 | K1: 8 | L1: 9 | M1: 10 | N1: 11 | O1: 12 | P1: 13 | Q1: 14 | R1: 15 | S1: 16 | T1: 17 | U1: 18 | V1: 19 | W1: 20 | X1: 21 | Y1: 22 | Z1: 23 | AA1: 24 | AB1: 25 | AC1: 26 | AD1: 27 | AE1: 28 | AF1: 29 | AG1: 30 | AH1: 31 | AI1: 32 | AJ1: 33 | AK1: 34 | AL1: 35 | AM1: 36 | AN1: 37 | AO1: 38 | AP1: 39
B2: Fan Size | C2: Voltage | D2: Fan Model | E2: Inlet Plate H&W | F2: Mtr Plate H&W | G2: Total Length Inlet to back | H2: Btwn Plates | I2: Inlet Plate Flng | J2: Plate Thk | K2: Mtr Plate Flng | L2: Inlet Mnt Hole Qty | M2: Inlet Mnt Hole Spacing | N2: Inlet Mnt Hole Start | O2: Inlet Mnt Hole Size | P2: side hrdwr ext. | Q2: Frame hrdwr to side | R2: Frame hrdwr 1 spacing | S2: Frame hrdwr 2 spacing | T2: Frame hrdwr dia. | U2: Mtr dia. | V2: back of mtr to inlet face | W2: WD | X2: Frame style oval/angle | Y2: Collar style | Z2: non "W" back of mtr to inlet face | AA2: Locate WAGO Connector | AE2: Damper
E3: FAN_A | F3: FAN_T | G3: FAN_TL | H3: FAN_S | I3: FAN_B | J3: FAN_C | K3: FAN_U | L3: FAN_F | M3: FAN_G | N3: FAN_E | O3: FAN_D | P3: FAN_SD | Q3: FAN_H | R3: FAN_J | S3: FAN_I | T3: FAN_HD | U3: FAN_AW | V3: FAN_LG | W3: FAN_WD | X3: FAN_FS | Y3: FAN_CS | Z3: FAN_LG_orig | AA3: WAGO_Dist1 | AB3: WAGO_Dist2 | AC3: WAGO_Dist3 | AD3: WAGO_Dist4 | AE3: OpeningOS | AF3: DamperSize
D4: =IF(OR(KW=4.5,KW=8),LEFT('001-013'!S15,14),'001-013'!S15) -> EG1R-480-450-48 | E4: =VLOOKUP($D$4,$D5:$AP$127,E1,FALSE) -> 24.803 | F4: =VLOOKUP($D$4,$D5:$AP$127,F1,FALSE) -> 19.685 | G4: =VLOOKUP($D$4,$D5:$AP$127,G1,FALSE) -> 17.128 | H4: =VLOOKUP($D$4,$D5:$AP$127,H1,FALSE) -> 13.807 | I4: =VLOOKUP($D$4,$D5:$AP$127,I1,FALSE) -> 0.591 | J4: =VLOOKUP($D$4,$D5:$AP$127,J1,FALSE) -> 0.12 | K4: =VLOOKUP($D$4,$D5:$AP$127,K1,FALSE) -> 1.181 | L4: =VLOOKUP($D$4,$D5:$AP$127,L1,FALSE) -> 3 | ... AD4: =VLOOKUP($D$4,$D5:$AP$127,AD1,FALSE) -> 0 | AE4: =(('Excel Calc'!V8)-DamperSize)/2 -> -0.125 | AF4: =VLOOKUP(D4,D5:AF111,29,FALSE) -> 24.25
B5: 250 | C5: 380-480 | D5: EG1R-480-250-12 | E5: 15.75 | F5: 12.6 | G5: 10.45 | H5: 8.122 | I5: =J5+0.03 -> 0.13 | J5: 0.1 | K5: 1.181 | L5: 2 | M5: 13.78 | N5: =IF(L5=2,M5/2,M5) -> 6.89 | O5: 0.43 | P5: 0 | Q5: 2.195 | R5: 1.063 | S5: 3 | T5: 0.41 | U5: 6.5 | V5: =G5-I5+J5 -> 10.42 | W5: 11.18 | X5: 1 | Y5: 1 | Z5: 10.454 | AF5: 15.25
B6: 250 | C6: 200-240 | D6: EG1R-240-250-12 | E6: 15.75 | F6: 12.6 | G6: 10.45 | H6: 8.122 | I6: =J6+0.03 -> 0.13 | J6: 0.1 | K6: 1.181 | L6: 2 | M6: 13.78 | N6: =IF(L6=2,M6/2,M6) -> 6.89 | O6: 0.43 | P6: 0 | Q6: 2.195 | R6: 1.063 | S6: 3 | T6: 0.41 | U6: 6.5 | V6: =G6-I6+J6 -> 10.42 | W6: 11.18 | X6: 1 | Y6: 1 | Z6: 10.454 | AF6: 15.25
B7: 25 | D7: GR25C | E7: 15.748 | F7: 12.283 | G7: 10.233 | H7: 8.307 | I7: 0.394 | J7: 0.079 | K7: 0.63 | L7: 2 | M7: 14.449 | N7: =IF(L7=2,M7/2,M7) -> 7.2245 | O7: 0.43 | P7: 0 | Q7: 1.591 | R7: 3.008 | S7: 1.45 | T7: 0.41 | U7: 5.621 | V7: =G7 -> 10.233 | W7: =5.709*2 -> 11.418 | X7: 4 | Y7: 3 | AF7: 14
B8: 280 | C8: 380-480 | D8: EG1R-480-280-12 | E8: 15.75 | F8: 12.6 | G8: 11.805 | H8: 9.48 | I8: =J8+0.03 -> 0.13 | J8: 0.1 | K8: 1.181 | L8: 2 | M8: 13.78 | N8: =IF(L8=2,M8/2,M8) -> 6.89 | O8: 0.43 | P8: 0 | Q8: 2.1949 | R8: 1.063 | S8: 3 | T8: 0.41 | U8: 6.5 | V8: =G8-I8+J8 -> 11.775 | W8: 12.56 | X8: 1 | Y8: 1 | Z8: 11.813 | AF8: 15.25
B9: 280 | C9: 200-240 | D9: EG1R-240-280-12 | E9: 15.75 | F9: 12.6 | G9: 11.805 | H9: 9.48 | I9: =J9+0.03 -> 0.13 | J9: 0.1 | K9: 1.181 | L9: 2 | M9: 13.78 | N9: =IF(L9=2,M9/2,M9) -> 6.89 | O9: 0.43 | P9: 0 | Q9: 2.1949 | R9: 1.063 | S9: 3 | T9: 0.41 | U9: 6.5 | V9: =G9-I9+J9 -> 11.775 | W9: 12.56 | X9: 1 | Y9: 1 | Z9: 11.813 | AF9: 15.25
B10: 310 | C10: 380-480 | D10: EG1R-480-310-35 | E10: 19.69 | F10: 16.54 | G10: 13.5 | H10: 10.18 | I10: 0.591 | J10: 0.118 | K10: 1.181 | L10: 2 | M10: 17.72 | N10: =IF(L10=2,M10/2,M10) -> 8.86 | O10: 0.43 | P10: 0 | Q10: 2.215 | R10: 1.89 | S10: 3 | T10: 0.64 | U10: 8.3 | V10: =G10-I10+J10 -> 13.027 | W10: 14.17 | X10: 1 | Y10: 1 | Z10: 13.027 | AF10: 19.25
B11: 310 | C11: 200-240 | D11: EG1R-240-310-35 | E11: 19.69 | F11: 16.54 | G11: 13.5 | H11: 10.18 | I11: 0.591 | J11: 0.118 | K11: 1.181 | L11: 2 | M11: 17.72 | N11: =IF(L11=2,M11/2,M11) -> 8.86 | O11: 0.43 | P11: 0 | Q11: 2.215 | R11: 1.89 | S11: 3 | T11: 0.64 | U11: 8.3 | V11: =G11-I11+J11 -> 13.027 | W11: 14.17 | X11: 1 | Y11: 1 | Z11: 13.027 | AF11: 19.25
B12: 310G3_4.5 | C12: 200-240 | D12: EG1R-240-310-A | E12: 19.69 | F12: 18.14 | G12: 13.45 | H12: 10.58 | I12: -1 | J12: 0.12 | K12: 2.75 | L12: 3 | M12: 8.86 | N12: 8.86 | O12: 0.43 | P12: 0 | Q12: 2.215 | R12: 1.89 | S12: 3 | T12: 0.64 | U12: 8.3 | V12: =G12-I12+J12 -> 14.57 | W12: 14.17 | X12: 4 | Y12: 3.5 | AF12: =16.25+3 -> 19.25
B13: 310G3_4.5 | C13: 380-480 | D13: EG1R-480-310-A | E13: 19.69 | F13: 18.14 | G13: 13.45 | H13: 10.58 | I13: -1 | J13: 0.12 | K13: 2.75 | L13: 3 | M13: 8.86 | N13: 8.86 | O13: 0.43 | P13: 0 | Q13: 2.215 | R13: 1.89 | S13: 3 | T13: 0.64 | U13: 8.3 | V13: =G13-I13+J13 -> 14.57 | W13: 14.17 | X13: 4 | Y13: 3.5 | AF13: =16.25+3 -> 19.25
B14: 31 | D14: GR31C | E14: 18.504 | F14: 14.764 | G14: 11.614 | H14: 9.311 | I14: 0.591 | J14: 0.098 | K14: 0.787 | L14: 2 | M14: 17.087 | N14: =IF(L14=2,M14/2,M14) -> 8.5435 | O14: 0.43 | P14: 0 | Q14: 1.634 | R14: 2.867 | S14: 1.754 | T14: 0.64 | U14: 6.654 | V14: =G14 -> 11.614 | W14: =7.087*2 -> 14.174 | X14: 4 | Y14: 3 | AF14: 16.25
B15: 355 | C15: 380-480 | D15: EG1R-480-355-32 | E15: 19.69 | F15: 16.54 | G15: 14.4 | H15: 11.2 | I15: 0.591 | J15: 0.108 | K15: 1.181 | L15: 2 | M15: 17.72 | N15: =IF(L15=2,M15/2,M15) -> 8.86 | O15: 0.43 | P15: 0 | Q15: 2.103 | R15: 1.89 | S15: 3 | T15: 0.64 | U15: 9.2 | V15: =G15-I15+J15 -> 13.917 | W15: 15.91 | X15: 1 | Y15: 1 | Z15: 13.917 | AF15: 19.25
B16: 355 | C16: 200-240 | D16: EG1R-240-355-32 | E16: 19.69 | F16: 16.54 | G16: 14.4 | H16: 11.2 | I16: 0.591 | J16: 0.108 | K16: 1.181 | L16: 2 | M16: 17.72 | N16: =IF(L16=2,M16/2,M16) -> 8.86 | O16: 0.43 | P16: 0 | Q16: 2.103 | R16: 1.89 | S16: 3 | T16: 0.64 | U16: 9.2 | V16: =G16-I16+J16 -> 13.917 | W16: 15.91 | X16: 1 | Y16: 1 | Z16: 13.917 | AF16: 19.25
B17: 355G3_4.5 | C17: 200-240 | D17: EG1R-240-355-A | E17: 19.69 | F17: 18.14 | G17: 14.66 | H17: 11.79 | I17: -1 | J17: 0.12 | K17: 2.75 | L17: 3 | M17: 8.86 | N17: 8.86 | O17: 0.43 | P17: 0 | Q17: 2.27 | R17: 1.85 | S17: 3 | T17: 0.64 | U17: 9.2 | V17: =G17-I17+J17 -> 15.78 | W17: 15.91 | X17: 4 | Y17: 3.5 | AF17: =16.25+3 -> 19.25
B18: 355G3_4.5 | C18: 380-480 | D18: EG1R-480-355-A | E18: 19.69 | F18: 18.14 | G18: 14.66 | H18: 11.79 | I18: -1 | J18: 0.12 | K18: 2.75 | L18: 3 | M18: 8.86 | N18: 8.86 | O18: 0.43 | P18: 0 | Q18: 2.27 | R18: 1.85 | S18: 3 | T18: 0.64 | U18: 9.2 | V18: =G18-I18+J18 -> 15.78 | W18: 15.91 | X18: 4 | Y18: 3.5 | AF18: =16.25+3 -> 19.25
B19: 35 | D19: GR35C | E19: 19.685 | F19: 16.339 | G19: 12.441 | H19: 10.138 | I19: 0.591 | J19: 0.098 | K19: 0.984 | L19: 2 | M19: 18.504 | N19: =IF(L19=2,M19/2,M19) -> 9.252 | O19: 0.43 | P19: 0 | Q19: 1.516 | R19: 4.204 | S19: 1.754 | T19: 0.64 | U19: 6.654 | V19: =G19 -> 12.441 | W19: =7.992*2 -> 15.984 | X19: 4 | Y19: 3 | AF19: 16.25
B20: 400 | C20: 380-480 | D20: EG1R-480-400-48 | E20: 21.69 | F20: 16.54 | G20: 15.934 | H20: 12.59 | I20: 0.591 | J20: 0.108 | K20: 1.181 | L20: 2 | M20: 19.72 | N20: =IF(L20=2,M20/2,M20) -> 9.86 | O20: 0.43 | P20: 0 | Q20: 3.103 | R20: 1.89 | S20: 3 | T20: 0.64 | U20: 9.3 | V20: =G20-I20+J20 -> 15.451 | W20: 17.91 | X20: 1 | Y20: 1 | Z20: 15.451 | AF20: 21.25
B21: 400 | C21: 200-240 | D21: EG1R-240-400-48 | E21: 21.69 | F21: 16.54 | G21: 15.934 | H21: 12.59 | I21: 0.591 | J21: 0.108 | K21: 1.181 | L21: 2 | M21: 19.72 | N21: =IF(L21=2,M21/2,M21) -> 9.86 | O21: 0.43 | P21: 0 | Q21: 3.103 | R21: 1.89 | S21: 3 | T21: 0.64 | U21: 9.3 | V21: =G21-I21+J21 -> 15.451 | W21: 17.91 | X21: 1 | Y21: 1 | Z21: 15.451 | AF21: 21.25
B22: 400G3_4.5 | C22: 200-240 | D22: EG1R-240-400-A | E22: 19.69 | F22: 18.14 | G22: 15.81 | H22: 12.94 | I22: -1 | J22: 0.12 | K22: 2.75 | L22: 3 | M22: 8.86 | N22: 8.86 | O22: 0.43 | P22: 0 | Q22: 1.77 | R22: 1.85 | S22: 3 | T22: 0.64 | U22: 9.3 | V22: =G22-I22+J22 -> 16.93 | W22: 17.91 | X22: 4 | Y22: 3.5 | AF22: =16.25+3 -> 19.25
B23: 400G3_4.5 | C23: 380-480 | D23: EG1R-480-400-A | E23: 19.69 | F23: 18.14 | G23: 15.81 | H23: 12.94 | I23: -1 | J23: 0.12 | K23: 2.75 | L23: 3 | M23: 8.86 | N23: 8.86 | O23: 0.43 | P23: 0 | Q23: 1.77 | R23: 1.85 | S23: 3 | T23: 0.64 | U23: 9.3 | V23: =G23-I23+J23 -> 16.93 | W23: 17.91 | X23: 4 | Y23: 3.5 | AF23: =16.25+3 -> 19.25
B24: 40 | D24: GR40C | E24: 21.654 | F24: 18.11 | G24: 14.488 | H24: 11.614 | I24: 0.591 | J24: 0.118 | K24: 0.984 | L24: 2 | M24: 20.433 | N24: =IF(L24=2,M24/2,M24) -> 10.2165 | O24: 0.43 | P24: 0 | Q24: 1.555 | R24: 4.538 | S24: 1.977 | T24: 0.64 | U24: 8.953 | V24: =G24 -> 14.488 | W24: =8.985*2 -> 17.97 | X24: 4 | Y24: 3 | AF24: 18
B25: 450 | C25: 380-480 | D25: EG1R-480-450-48 | E25: 24.803 | F25: 19.685 | G25: 17.128 | H25: 13.807 | I25: 0.591 | J25: 0.12 | K25: 1.181 | L25: 3 | M25: 11.417 | N25: =IF(L25=2,M25/2,M25) -> 11.417 | O25: 0.43 | P25: 0 | Q25: 3.173 | R25: 1.89 | S25: 3 | T25: 0.64 | U25: 9.2 | V25: =G25-I25+J25 -> 16.657 | W25: 19.88 | X25: 1 | Y25: 1 | Z25: 16.657 | AF25: 24.25
B26: 450 | C26: 380-480 | D26: EG1R-480-450-68 | E26: 24.803 | F26: 20.5 | G26: 19.11 | H26: 14.083 | I26: 0.591 | J26: 0.12 | K26: 1.181 | L26: 3 | M26: 11.417 | N26: =IF(L26=2,M26/2,M26) -> 11.417 | O26: 0.43 | P26: 0 | Q26: 3.14 | R26: 1.17 | S26: 3.842 | T26: 0.64 | U26: 10.9 | V26: =G26-I26+J26 -> 18.639 | W26: 19.88 | X26: 2 | Y26: 1 | Z26: 18.639 | AF26: 24.25
B27: 450 | C27: 200-240 | D27: EG1R-240-450-48 | E27: 24.803 | F27: 19.685 | G27: 17.128 | H27: 13.807 | I27: 0.591 | J27: 0.12 | K27: 1.181 | L27: 3 | M27: 11.417 | N27: =IF(L27=2,M27/2,M27) -> 11.417 | O27: 0.43 | P27: 0 | Q27: 3.173 | R27: 1.89 | S27: 3 | T27: 0.64 | U27: 9.2 | V27: =G27-I27+J27 -> 16.657 | W27: 19.88 | X27: 1 | Y27: 1 | Z27: 16.657 | AF27: 24.25
B28: 450 | C28: 200-240 | D28: EG1R-240-450-68 | E28: 24.803 | F28: 20.5 | G28: 19.11 | H28: 14.083 | I28: 0.591 | J28: 0.12 | K28: 1.181 | L28: 3 | M28: 11.417 | N28: =IF(L28=2,M28/2,M28) -> 11.417 | O28: 0.43 | P28: 0 | Q28: 3.14 | R28: 1.17 | S28: 3.842 | T28: 0.64 | U28: 10.9 | V28: =G28-I28+J28 -> 18.639 | W28: 19.88 | X28: 2 | Y28: 1 | Z28: 18.639 | AF28: 24.25
B29: 450G3_4.5 | C29: 200-240 | D29: EG1R-240-450-A | E29: 24.8 | F29: 23.24 | G29: 17.34 | H29: 14.47 | I29: -1 | J29: 0.12 | K29: 2.75 | L29: 3 | M29: 11.415 | N29: 11.415 | O29: 0.43 | P29: 0 | Q29: 1.98 | R29: 1.85 | S29: 3 | T29: 0.64 | U29: 10.9 | V29: =G29-I29+J29 -> 18.46 | W29: 19.88 | X29: 4 | Y29: 3.5 | AF29: 24.25
B30: 450G3_4.5 | C30: 380-480 | D30: EG1R-480-450-A | E30: 24.8 | F30: 23.24 | G30: 17.34 | H30: 14.47 | I30: -1 | J30: 0.12 | K30: 2.75 | L30: 3 | M30: 11.415 | N30: 11.415 | O30: 0.43 | P30: 0 | Q30: 1.98 | R30: 1.85 | S30: 3 | T30: 0.64 | U30: 10.9 | V30: =G30-I30+J30 -> 18.46 | W30: 19.88 | X30: 4 | Y30: 3.5 | AF30: 24.25
B31: 450G3_8 | C31: 200-240 | D31: EG1R-240-450-B | E31: 24.8 | F31: 19.38 | G31: 21.1835 | H31: 17.348 | I31: -1 | J31: 0.135 | K31: 2.231 | L31: 3 | M31: 11.415 | N31: 11.415 | O31: 0.43 | P31: 0 | Q31: 2.455 | R31: 1.9 | S31: 3 | T31: 0.7756 | U31: 10.92 | V31: 21.1835 | W31: 20.86 | X31: 1.5 | Y31: 3.5 | AF31: 24.25
B32: 450G3_8 | C32: 380-480 | D32: EG1R-480-450-B | E32: 24.8 | F32: 19.38 | G32: 21.1835 | H32: 17.348 | I32: -1 | J32: 0.135 | K32: 2.231 | L32: 3 | M32: 11.415 | N32: 11.415 | O32: 0.43 | P32: 0 | Q32: 2.455 | R32: 1.9 | S32: 3 | T32: 0.7756 | U32: 10.92 | V32: 21.1835 | W32: 20.86 | X32: 1.5 | Y32: 3.5 | AF32: 24.25
B33: 45 | D33: GR45C | E33: 24.803 | F33: 20.315 | G33: 15.61 | H33: 12.736 | I33: 0.591 | J33: 0.118 | K33: 0.984 | L33: 2 | M33: 22.835 | N33: =IF(L33=2,M33/2,M33) -> 11.4175 | O33: 0.43 | P33: 0 | Q33: 1.909 | R33: 5.039 | S33: 1.977 | T33: 0.64 | U33: 8.953 | V33: =G33 -> 15.61 | W33: =10.127*2 -> 20.254 | X33: 4 | Y33: 3 | AF33: 21
B34: 500 | C34: 380-480 | D34: EG1R-480-500-48 | E34: 26.76 | F34: 20.87 | G34: 17.6151 | H34: 14.26 | I34: 0.625 | J34: 0.108 | K34: 1 | L34: 3 | M34: 12.396 | N34: =IF(L34=2,M34/2,M34) -> 12.396 | O34: 0.43 | P34: 0 | Q34: 3.475 | R34: 1.89 | S34: 3 | T34: 0.64 | U34: 9.2 | V34: =G34-I34+J34 -> 17.0981 | W34: 22.28 | X34: 1 | Y34: 1 | Z34: 17.0981 | AF34: 26.25
B35: 500 | C35: 380-480 | D35: EG1R-480-500-58 | E35: 26.76 | F35: 22.047 | G35: 20.904 | H35: 15.857 | I35: 0.591 | J35: 0.12 | K35: 1.181 | L35: 3 | M35: 12.412 | N35: =IF(L35=2,M35/2,M35) -> 12.412 | O35: 0.43 | P35: 0 | Q35: 3.341 | R35: 1.168 | S35: 3.841 | T35: 0.64 | U35: 10.7 | V35: =G35-I35+J35 -> 20.433 | W35: 22.28 | X35: 2 | Y35: 1 | Z35: 20.433 | AF35: 26.25
B36: 500 | C36: 200-240 | D36: EG1R-240-500-48 | E36: 26.76 | F36: 20.87 | G36: 17.6171 | H36: 14.26 | I36: 0.625 | J36: 0.108 | K36: 1 | L36: 3 | M36: 12.396 | N36: =IF(L36=2,M36/2,M36) -> 12.396 | O36: 0.43 | P36: 0 | Q36: 3.475 | R36: 1.89 | S36: 3 | T36: 0.64 | U36: 9.2 | V36: =G36-I36+J36 -> 17.1001 | W36: 22.28 | X36: 1 | Y36: 1 | Z36: 17.1001 | AF36: 26.25
B37: 500 | C37: 200-240 | D37: EG1R-240-500-58 | E37: 26.76 | F37: 22.047 | G37: 20.904 | H37: 15.857 | I37: 0.591 | J37: 0.12 | K37: 1.181 | L37: 3 | M37: 12.412 | N37: =IF(L37=2,M37/2,M37) -> 12.412 | O37: 0.43 | P37: 0 | Q37: 3.341 | R37: 1.168 | S37: 3.841 | T37: 0.64 | U37: 10.7 | V37: =G37-I37+J37 -> 20.433 | W37: 22.28 | X37: 2 | Y37: 1 | Z37: 20.433 | AF37: 26.25
B38: 500G3_4.5 | C38: 200-240 | D38: EG1R-240-500-A | E38: 24.8 | F38: 23.24 | G38: 18.58 | H38: 15.71 | I38: -1 | J38: 0.12 | K38: 2.75 | L38: 3 | M38: 11.415 | N38: 11.415 | O38: 0.43 | P38: 0 | Q38: 1.98 | R38: 1.85 | S38: 3 | T38: 0.64 | U38: 10.7 | V38: =G38-I38+J38 -> 19.7 | W38: 22.28 | X38: 4 | Y38: 3.5 | AF38: 24.25
B39: 500G3_4.5 | C39: 380-480 | D39: EG1R-480-500-A | E39: 24.8 | F39: 23.24 | G39: 18.58 | H39: 15.71 | I39: -1 | J39: 0.12 | K39: 2.75 | L39: 3 | M39: 11.415 | N39: 11.415 | O39: 0.43 | P39: 0 | Q39: 1.98 | R39: 1.85 | S39: 3 | T39: 0.64 | U39: 10.7 | V39: =G39-I39+J39 -> 19.7 | W39: 22.28 | X39: 4 | Y39: 3.5 | AF39: 24.25
B40: 500G3_8 | C40: 200-240 | D40: EG1R-240-500-B | E40: 24.8 | F40: 19.25 | G40: 23.7544 | H40: 19.957 | I40: -1 | J40: 0.135 | K40: 2.231 | L40: 3 | M40: 11.415 | N40: 11.415 | O40: 0.43 | P40: 0 | Q40: 2.308 | R40: 1.9 | S40: 3 | T40: 0.7756 | U40: 10.92 | V40: 23.7544 | W40: 23.03 | X40: 1.5 | Y40: 3.5 | AF40: 24.25
...

Sheet 001-013
B1: Page: 001-013 | G1: Edit Manual | K1: PRODUCT: Solution
B2: Title: ECM Fans Purchase Parts | K2: 001-013.xls | L2: Rel/Rev Date: 11-08-16
K3: Revision Level : New | L3: ECN Number : 16-9146
N14: =VLOOKUP(A15,A16:S318,14,FALSE) -> 96
A15: =IF(FANSIZE+0<100,CONCATENATE(FANSIZE+0,"_0_0"),CONCATENATE(FANSIZE+0,"_",MTRVOLT,"_",KW)) -> 450_460_3 | B15: EFFDATE | C15: INFFANTYPE | D15: FANSIZE | E15: VOLTAGE | F15: KW | G15: HP | H15: INLET GUARD/SCREEN | I15: PIEZORING | J15: PART_NUMBER | K15: Description (30 character max) | L15: Extended description 1 (40 character max) | M15: Extended description 2 (40 character max) | N15: Weight | O15: FLA | P15: Nominal RPM | Q15: Power Factor | R15: Efficiency | S15: =VLOOKUP(A15,A16:S318,19,FALSE) -> EG1R-480-450-48 | T15: Compare WAGO P/N to non-WAGO P/N | U15: FanVoltKW
A16: =CONCATENATE(D16,"_",E16,"_",F16) -> 250_460_1 | B16: 42583 | C16: PLENUMRADIPAC | D16: 250 | E16: 460 | F16: 1 | G16: =F16*1.34102 -> 1.34102 | H16: 0 | I16: YES | J16: 026-50033-001 | K16: EBM_250_380-480V_3PH_1KW | L16: WITHOUT_FINGER_INLET_GUARD | M16: EBM_PN:_EG1R-480-250-12 | N16: 22 | O16: 1.17 | P16: 3580 | Q16: 0.81 | R16: 87.6 | S16: =MID(M16,9,50) -> EG1R-480-250-12 | T16: =VLOOKUP(CONCATENATE(A16,"_W"),A16:S$318,19,FALSE) -> EG1R-480-250-11W | U16: 250_460_1
