Workbook
Name Construction: Data!$B$11
Name ERRORS: Data!$B$15
Name FAN_A: 'Fan Data'!$D$3
Name FAN_B: 'Fan Data'!$E$3
Name Fan_Data_Column_Names: 'Fan Data'!$C$3:$H$3
Name Fan_Data_Table: 'Fan Data'!$C$3:$H$25
Name FAN_DC: 'Fan Data'!$F$3
Name FAN_Q: 'Fan Data'!$G$3
Name FAN_X_LOCATION: Data!$B$7
Name FANDISCHARGELOC: Data!$B$6
Name FANSIZE: Data!$B$5
Name FanStndStrBasePadThk: Data!$G$4
Name FLOOR_CHAN_1_X_ARRAY_OFFSET: 'Channel Loc'!$D$6
Name FLOOR_CHAN_1_X_ARRAY_QTY: 'Channel Loc'!$E$6
Name FLOOR_CHAN_1_X_ARRAY_SPACING: 'Channel Loc'!$F$6
Name FLOOR_CHAN_1_Z_LOC: 'Channel Loc'!$C$6
Name FLOOR_CHAN_10_X_ARRAY_OFFSET: 'Channel Loc'!$D$15
Name FLOOR_CHAN_10_X_ARRAY_QTY: 'Channel Loc'!$E$15
Name FLOOR_CHAN_10_X_ARRAY_SPACING: 'Channel Loc'!$F$15
Name FLOOR_CHAN_10_Z_LOC: 'Channel Loc'!$C$15
Name FLOOR_CHAN_11_X_ARRAY_OFFSET: 'Channel Loc'!$D$16
Name FLOOR_CHAN_11_X_ARRAY_QTY: 'Channel Loc'!$E$16
Name FLOOR_CHAN_11_X_ARRAY_SPACING: 'Channel Loc'!$F$16
Name FLOOR_CHAN_11_Z_LOC: 'Channel Loc'!$C$16
Name FLOOR_CHAN_12_X_ARRAY_OFFSET: 'Channel Loc'!$D$17
Name FLOOR_CHAN_12_X_ARRAY_QTY: 'Channel Loc'!$E$17
Name FLOOR_CHAN_12_X_ARRAY_SPACING: 'Channel Loc'!$F$17
Name FLOOR_CHAN_12_Z_LOC: 'Channel Loc'!$C$17
Name FLOOR_CHAN_13_X_ARRAY_OFFSET: 'Channel Loc'!$D$18
Name FLOOR_CHAN_13_X_ARRAY_QTY: 'Channel Loc'!$E$18
Name FLOOR_CHAN_13_X_ARRAY_SPACING: 'Channel Loc'!$F$18
Name FLOOR_CHAN_13_Z_LOC: 'Channel Loc'!$C$18
Name FLOOR_CHAN_14_X_ARRAY_OFFSET: 'Channel Loc'!$D$19
Name FLOOR_CHAN_14_X_ARRAY_QTY: 'Channel Loc'!$E$19
Name FLOOR_CHAN_14_X_ARRAY_SPACING: 'Channel Loc'!$F$19
Name FLOOR_CHAN_14_Z_LOC: 'Channel Loc'!$C$19
Name FLOOR_CHAN_15_X_ARRAY_OFFSET: 'Channel Loc'!$D$20
Name FLOOR_CHAN_15_X_ARRAY_QTY: 'Channel Loc'!$E$20
Name FLOOR_CHAN_15_X_ARRAY_SPACING: 'Channel Loc'!$F$20
Name FLOOR_CHAN_15_Z_LOC: 'Channel Loc'!$C$20
Name FLOOR_CHAN_16_X_ARRAY_OFFSET: 'Channel Loc'!$D$21
Name FLOOR_CHAN_16_X_ARRAY_QTY: 'Channel Loc'!$E$21
Name FLOOR_CHAN_16_X_ARRAY_SPACING: 'Channel Loc'!$F$21
Name FLOOR_CHAN_16_Z_LOC: 'Channel Loc'!$C$21
Name FLOOR_CHAN_17_X_ARRAY_OFFSET: 'Channel Loc'!$D$22
Name FLOOR_CHAN_17_X_ARRAY_QTY: 'Channel Loc'!$E$22
Name FLOOR_CHAN_17_X_ARRAY_SPACING: 'Channel Loc'!$F$22
Name FLOOR_CHAN_17_Z_LOC: 'Channel Loc'!$C$22
Name FLOOR_CHAN_18_X_ARRAY_OFFSET: 'Channel Loc'!$D$23
Name FLOOR_CHAN_18_X_ARRAY_QTY: 'Channel Loc'!$E$23
Name FLOOR_CHAN_18_X_ARRAY_SPACING: 'Channel Loc'!$F$23
Name FLOOR_CHAN_18_Z_LOC: 'Channel Loc'!$C$23
Name FLOOR_CHAN_19_X_ARRAY_OFFSET: 'Channel Loc'!$D$24
Name FLOOR_CHAN_19_X_ARRAY_QTY: 'Channel Loc'!$E$24
Name FLOOR_CHAN_19_X_ARRAY_SPACING: 'Channel Loc'!$F$24
Name FLOOR_CHAN_19_Z_LOC: 'Channel Loc'!$C$24
Name FLOOR_CHAN_2_X_ARRAY_OFFSET: 'Channel Loc'!$D$7
Name FLOOR_CHAN_2_X_ARRAY_QTY: 'Channel Loc'!$E$7
Name FLOOR_CHAN_2_X_ARRAY_SPACING: 'Channel Loc'!$F$7
Name FLOOR_CHAN_2_Z_LOC: 'Channel Loc'!$C$7

Sheet Sheet1
A1: Parameter | B1: Value | C1: UM | D1: Comments
A2: Inside_Height | B2: ='Excel Calcs'!B5 -> 144 | C2: in
A3: Inside_Width | B3: ='Excel Calcs'!B6 -> 144 | C3: in
A4: Perf_H_Total | B4: ='Excel Calcs'!E25 -> 88.9 | C4: in
A5: Perf_W_Total | B5: ='Excel Calcs'!E26 -> 119 | C5: in
A6: Perf_Rows_High | B6: ='Excel Calcs'!E29 -> 1 | C6: ul
A7: Perf_Rows_Wide | B7: ='Excel Calcs'!E30 -> 4 | C7: ul
A8: Perf_H | B8: ='Excel Calcs'!E31 -> 88.9 | C8: in
A9: Perf_W | B9: ='Excel Calcs'!E32 -> 29.75 | C9: in
A10: Perf_Thk | B10: ='Excel Calcs'!E33 -> 0.044 | C10: in
A11: SupFrame_X_Loc | B11: ='Excel Calcs'!H4 -> 72 | C11: in
A12: SupFrame_Y_Loc | B12: ='Excel Calcs'!H5 -> 72 | C12: in
A13: SupFrame_Z_Loc | B13: ='Excel Calcs'!H6 -> 21 | C13: in
A14: SupFrame_Y_FanDisch_Loc | B14: ='Excel Calcs'!H7 -> 88.6275 | C14: in
A15: SupFrame_Clr_Hole_Dia | B15: ='Excel Calcs'!H8 -> 0.218 | C15: in
A16: SupFrame_VertChan_L | B16: ='Excel Calcs'!H11 -> 144 | C16: in
A17: SupFrame_VertChan_WebL | B17: ='Excel Calcs'!H12 -> 2 | C17: in
A18: SupFrame_VertChan_FlngL | B18: ='Excel Calcs'!H13 -> 1 | C18: in
A19: SupFrame_VertChan_FootFlngL | B19: ='Excel Calcs'!H14 -> 2 | C19: in
A20: SupFrame_VertChan_Thk | B20: ='Excel Calcs'!H15 -> 0.05601 | C20: in
A21: SupFrame_VertChan_Mid_Plane | B21: ='Excel Calcs'!H17 -> 59.5 | C21: in
A22: SupFrame_VertChan_Eng_Hole_Dia | B22: ='Excel Calcs'!H18 -> 0.152 | C22: in
A23: SupFrame_VertChan_Foot_Hole_XLoc | B23: ='Excel Calcs'!H19 -> 0.5 | C23: in
A24: SupFrame_VertChan_Hole1_YLoc | B24: ='Excel Calcs'!H20 -> 44.615 | C24: in
A25: SupFrame_VertChan_Hole1_XLoc | B25: ='Excel Calcs'!H21 -> 0.5 | C25: in
A26: SupFrame_VertChan_Hole1_YArrayQty | B26: ='Excel Calcs'!H22 -> 2 | C26: ul
A27: SupFrame_VertChan_Hole1_YArrayDist | B27: ='Excel Calcs'!H23 -> 87.4 | C27: in
A28: SupFrame_VertChan_Ind_Hole_Dia | B28: ='Excel Calcs'!H24 -> 0.125 | C28: in
A29: SupFrame_VertChan_Ind_Hole_Spac | B29: ='Excel Calcs'!H25 -> 0.25 | C29: in
A30: SupFrame_VertChan_Hole2_Dia | B30: ='Excel Calcs'!H26 -> 0.152 | C30: in
A31: SupFrame_VertChan_Hole2_XLoc | B31: ='Excel Calcs'!H27 -> 0.5 | C31: in
A32: SupFrame_VertChan_Hole2_YLoc | B32: ='Excel Calcs'!H28 -> 1 | C32: in
A33: SupFrame_VertChan_Hole2_Yspac | B33: ='Excel Calcs'!H29 -> 2 | C33: in
A34: SupFrame_HorzChan_L | B34: ='Excel Calcs'!H32 -> 118.82598 | C34: in
A35: SupFrame_HorzChan_WebL | B35: ='Excel Calcs'!H33 -> 1.85698 | C35: in
A36: SupFrame_HorzChan_FlngL_FIA | B36: ='Excel Calcs'!H34 -> 0.875 | C36: in
A37: SupFrame_HorzChan_FlngL_LIA | B37: ='Excel Calcs'!H35 -> 1.5 | C37: in
A38: SupFrame_HorzChan_Thk | B38: ='Excel Calcs'!H36 -> 0.05601 | C38: in
A39: SupFrame_HorzChan_Mid_Plane | B39: ='Excel Calcs'!H38 -> 44.45 | C39: in
A40: SupFrame_HorzChan_Eng_Hole_Dia | B40: ='Excel Calcs'!H39 -> 0.152 | C40: in
...

Sheet Data
A1: INPUTS
A2: Parameter | B2: Value | C2: Description | F2: THIS BOX IS OUTPUT ONLY … DO NOT USE AS INPUTS
A3: IH | B3: 144 | C3: Inside Height | F3: Thickness Outputs
A4: IW | B4: 144 | C4: Inside Width | F4: SupFrameThk | G4: =IF(SupFrameThkO="-",'Excel Calcs'!H15,SupFrameThkO) -> 0.05601 | H4: SUPPORT FRAME WORK SHEETMETAL THICKNESS
A5: FANSIZE | B5: 600 | C5: 122 to 600 Class 1 & 2 182 to 600 Class 3 - EPFN or EPQN only | F5: PerfThk | G5: =IF(PerfThkO="-",'Excel Calcs'!E33,PerfThkO) -> 0.044 | H5: SUPPORT FRAME WORK SHEETMETAL THICKNESS
A6: FANDISCHARGELOC | B6: F | C6: F, FI, R, RI, (Front, Front Inverted, Rear, Rear Inverted) | D6: F, FI, R, RI
A7: FAN_X_LOCATION | B7: 0 | C7: Location of "Base" fan in X direction (across width of unit). Dim is from RH origin plane (RH side of IW of unit) to center of Fan Discharge Default = 0 - Default value centers fan discharge in IW of unit
A8: ISOLATORDEFLECTION | B8: 2 | C8: 1 or 2 - Default = 2 | D8: 1, 2
A9: INERTIA | B9: NO | C9: YES or NO - Default = NO - Smaller fans that default to Type A base are forced to Type B when inertia is selected | D9: YES, NO
A10: MaterialStyle | B10: STL GALV | C10: STL GALV, SST304, SST304L, SST316L | D10: STL GALV, SST304, SST304L, SST316L
A11: Construction | B11: BASELINE | C11: TBD | D11: BASELINE
A12: SupFrameThkO | B12: - | C12: Top Discharge Transition Thickness Override - set to "-" when using defaults - Default = 16ga
A13: PerfThkO | B13: - | C13: Top Discharge Transition Thickness Override - set to "-" when using defaults - Default = 18ga, 0.500" holes on 0.688" stagger
A15: ERRORS | B15: =Sheet1!B94 -> 0

Sheet Excel Calcs
A2: Parameter | B2: Value | D2: Parameter | E2: Value | G2: Parameter | H2: Value | J2: Parameter | K2: Value
A3: General | D3: Fan Y Location Calculation Data | G3: Support Frame Data | J3: Vertical Cover
A4: Sheetmetal Weight lb/sqft/in | B4: 40.793 | D4: Isolator Data | G4: SupFrame_X_Loc | H4: =B11 -> 72 | J4: Cover_VertChan_L | K4: =E25-(2*(K20+0.125)) -> 86.65
A5: Inside Height | B5: =IH -> 144 | D5: Plate_Thickness | E5: ='Isolator Plate'!F6 -> 0.1875 | G5: SupFrame_Y_Loc | H5: =H11/2 -> 72 | J5: Cover_VertChan_ML | K5: =K4/2 -> 43.325
A6: Inside Width | B6: =IW -> 144 | D6: Isolator_Operating_Height | E6: =IF(AND(B13=1,B12="TYPEA"),4.625,7.25) -> 7.25 | G6: SupFrame_Z_Loc | H6: =B7/2 -> 21 | J6: Cover_VertChan_W | K6: 1
A7: Segment_Length | B7: =ROUNDUP(((SQRT((B5*B6)))*2)/7,0) -> 42 | D7: Type B & C DOA Channel Data | G7: SupFrame_Y_FanDisch_Loc | H7: =IF(OR(B18=1,B18=3),B10+B21+B22,B10+B21-B22) -> 88.6275 | J7: Cover_VertChan_MW | K7: =K6/2 -> 0.5
A8: SupFrame_Tolerance_Gap | B8: =IF(H16<=12,0.063,0.031) -> 0.031 | D8: FanBase_Str_DOA_CHAN_Lookup | E8: =CONCATENATE("Channel",E9,E10) -> Channel811.5 | G8: SupFrame_Clr_Hole_Dia | H8: ='Hole Sizes'!B7 -> 0.218 | J8: Cover_VertChan_D | K8: 1
A9: Side BH to Shell Clearance | B9: 0.31 | D9: FanBase_Str_DOA_CHAN_H | E9: =IF(B12="TYPEC",8,6) -> 8 | J9: Cover_VertChan_Thk | K9: =IF(OR(MaterialStyle="STL GALV",MaterialStyle="SST304",MaterialStyle="SST316L"),VLOOKUP(CONCATENATE(20,MaterialStyle),'Material List'!$A$8:$S$500,8,FALSE),0.03501) -> 0.03401
A10: Base_Fan_Y_Location | B10: =IF(B12="TYPEA",E5+E6+E20,E5+E6+E14+E15) -> 8.9375 | D10: FanBase_Str_DOA_CHAN_LBFT | E10: =IF(E9=6,8.2,11.5) -> 11.5 | G10: Support Frame Vertical Data | J10: Cover_VertChan_Hole1_Dia | K10: ='Hole Sizes'!B7 -> 0.218
A11: Base_Fan_X_Location | B11: =IF(FAN_X_LOCATION=0,B6/2,FAN_X_LOCATION) -> 72 | D11: FanBase_Str_DOA_CHAN_D | E11: =VLOOKUP(E8,Steel_List_Table,MATCH(STL_D,Steel_List_Column_Names,0),FALSE) -> 2.26 | G11: SupFrame_VertChan_L | H11: =B5 -> 144 | J11: Cover_VertChan_Hole1_Xloc | K11: =K6/2 -> 0.5
A12: FanBase_Type | B12: =IF(AND(VALUE(LEFT(FANSIZE,2))<=22,INERTIA="YES"),"TYPEB",IF(FANSIZE<=22,"TYPEA",IF(AND(FANSIZE>22,FANSIZE<=36),"TYPEB",IF(AND(FANSIZE>36,FANSIZE<=55),"TYPEC",IF(FANSIZE<=222,"TYPEA",IF(AND(FANSIZE>222,FANSIZE<=365),"TYPEB",IF(FANSIZE>365,"TYPEC",FALSE))))))) -> TYPEC | D12: Type B & C Isolator Support Angle Data | G12: SupFrame_VertChan_WebL | H12: 2 | J12: Cover_VertChan_Hole1_Yloc | K12: =H41+(H42/2) -> 0.75
A13: Isolator_Deflection | B13: =ISOLATORDEFLECTION -> 2 | D13: FanBase_Str_IsoSup_ANG_Lookup | E13: =IF(B13=1,1,2) -> 2 | G13: SupFrame_VertChan_FlngL | H13: 1 | J13: Cover_VertChan_Hole1_YArrayQty | K13: =ROUNDUP((K4-(2*K12))/10,0) -> 9
D14: FanBase_Str_IsoSup_ANG_WT | E14: =VLOOKUP(E13,Isolator_SupAng_Table,MATCH(SUPANG_WT,Isolator_SupAng_Column_Names,0),FALSE) -> 0.5 | G14: SupFrame_VertChan_FootFlngL | H14: 2 | J14: Cover_VertChan_Hole1_YArrayDist | K14: =(K4-(2*K12))/(K13) -> 9.4611111
A15: Parameter | B15: Value | D15: FanBase_Str_IsoSup_ANG_STD_Offset | E15: =IF(OR(E9=6,E9=8),1,IF(E9=10,3,IF(E9=12, 5,FALSE))) -> 1 | G15: SupFrame_VertChan_Thk | H15: =IF(SupFrameThkO<>"-",SupFrameThkO,VLOOKUP(CONCATENATE(H16,MaterialStyle),'Material List'!$A$8:$S$500,8,FALSE)) -> 0.05601
A16: Fan Data | D16: Type A DOA Angle Data | G16: SupFrame_VertChan_GA | H16: =IF(SupFrameThkO<>"-","NA",16) -> 16
A17: FAN_Lookup | B17: =FANSIZE -> 600 | D17: FanBase_Str_DOA_ANG_Lookup | E17: =CONCATENATE("Angle",E18,E19,E20) -> Angle640.375 | G17: SupFrame_VertChan_Mid_Plane | H17: =E26/2 -> 59.5 | J17: Horz Cover
A18: FAN_FanType_Selection | B18: =IF(FANDISCHARGELOC="F",1,IF(FANDISCHARGELOC="FI",2,IF(FANDISCHARGELOC="R",3,IF(FANDISCHARGELOC="RI",4,FALSE)))) -> 1 | D18: FanBase_Str_DOA_ANG_H | E18: 6 | G18: SupFrame_VertChan_Eng_Hole_Dia | H18: ='Hole Sizes'!I11 -> 0.152 | J18: Cover_HorzChan_L | K18: =E26-2*(0.125+B8)-2 -> 116.688
A19: FAN_A | B19: =VLOOKUP(B17,Fan_Data_Table,MATCH(FAN_A,Fan_Data_Column_Names,0),FALSE) -> 63.5 | D19: FanBase_Str_DOA_ANG_D | E19: 4 | G19: SupFrame_VertChan_Foot_Hole_XLoc | H19: 0.5 | J19: Cover_HorzChan_ML | K19: =K18/2 -> 58.344
A20: FAN_B | B20: =VLOOKUP(B17,Fan_Data_Table,MATCH(FAN_B,Fan_Data_Column_Names,0),FALSE) -> 85 | D20: FanBase_Str_DOA_ANG_WT | E20: 0.375 | G20: SupFrame_VertChan_Hole1_YLoc | H20: =H7-(E25/2)+H41 -> 44.615 | J20: Cover_HorzChan_W | K20: 1
A21: FAN_DC | B21: =VLOOKUP(B17,Fan_Data_Table,MATCH(FAN_DC,Fan_Data_Column_Names,0),FALSE) -> 48 | G21: SupFrame_VertChan_Hole1_XLoc | H21: =H13/2 -> 0.5 | J21: Cover_HorzChan_MW | K21: =K20/2 -> 0.5
A22: FAN_Q | B22: =VLOOKUP(B17,Fan_Data_Table,MATCH(FAN_Q,Fan_Data_Column_Names,0),FALSE) -> 31.69 | D22: Parameter | E22: Value | G22: SupFrame_VertChan_Hole1_YArrayQty | H22: 2 | J22: Cover_HorzChan_D | K22: 1
D23: Perf Data | G23: SupFrame_VertChan_Hole1_YArrayDist | H23: =E25-H35 -> 87.4 | J23: Cover_HorzChan_Thk | K23: =IF(OR(MaterialStyle="STL GALV",MaterialStyle="SST304",MaterialStyle="SST316L"),VLOOKUP(CONCATENATE(20,MaterialStyle),'Material List'!$A$8:$S$500,8,FALSE),0.03501) -> 0.03401
D24: Support Frame Verticals Data | G24: SupFrame_VertChan_Ind_Hole_Dia | H24: =IF(H15<=0.09,'Hole Sizes'!B35,IF(AND(H15>0.09,H15<0.14),'Hole Sizes'!B36,IF(H15>=0.14,'Hole Sizes'!B37))) -> 0.125 | J24: Cover_HorzChan_Hole1_Dia | K24: ='Hole Sizes'!B7 -> 0.218
D25: Perf_H_Total | E25: =B19*1.4 -> 88.9 | G25: SupFrame_VertChan_Ind_Hole_Spac | H25: =H24*2 -> 0.25 | J25: Cover_HorzChan_Hole1_Xloc | K25: 1
D26: Perf_W_Total | E26: =B20*1.4 -> 119 | G26: SupFrame_VertChan_Hole2_Dia | H26: ='Hole Sizes'!E17 -> 0.152 | J26: Cover_HorzChan_Hole1_Yloc | K26: 0.5
D27: Perf_Direction | E27: ="VERTICAL" -> VERTICAL | G27: SupFrame_VertChan_Hole2_XLoc | H27: =K45 -> 0.5 | J27: Cover_HorzChan_Hole1_XArrayQty | K27: =ROUNDUP((K18-(K25*2))/10,0) -> 12
D28: Perf_MaxSize_In_Direction | E28: 36 | G28: SupFrame_VertChan_Hole2_YLoc | H28: =K46 -> 1 | J28: Cover_HorzChan_Hole1_XArrayDist | K28: =ROUNDUP((K18-(K25*2))/K27,5) -> 9.55734
D29: Perf_Rows_High | E29: =IF(E27="HORIZONTAL",ROUNDUP(E25/E28,0),1) -> 1 | G29: SupFrame_VertChan_Hole2_Yspac | H29: 2
D30: Perf_Rows_Wide | E30: =IF(AND(E27="VERTICAL",FANSIZE>300),ROUNDUP(E26/E28,0),1) -> 4
D31: Perf_H | E31: =IF(E29=1,E25,E25/E29) -> 88.9 | G31: Support Frame Horizontal Data | J31: Roof Ang
D32: Perf_W | E32: =IF(E30=1,E26,E26/E30) -> 29.75 | G32: SupFrame_HorzChan_L | H32: =E26-H15*2-B8*2 -> 118.82598 | J32: Roof_AngChan_L | K32: =E26 -> 119
D33: Perf_Thk | E33: =IF(PerfThkO<>"-",PerfThkO,IF(MaterialStyle="STL GALV",VLOOKUP(CONCATENATE(E34,"GALV PRFH"),'Material List'!$A$8:$S$500,8,FALSE),IF(LEFT(MaterialStyle,3)="SST",VLOOKUP(CONCATENATE(E34,"SST304PB"),'Material List'!$A$8:$S$500,8,FALSE)))) -> 0.044 | G33: SupFrame_HorzChan_WebL | H33: =H12-H15*2-B8 -> 1.85698 | J33: Roof_AngChan_ML | K33: =K32/2 -> 59.5
D34: Perf_GA | E34: =IF(PerfThkO<>"-","NA",18) -> 18 | G34: SupFrame_HorzChan_FlngL_FIA | H34: 0.875 | J34: Roof_AngChan_W | K34: =4-K37-0.0003 -> 3.94369
G35: SupFrame_HorzChan_FlngL_LIA | H35: 1.5 | J35: Roof_AngChan_MW | K35: =K34/2 -> 1.971845
G36: SupFrame_HorzChan_Thk | H36: =IF(SupFrameThkO<>"-",SupFrameThkO,VLOOKUP(CONCATENATE(H37,MaterialStyle),'Material List'!$A$8:$S$500,8,FALSE)) -> 0.05601 | J36: Roof_AngChan_D | K36: 2
G37: SupFrame_HorzChan_GA | H37: =H16 -> 16 | J37: Roof_AngChan_Thk | K37: =IF(SupFrameThkO<>"-",SupFrameThkO,VLOOKUP(CONCATENATE(H37,MaterialStyle),'Material List'!$A$8:$S$500,8,FALSE)) -> 0.05601
G38: SupFrame_HorzChan_Mid_Plane | H38: =E25/2 -> 44.45 | J38: Roof_AngChan_Cutout_Depth | K38: =H14+B8 -> 2.031
G39: SupFrame_HorzChan_Eng_Hole_Dia | H39: ='Hole Sizes'!I12 -> 0.152 | J39: Roof_AngChan_Hole1_Dia | K39: ='Hole Sizes'!B7 -> 0.218
G40: SupFrame_HorzChan_Hole1_XLoc | H40: =H21-H15-B8 -> 0.41299 | J40: Roof_AngChan_Hole1_Xloc | K40: 2
G41: SupFrame_HorzChan_Hole1_YLoc | H41: =H34/2 -> 0.4375 | J41: Roof_AngChan_Hole1_Yloc | K41: =K36/2 -> 1
...

Sheet Fan Data
C2: Twin City BAE DWDI Fan Discharge Data
C3: FAN | D3: FAN_A | E3: FAN_B | F3: FAN_DC | G3: FAN_Q
B4: TYPE A | C4: 122 | D4: 13 | E4: 17.44 | F4: =IF(OR(FANDISCHARGELOC="F",FANDISCHARGELOC="R"),10.25,15) -> 10.25 | G4: 6.44
C5: 135 | D5: 14.31 | E5: 19.44 | F5: =IF(OR(FANDISCHARGELOC="F",FANDISCHARGELOC="R"),11.25,16.25) -> 11.25 | G5: 7.13
C6: 150 | D6: 15.88 | E6: 21.44 | F6: =IF(OR(FANDISCHARGELOC="F",FANDISCHARGELOC="R"),12.25,18) -> 12.25 | G6: 7.88
C7: 165 | D7: 17.44 | E7: 23.56 | F7: =IF(OR(FANDISCHARGELOC="F",FANDISCHARGELOC="R"),13.5,19.5) -> 13.5 | G7: 8.69
C8: 182 | D8: 19.38 | E8: 26 | F8: =IF(OR(FANDISCHARGELOC="F",FANDISCHARGELOC="R"),14.75,21.5) -> 14.75 | G8: 9.63
C9: 200 | D9: 21.19 | E9: 28.5 | F9: =IF(OR(FANDISCHARGELOC="F",FANDISCHARGELOC="R"),16.25,23.5) -> 16.25 | G9: 10.56
C10: 222 | D10: 23.56 | E10: 31.63 | F10: =IF(OR(FANDISCHARGELOC="F",FANDISCHARGELOC="R"),18,26) -> 18 | G10: 11.75
B11: TYPE B | C11: 245 | D11: 25.94 | E11: 34.81 | F11: =IF(OR(FANDISCHARGELOC="F",FANDISCHARGELOC="R"),20,28.25) -> 20 | G11: 12.94
C12: 270 | D12: 28.63 | E12: 38.25 | F12: =IF(OR(FANDISCHARGELOC="F",FANDISCHARGELOC="R"),22,31) -> 22 | G12: 14.25
C13: 300 | D13: 31.81 | E13: 42.69 | F13: =IF(OR(FANDISCHARGELOC="F",FANDISCHARGELOC="R"),24.5,34.25) -> 24.5 | G13: 15.81
C14: 330 | D14: 35.13 | E14: 46.69 | F14: =IF(OR(FANDISCHARGELOC="F",FANDISCHARGELOC="R"),27,37.25) -> 27 | G14: 17.5
C15: 365 | D15: 38.69 | E15: 51.81 | F15: =IF(OR(FANDISCHARGELOC="F",FANDISCHARGELOC="R"),29.5,41) -> 29.5 | G15: 19.25
B16: TYPE C | C16: 402 | D16: 42.63 | E16: 57.19 | F16: =IF(OR(FANDISCHARGELOC="F",FANDISCHARGELOC="R"),33,45.5) -> 33 | G16: 21.25
C17: 445 | D17: 47.13 | E17: 63.13 | F17: =IF(OR(FANDISCHARGELOC="F",FANDISCHARGELOC="R"),35.5,50) -> 35.5 | G17: 23.5
C18: 490 | D18: 51.94 | E18: 69.44 | F18: =IF(OR(FANDISCHARGELOC="F",FANDISCHARGELOC="R"),39,54.75) -> 39 | G18: 25.88
C19: 542 | D19: 57.38 | E19: 76.94 | F19: =IF(OR(FANDISCHARGELOC="F",FANDISCHARGELOC="R"),43.5,60.25) -> 43.5 | G19: 28.63
C20: 600 | D20: 63.5 | E20: 85 | F20: =IF(OR(FANDISCHARGELOC="F",FANDISCHARGELOC="R"),48,66.25) -> 48 | G20: 31.69
C21: 660 | D21: 69.69 | E21: 93.69 | F21: =IF(OR(FANDISCHARGELOC="F",FANDISCHARGELOC="R"),52.5,73.25) -> 52.5 | G21: 34.75
C22: 730 | D22: 77.25 | E22: 103.38 | F22: =IF(OR(FANDISCHARGELOC="F",FANDISCHARGELOC="R"),57,80.75) -> 57 | G22: 38.5

Sheet Channel Loc
B2: CHANNEL LOCATION DIMENSIONS (Z_LOCATION) FROM PRIMARY_Z_PLANE (SEGMENT START)
B5: Channel Name | C5: Z_LOCATION | D5: X_ARRAY_OFFSET | E5: X_ARRAY_QTY | F5: X_ARRAY_SPACING | G5: FLOOR CHANNELS
B6: FLOOR_CHAN_1 | C6: ='Excel Calcs'!B7/2 -> 21 | D6: ='Excel Calcs'!H4-('Excel Calcs'!E26/2)+'Excel Calcs'!H19 -> 13 | E6: 2 | F6: ='Excel Calcs'!H14-'Excel Calcs'!H19*2 -> 1 | H6: 091-30103-139:1 - RH Vertical
B7: FLOOR_CHAN_2 | C7: =FLOOR_CHAN_1_Z_LOC -> 21 | D7: ='Excel Calcs'!H4+('Excel Calcs'!E26/2)-'Excel Calcs'!H14+'Excel Calcs'!H19 -> 130 | E7: 2 | F7: =FLOOR_CHAN_1_X_ARRAY_SPACING -> 1 | H7: 091-30103-139:2 - LH Vertical
B8: FLOOR_CHAN_3 | C8: 0 | D8: 0 | E8: 0 | F8: 0 | H8: NOT USED
B9: FLOOR_CHAN_4 | C9: 0 | D9: 0 | E9: 0 | F9: 0 | H9: NOT USED
B10: FLOOR_CHAN_5 | C10: 0 | D10: 0 | E10: 0 | F10: 0 | H10: NOT USED
B11: FLOOR_CHAN_6 | C11: 0 | D11: 0 | E11: 0 | F11: 0 | H11: NOT USED
B12: FLOOR_CHAN_7 | C12: 0 | D12: 0 | E12: 0 | F12: 0 | H12: NOT USED
B13: FLOOR_CHAN_8 | C13: 0 | D13: 0 | E13: 0 | F13: 0 | H13: NOT USED
B14: FLOOR_CHAN_9 | C14: 0 | D14: 0 | E14: 0 | F14: 0 | H14: NOT USED
B15: FLOOR_CHAN_10 | C15: 0 | D15: 0 | E15: 0 | F15: 0 | H15: NOT USED
B16: FLOOR_CHAN_11 | C16: 0 | D16: 0 | E16: 0 | F16: 0 | H16: NOT USED
B17: FLOOR_CHAN_12 | C17: 0 | D17: 0 | E17: 0 | F17: 0 | H17: NOT USED
B18: FLOOR_CHAN_13 | C18: 0 | D18: 0 | E18: 0 | F18: 0 | H18: NOT USED
B19: FLOOR_CHAN_14 | C19: 0 | D19: 0 | E19: 0 | F19: 0 | H19: NOT USED
... B25: FLOOR_CHAN_20 | C25: 0 | D25: 0 | E25: 0 | F25: 0 | H25: NOT USED
B27: Channel Name | C27: Z_LOCATION | D27: X_ARRAY_OFFSET | E27: X_ARRAY_QTY | F27: X_ARRAY_SPACING | G27: ROOF CHANNELS
B28: ROOF_CHAN_1 | C28: =FLOOR_CHAN_1_Z_LOC -> 21 | D28: =FLOOR_CHAN_1_X_ARRAY_OFFSET -> 13 | E28: 2 | F28: ='Excel Calcs'!H14-'Excel Calcs'!H19*2 -> 1 | H28: 091-30103-139:1 - RH Vertical
B29: ROOF_CHAN_2 | C29: =ROOF_CHAN_1_Z_LOC -> 21 | D29: =FLOOR_CHAN_2_X_ARRAY_OFFSET -> 130 | E29: 2 | F29: =ROOF_CHAN_1_X_ARRAY_SPACING -> 1 | H29: 091-30103-139:2 - LH Vertical
B30: ROOF_CHAN_3 | C30: 0 | D30: 0 | E30: 0 | F30: 0 | H30: NOT USED
B31: ROOF_CHAN_4 | C31: 0 | D31: 0 | E31: 0 | F31: 0 | H31: NOT USED
B32: ROOF_CHAN_5 | C32: 0 | D32: 0 | E32: 0 | F32: 0 | H32: NOT USED
B33: ROOF_CHAN_6 | C33: 0 | D33: 0 | E33: 0 | F33: 0 | H33: NOT USED
B34: ROOF_CHAN_7 | C34: 0 | D34: 0 | E34: 0 | F34: 0 | H34: NOT USED
B35: ROOF_CHAN_8 | C35: 0 | D35: 0 | E35: 0 | F35: 0 | H35: NOT USED
B36: ROOF_CHAN_9 | C36: 0 | D36: 0 | E36: 0 | F36: 0 | H36: NOT USED
B37: ROOF_CHAN_10 | C37: 0 | D37: 0 | E37: 0 | F37: 0 | H37: NOT USED
B38: ROOF_CHAN_11 | C38: 0 | D38: 0 | E38: 0 | F38: 0 | H38: NOT USED
B39: ROOF_CHAN_12 | C39: 0 | D39: 0 | E39: 0 | F39: 0 | H39: NOT USED
B40: ROOF_CHAN_13 | C40: 0 | D40: 0 | E40: 0 | F40: 0 | H40: NOT USED
B41: ROOF_CHAN_14 | C41: 0 | D41: 0 | E41: 0 | F41: 0 | H41: NOT USED
B42: ROOF_CHAN_15 | C42: 0 | D42: 0 | E42: 0 | F42: 0 | H42: NOT USED
B44: Channel Name | C44: Z_LOCATION | D44: Y_ARRAY_OFFSET | E44: Y_ARRAY_QTY | F44: Y_ARRAY_SPACING | G44: NORTH WALL CHANNELS
B45: RIGHT_HAND_CHAN_1 | C45: 0 | D45: 0 | E45: 0 | F45: 0 | H45: NOT USED
B46: RIGHT_HAND_CHAN_2 | C46: 0 | D46: 0 | E46: 0 | F46: 0 | H46: NOT USED
B47: RIGHT_HAND_CHAN_3 | C47: 0 | D47: 0 | E47: 0 | F47: 0 | H47: NOT USED
B48: RIGHT_HAND_CHAN_4 | C48: 0 | D48: 0 | E48: 0 | F48: 0 | H48: NOT USED
B49: RIGHT_HAND_CHAN_5 | C49: 0 | D49: 0 | E49: 0 | F49: 0 | H49: NOT USED
B50: RIGHT_HAND_CHAN_6 | C50: 0 | D50: 0 | E50: 0 | F50: 0 | H50: NOT USED
...

Sheet Isolator Plate
B2: Plate Designation | C2: Plate | D2: Plate Width | E2: Plate Length | F2: Plate Thickness
B3: PLT_D | D3: PLT_W | E3: PLT_L | F3: PLT_T
B4: 1 | C4: AMSR-1C STANDARD | D4: 9 | E4: 13 | F4: 0.1875
B5: 2 | C5: AMSR-1C OFFSET | D5: 9 | E5: 13 | F5: 0.1875
B6: 3 | C6: AMSR-2D STANDARD | D6: 9 | E6: 13 | F6: 0.1875
B7: 4 | C7: AMSR-2D OFFSET | D7: =D6 -> 9 | E7: =E6 -> 13 | F7: =F6 -> 0.1875
B8: 5 | C8: AMSR-2E STANDARD | D8: =D6 -> 9 | E8: =E6 -> 13 | F8: =F6 -> 0.1875
B9: 6 | C9: AMSR-2E OFFSET | D9: =D6 -> 9 | E9: =E6 -> 13 | F9: =F6 -> 0.1875

Sheet Iso Sup Angle
B2: Isolator Designation | C2: OPERATING HEIGHT | D2: Angle Height | E2: Angle Depth | F2: Angle Length | G2: Angle Thickness
B3: SUPANG_DESG | D3: SUPANG_H | E3: SUPANG_D | F3: SUPANG_L | G3: SUPANG_WT
B4: 1 | C4: 4.625 | D4: 4 | E4: 6 | F4: 8 | G4: 0.5
B5: 2 | C5: 7.25 | D5: 4 | E5: 6 | F5: 8 | G5: 0.5

Sheet Hole Sizes
A1: Standard Hole Sizes
A2: Clearance | D2: Engagement
A3: 1/8 Rivet | B3: 0.152 | D3: 1/8 Rivet | E3: 0.140
A4: 3/16 Rivet | B4: 0.218 | D4: 3/16 Rivet | E4: 0.208
A5: #6 Hardware | B5: 0.188 | D5: 28-20 ga. (<.04 thickness)
A6: #8 Hardware | B6: 0.218 | D6: #6 Hardware | E6: 0.109
A7: #10 Hardware | B7: 0.218 | D7: #8 Hardware | E7: 0.109
A8: 1/4 Hardware | B8: 0.312 | D8: #10 Hardware | E8: 0.109
A9: 5/16 Hardware | B9: 0.375 | D9: 1/4 Hardware - galv material | E9: 0.109
A10: 3/8 Hardware | B10: 0.437 | D10: 1/4 Hardware - sst | E10: 0.188 | H10: Engagement holes per part
A11: 1/2 Hardware | B11: 0.562 | D11: 5/16 Hardware | E11: 0.109 | H11: SupFrameVertChanEngHole | I11: =IF('Excel Calcs'!H15<0.04,$E$8,IF(AND('Excel Calcs'!H15>=0.04,'Excel Calcs'!H15<=0.09),$E$17,IF('Excel Calcs'!H15>0.09,$E$25))) -> 0.152
D12: 3/8 Hardware | E12: 0.109 | H12: SupFrameHorzChanEngHole | I12: =IF('Excel Calcs'!H36<0.04,$E$8,IF(AND('Excel Calcs'!H36>=0.04,'Excel Calcs'!H36<=0.09),$E$17,IF('Excel Calcs'!H36>0.09,$E$25))) -> 0.152
D13: 18-14 ga. (>=.04 and <=.09 thickness) | H13: SupFrameVertStfnrEngHole | I13: =IF('Excel Calcs'!H56<0.04,$E$8,IF(AND('Excel Calcs'!H56>=0.04,'Excel Calcs'!H56<=0.09),$E$17,IF('Excel Calcs'!H56>0.09,$E$25))) -> 0.152
D14: #6 Hardware | E14: 0.109
D15: #8 Hardware AB, B | E15: 0.136
D16: #8 Hardware D,F,G &T | E16: 0.140
D17: #10 Hardware | E17: 0.152
D18: 1/4 Hardware AB, B | E18: 0.188
D19: 1/4 Hardware D,F,G&T | E19: 0.203
D20: 5/16 Hardware | E20: 0.218
D21: 3/8 Hardware AB,B | E21: 0.281
D22: 3/8 Hardware D,F,G&T | E22: 0.312
D23: 12 ga and up (>.09 thickness)
D24: #8 Hardware | E24: 0.152
D25: #10 Hardware | E25: 0.152
D26: 1/4 Hardware AB, B | E26: 0.203
D27: 1/4 Hardware D,F,G&T | E27: 0.218
D28: 5/16 Hardware AB,B | E28: 0.250
D29: 5/16 Hardware D,F,G&T | E29: 0.281
D30: 3/8 Hardware AB,B | E30: 0.312
D31: 3/8 Hardware D,F,G&T | E31: 0.344
A32: SPECIAL HOLE SIZES
B33: Indicator holes
A34: Ga | B34: dia | C34: spacing
A35: 28 ga - 14 ga (<=.09 thickness) | B35: 0.125 | C35: =B35 -> 0.125
A36: 12 ga - 10 ga (>.09 and < .14) | B36: 0.188 | C36: =B36 -> 0.188
A37: 8 ga. (>= .14 thickness) | B37: 0.25 | C37: =B37 -> 0.25

Sheet Material List
A1: Page: 102-006 | K1: Edit Manual | M1: PRODUCT: Solution
A2: Title: Raw Material Part Numbers, Mapics Codes, Calculations And Others | M2: 102-006.xls | Q2: Rel/Rev Date:
M3: Revision Level : | Q3: ECN Number :
B5: Solution Project, Raw material codes and calculations, Sheet or Coil stock, Square Foot
D6: Mat'l Group | E6: Metal Gauge | F6: Metal Thickness Min. | G6: Design Thickness (Ref) | H6: Inventor Thickness Key_PK | I6: Active Product "XT" | J6: Active Product "YC" | K6: Mapics Part Number | L6: Material description | M6: Material Type | N6: York "R" Std | O6: Max Cut Size | P6: Unit of Measure | Q6: Inventor Material Designation | R6: "DXF" Mat'l Data | S6: Hole Size / Texture | T6: Staggered Centers
A7: MAT_LOOKUP | D7: MAT_GRP | E7: MAT_GA | F7: MAT_MINT | G7: MAT_DEST | H7: MAT_KEYT | I7: MAT_XT | J7: MAT_YC | K7: MAT_PNUM | L7: MAT_DESC | M7: MAT_TYPE | N7: MAT_RSTD | O7: MAT_CUT | P7: MAT_UMSR | Q7: MAT_DESG | R7: MAT_DXF | S7: MAT_HLSZ | T7: MAT_STG
C8: Sheet Products, Solid
A9: =CONCATENATE(E9,Q9) -> 8STL GALV | D9: Sheet, G90 | E9: 8 | F9: .156 | G9: .156 | H9: 0.15601 | I9: XT | J9: YC | K9: 005 06145 008 | L9: Galvanized Steel | M9: G90 | N9: R259 w/ note 4 | O9: 48 X 144 | P9: SF | Q9: STL GALV | R9: GLVS157- | S9: N/A | T9: N/A
A10: =CONCATENATE(E10,Q10) -> 10STL GALV | D10: Sheet, G90 | E10: 10 | F10: .125 | G10: .126 | H10: 0.12601 | I10: - | J10: YC | K10: 005 06145 010 | L10: Galvanized Steel | M10: G90 | N10: R259 w/ note 4 | O10: 48 X 144 | P10: SF | Q10: STL GALV | R10: GLVS126- | S10: N/A | T10: N/A
A11: =CONCATENATE(E11,Q11) -> 12STL GALV | D11: Sheet, G90 | E11: 12 | F11: .096 | G11: .097 | H11: 0.09701 | I11: - | J11: YC | K11: 005 06145 012 | L11: Galvanized Steel | M11: G90 | N11: R259 w/ note 4 | O11: 60 X 144 | P11: SF | Q11: STL GALV | R11: GLVS097- | S11: N/A | T11: N/A
A12: =CONCATENATE(E12,Q12) -> 14STL GALV | D12: Sheet, G90 | E12: 14 | F12: .069 | G12: .070 | H12: 0.07001 | I12: - | J12: YC | K12: 005 06145 014 | L12: Galvanized Steel | M12: G90 | N12: R259 w/ note 4 | O12: 60 X 144 | P12: SF | Q12: STL GALV | R12: GLVS070- | S12: N/A | T12: N/A
A13: =CONCATENATE(E13,Q13) -> 16STL GALV | D13: Sheet, G90 | E13: 16 | F13: .055 | G13: .056 | H13: 0.05601 | I13: XT | J13: YC | K13: 005 06145 016 | L13: Galvanized Steel | M13: G90 | N13: R259 w/ note 4 | O13: 60 X 144 | P13: SF | Q13: STL GALV | R13: GLVS056A | S13: N/A | T13: N/A
A14: =CONCATENATE(E14,Q14) -> 18STL GALV | D14: Sheet, G90 | E14: 18 | F14: .044 | G14: .045 | H14: 0.04501 | I14: XT | J14: YC | K14: 005 06145 018 | L14: Galvanized Steel | M14: G90 | N14: R259 w/ note 4 | O14: 60 X 144 | P14: SF | Q14: STL GALV | R14: GLVS045A | S14: N/A | T14: N/A
A15: =CONCATENATE(E15,Q15) -> 20STL GALV | D15: Sheet, G90 | E15: 20 | F15: .033 | G15: .034 | H15: 0.03401 | I15: XT | J15: YC | K15: 005 06145 020 | L15: Galvanized Steel | M15: G90 | N15: R259 w/ note 4 | O15: 60 X 144 | P15: SF | Q15: STL GALV | R15: GLVS034- | S15: N/A | T15: N/A
A16: =CONCATENATE(E16,Q16) -> 22STL GALV | D16: Sheet, G90 | E16: 22 | F16: .028 | G16: .028 | H16: 0.02801 | I16: - | J16: YC | K16: 005 06145 022 | L16: Galvanized Steel | M16: G90 | N16: R259 w/ note 4 | O16: 60 X 144 | P16: SF | Q16: STL GALV | R16: GLVS028- | S16: N/A | T16: N/A
A17: =CONCATENATE(E17,Q17) -> 24STL GALV | D17: Sheet, G90 | E17: 24 | F17: .022 | G17: .022 | H17: 0.02201 | I17: XT | J17: YC | K17: 005 06145 024 | L17: Galvanized Steel | M17: G90 | N17: R259 w/ note 4 | O17: 60 X 144 | P17: SF | Q17: STL GALV | R17: GLVS022- | S17: N/A | T17: N/A
A18: =CONCATENATE(E18,Q18) -> 16STL GALV2 | D18: Roll Form Coil | E18: 16 | F18: .055 | G18: .056 | H18: 0.05605 | I18: - | J18: YC | K18: 001 07591 467 | L18: Channel,Rf,16ga,Glv,4.67w_Flat, YC 2" Housing Channel | M18: G40 | N18: R259 w/ note 4 | O18: 4.67 X Lg | P18: SF | Q18: STL GALV2 | R18: GLVS056C | S18: N/A | T18: N/A
A19: =CONCATENATE(E19,Q19) -> 16STL GALV3 | D19: Roll Form Coil | E19: 16 | F19: .055 | G19: .056 | H19: 0.05606 | I19: - | J19: YC | K19: 001 07591 567 | L19: Channel,Rf,16ga,Glv,5.67w_Flat, YC 3" Housing Channel | M19: G40 | N19: R259 w/ note 4 | O19: 5.67 X Lg | P19: SF | Q19: STL GALV3 | R19: GLVS056D | S19: N/A | T19: N/A
A20: =CONCATENATE(E20,Q20) -> 16STL GALV4 | D20: Roll Form Coil | E20: 16 | F20: .055 | G20: .056 | H20: 0.05607 | I20: - | J20: YC | K20: 001 07591 667 | L20: Channel,Rf,16ga,Glv,6.67w_Flat, YC 4" Housing Channel | M20: G40 | N20: R259 w/ note 4 | O20: 6.67 X Lg | P20: SF | Q20: STL GALV4 | R20: GLVS056E | S20: N/A | T20: N/A
A21: =CONCATENATE(E21,Q21) -> 18STL GALVS | D21: Roll Form Coil | E21: 18 | F21: .044 | G21: .045 | H21: 0.04502 | I21: XT | J21: - | K21: 005 06160 001 | L21: Galvanized Steel, Coil, XT Seam Cap | M21: G90 | N21: R259 w/ note 4 | O21: 2.491 X Lg | P21: SF | Q21: STL GALVS | R21: GLVS045B | S21: N/A | T21: N/A
A22: =CONCATENATE(E22,Q22) -> 16STL GALVR | D22: Roll Form Coil | E22: 16 | F22: .055 | G22: .056 | H22: 0.05602 | I22: XT | J22: - | K22: 005 06161 001 | L22: Galvanized Steel, Coil, XT Raceway | M22: G90 | N22: R259 w/ note 4 | O22: 12.62 X Lg | P22: SF | Q22: STL GALVR | R22: GLVS056B | S22: N/A | T22: N/A
A23: =CONCATENATE(E23,Q23) -> 14STL GALV PPG | D23: Sheet, Pre-Paint | E23: 14 | F23: .069 | G23: .070 | H23: 0.07003 | I23: - | J23: YC | K23: 005 07110 014 | L23: Sheet,Pre-Paint,Gray,14ga | M23: P-Paint | N23: M-310 | O23: 48 x Lg | P23: SF | Q23: STL GALV PPG | R23: GLVPP070A | S23: Gray Paint | T23: N/A
A24: =CONCATENATE(E24,Q24) -> 16STL GALV PPG | D24: Sheet, Pre-Paint | E24: 16 | F24: .055 | G24: .056 | H24: 0.05603 | I24: - | J24: YC | K24: 005 07110 016 | L24: Sheet,Pre-Paint,Gray,16ga | M24: P-Paint | N24: M-310 | O24: 48 x Lg | P24: SF | Q24: STL GALV PPG | R24: GLVPP056A | S24: Gray Paint | T24: N/A
A25: =CONCATENATE(E25,Q25) -> 16STL GALV PPC | D25: Sheet, Pre-Paint | E25: 16 | F25: .055 | G25: .056 | H25: 0.05604 | I25: - | J25: YC | K25: 005 07110 116 | L25: Sheet,Pre-Paint,Champagne,16ga | M25: P-Paint | N25: M-310 | O25: 48 x Lg | P25: SF | Q25: STL GALV PPC | R25: GLVPP056B | S25: Champagne Paint | T25: N/A
A26: =CONCATENATE(E26,Q26) -> 18STL GALV PPW | D26: Sheet, Pre-Paint | E26: 18 | F26: .044 | G26: .045 | H26: 0.04503 | I26: - | J26: YC | K26: 005 07110 117 | L26: Sheet,Pre-Paint,Msftwhite,18ga | M26: P-Paint | N26: M-310 | O26: 48 x Lg | P26: SF | Q26: STL GALV PPW | R26: GLVPP045A | S26: Msftwhite Paint | T26: N/A
A27: =CONCATENATE(E27,Q27) -> 18STL GALV PPC | D27: Sheet, Pre-Paint | E27: 18 | F27: .044 | G27: .045 | H27: 0.04504 | I27: - | J27: YC | K27: 005 07110 118 | L27: Sheet,Pre-Paint,Champagne,18ga | M27: P-Paint | N27: M-310 | O27: 48 x Lg | P27: SF | Q27: STL GALV PPC | R27: GLVPP045B | S27: Champagne Paint | T27: N/A
A28: =CONCATENATE(E28,Q28) -> 10STL HOT ROLL | D28: Sheet, HR | E28: 10 | F28: .127 | G28: .127 | H28: 0.12701 | I28: - | J28: YC | K28: 005 07113 010 | L28: Sheet,Hot-Rolled,10ga | M28: HR | N28: - | O28: 48 X 144 | P28: SF | Q28: STL HOT ROLL | R28: STLHR127A | S28: Hot-Rolled | T28: N/A
A29: =CONCATENATE(E29,Q29) -> 11STL HOT ROLL | D29: Sheet, HR | E29: 11 | F29: .112 | G29: .112 | H29: 0.11201 | I29: - | J29: YC | K29: 005 07113 011 | L29: Sheet,Hot-Rolled,11ga | M29: HR | N29: - | O29: 48 X 96 | P29: SF | Q29: STL HOT ROLL | R29: STLHR112A | S29: Hot-Rolled | T29: N/A
A30: =CONCATENATE(E30,Q30) -> 12STL HOT ROLL | D30: Sheet, HR | E30: 12 | F30: .097 | G30: .097 | H30: 0.09704 | I30: - | J30: YC | K30: 005 07113 012 | L30: Sheet,Hot-Rolled,12ga | M30: HR | N30: - | O30: 48 X 96 | P30: SF | Q30: STL HOT ROLL | R30: STLHR097A | S30: Hot-Rolled | T30: N/A
A31: =CONCATENATE(E31,Q31) -> 14STL HOT ROLL | D31: Sheet, HR | E31: 14 | F31: .068 | G31: .068 | H31: 0.06801 | I31: - | J31: YC | K31: 005 07113 014 | L31: Sheet,Hot-Rolled,14ga | M31: HR | N31: - | O31: 48 X 120 | P31: SF | Q31: STL HOT ROLL | R31: STLHR068A | S31: Hot-Rolled | T31: N/A
A32: =CONCATENATE(E32,Q32) -> 20ALM SHT | D32: Sheet, AL | E32: 20 | F32: .040 | G32: .040 | H32: 0.04001 | I32: - | J32: YC | K32: 008 02570 040 | L32: Sheet,Al,3003h14,.040 | M32: AL | N32: R-777 | O32: 48 x 144 | P32: SF | Q32: ALM SHT | R32: ALUS040A | S32: N/A | T32: N/A
A33: =CONCATENATE(E33,Q33) -> 18ALM SHT | D33: Sheet, AL | E33: 18 | F33: .050 | G33: .050 | H33: 0.05003 | I33: - | J33: YC | K33: 008 02570 050 | L33: Sheet,Al,3003h14,.050 | M33: AL | N33: R-777 | O33: 48 x 144 | P33: SF | Q33: ALM SHT | R33: ALUS050A | S33: N/A | T33: N/A
A34: =CONCATENATE(E34,Q34) -> 16ALM SHT | D34: Sheet, AL | E34: 16 | F34: .063 | G34: .063 | H34: 0.06301 | I34: - | J34: YC | K34: 008 02570 063 | L34: Sheet,Al,3003h14,.063 | M34: AL | N34: R-777 | O34: 48 x 144 | P34: SF | Q34: ALM SHT | R34: ALUS063A | S34: N/A | T34: N/A
A35: =CONCATENATE(E35,Q35) -> 14ALM SHT | D35: Sheet, AL | E35: 14 | F35: .080 | G35: .080 | H35: 0.08001 | I35: - | J35: YC | K35: 008 02570 080 | L35: Sheet,Al,3003h14,.080 | M35: AL | N35: R-777 | O35: 48 x 144 | P35: SF | Q35: ALM SHT | R35: ALUS080A | S35: N/A | T35: N/A
A36: =CONCATENATE(E36,Q36) -> 10ALM SHT | D36: Sheet, AL | E36: 10 | F36: .125 | G36: .125 | H36: 0.12501 | I36: - | J36: YC | K36: 008 02570 125 | L36: Sheet,Al,3003h14,.125 | M36: AL | N36: R-777 | O36: 48 x 144 | P36: SF | Q36: ALM SHT | R36: ALUS125A | S36: N/A | T36: N/A
A37: =CONCATENATE(E37,Q37) -> 8ALM SHT | D37: Sheet, AL | E37: 8 | F37: .190 | G37: .190 | H37: 0.19001 | I37: - | J37: YC | K37: 008 02570 190 | L37: Sheet,Al,3003h14,.190 | M37: AL | N37: R-777 | O37: 48 x 144 | P37: SF | Q37: ALM SHT | R37: ALUS190A | S37: N/A | T37: N/A
A38: =CONCATENATE(E38,Q38) -> 8SST304 | D38: Sheet, SST | E38: 8 | F38: .165 | G38: .165 | H38: 0.16501 | I38: N/A | J38: N/A | K38: 005 06146 008 | L38: Stainless steel | M38: 304 | N38: R52 | O38: 48 X 144 | P38: SF | Q38: SST304 | R38: SSTS165- | S38: N/A | T38: N/A
A39: =CONCATENATE(E39,Q39) -> 10SST304 | D39: Sheet, SST | E39: 10 | F39: .135 | G39: .135 | H39: 0.13501 | I39: XT | J39: YC | K39: 005 06146 010 | L39: Stainless steel | M39: 304 | N39: R52 | O39: 48 X 144 | P39: SF | Q39: SST304 | R39: SSTS135- | S39: N/A | T39: N/A
A40: =CONCATENATE(E40,Q40) -> 12SST304 | D40: Sheet, SST | E40: 12 | F40: .105 | G40: .105 | H40: 0.10501 | I40: XT | J40: YC | K40: 005 06146 012 | L40: Stainless steel | M40: 304 | N40: R52 | O40: 60 X 144 | P40: SF | Q40: SST304 | R40: SSTS105- | S40: N/A | T40: N/A
A41: =CONCATENATE(E41,Q41) -> 14SST304 | D41: Sheet, SST | E41: 14 | F41: .075 | G41: .075 | H41: 0.07501 | I41: XT | J41: YC | K41: 005 06146 014 | L41: Stainless steel | M41: 304 | N41: R52 | O41: 60 X 144 | P41: SF | Q41: SST304 | R41: SSTS075- | S41: N/A | T41: N/A
...

Sheet Steel List
B2: Solution Project, Raw material codes and calculations, Sheet or Coil stock, Square Foot
D3: Mat'l Group | E3: LBS/FT | F3: Web/Wall Thickness | G3: Height | I3: Depth | J3: Flange Thickness/ Radius | K3: Active Product "XT" | L3: Active Product "YC" | M3: Mapics Part Number | N3: Material description | O3: Material Type | P3: York "R" Std | Q3: Max Cut Size | R3: Unit of Measure | S3: Inventor Material Designation | T3: "DXF" Mat'l Data
A4: STL_LOOKUP | D4: STL_GRP | E4: STL_LBFT | F4: STL_WT | G4: STL_H | I4: STL_D | J4: STL_FTR | K4: STL_XT | L4: STL_YC | M4: STL_PNUM | N4: STL_DESC | O4: STL_TYPE | P4: STL_RSTD | Q4: STL_CUT | R4: STL_UMSR | S4: STL_DESG | T4: STL_DXF
C5: Structural Steel, Shapes
A6: =CONCATENATE(RIGHT(D6,LEN(D6)-FIND(" ",D6)),G6,E6) -> Channel20.56 | D6: Steel, Channel | E6: 0.56 | F6: 0.188 | G6: 2 | I6: 1.000 | J6: 0.188 | K6: - | L6: YC | M6: 001-07500-000 | N6: Channel 2 X 1 X .19,R-18 Std | O6: A572 HRS | P6: R18 | Q6: 324 IN length | R6: IN | S6: - | T6: -
A7: =CONCATENATE(RIGHT(D7,LEN(D7)-FIND(" ",D7)),G7,E7) -> Channel34.1 | D7: Steel, Channel | E7: 4.1 | F7: 0.17 | G7: 3 | I7: 1.41 | J7: 0.273 | K7: - | L7: YC | M7: 001-07501-000 | N7: Channel 3 X 4.1 Lb/Ft,R-18 Std | O7: A572 HRS | P7: R18 | Q7: 324 IN length | R7: IN | S7: - | T7: -
A8: =CONCATENATE(RIGHT(D8,LEN(D8)-FIND(" ",D8)),G8,E8) -> Channel35 | D8: Steel, Channel | E8: 5 | F8: 0.258 | G8: 3 | I8: 1.498 | J8: 0.273 | K8: XT | L8: - | M8: 001 08405 003 | N8: 3" x 5.0# Structural Channel | O8: A572 HRS | P8: R18 | Q8: 324 IN length | R8: IN | S8: - | T8: -
A9: =CONCATENATE(RIGHT(D9,LEN(D9)-FIND(" ",D9)),G9,E9) -> Channel45.4 | D9: Steel, Channel | E9: 5.4 | F9: 0.184 | G9: 4 | I9: 1.584 | J9: 0.296 | K9: XT | L9: YC | M9: 001 08405 004 | N9: 4" x 5.4# Structural Channel | O9: A572 HRS | P9: R18 | Q9: 324 IN length | R9: IN | S9: - | T9: -
A10: =CONCATENATE(RIGHT(D10,LEN(D10)-FIND(" ",D10)),G10,E10) -> Channel47.25 | D10: Steel, Channel | E10: 7.25 | F10: 0.321 | G10: 4 | I10: 1.721 | J10: 0.296 | K10: XT | L10: - | M10: 001 08405 104 | N10: 4" x 7.25# Structural Channel | O10: A572 HRS | P10: R18 | Q10: 324 IN length | R10: IN | S10: - | T10: -
A11: =CONCATENATE(RIGHT(D11,LEN(D11)-FIND(" ",D11)),G11,E11) -> Channel56.7 | D11: Steel, Channel | E11: 6.7 | F11: 0.19 | G11: 5 | I11: 1.75 | J11: 0.32 | K11: - | L11: YC | M11: 001 08405 005 | N11: Channel 5 X 6.7 Lb/Ft,R-18 Std | O11: A572 HRS | P11: R18 | Q11: 324 IN length | R11: IN | S11: - | T11: -
A12: =CONCATENATE(RIGHT(D12,LEN(D12)-FIND(" ",D12)),G12,E12) -> Channel68.2 | D12: Steel, Channel | E12: 8.2 | F12: 0.2 | G12: 6 | I12: 1.92 | J12: 0.343 | K12: XT | L12: YC | M12: 001 08405 006 | N12: 6" x 8.2# Structural Channel | O12: A572 HRS | P12: R18 | Q12: 324 IN length | R12: IN | S12: - | T12: -
A13: =CONCATENATE(RIGHT(D13,LEN(D13)-FIND(" ",D13)),G13,E13) -> Channel811.5 | D13: Steel, Channel | E13: 11.5 | F13: 0.22 | G13: 8 | I13: 2.26 | J13: 0.39 | K13: XT | L13: YC | M13: 001 08405 008 | N13: 8" x 11.5# Structural Channel | O13: A572 HRS | P13: R18 | Q13: 324 IN length | R13: IN | S13: - | T13: -
A14: =CONCATENATE(RIGHT(D14,LEN(D14)-FIND(" ",D14)),G14,E14) -> Channel1015.3 | D14: Steel, Channel | E14: 15.3 | F14: 0.24 | G14: 10 | I14: 2.6 | J14: 0.438 | K14: XT | L14: YC | M14: 001 08405 010 | N14: 10" x 15.3# Structural Channel | O14: A572 HRS | P14: R18 | Q14: 324 IN length | R14: IN | S14: - | T14: -
A15: =CONCATENATE(RIGHT(D15,LEN(D15)-FIND(" ",D15)),G15,E15) -> Channel1220.7 | D15: Steel, Channel | E15: 20.7 | F15: 0.282 | G15: 12 | I15: 2.942 | J15: 0.501 | K15: XT | L15: YC | M15: 001 08405 012 | N15: 12" x 20.7# Structural Channel | O15: A572 HRS | P15: R18 | Q15: 324 IN length | R15: IN | S15: - | T15: -
A16: =CONCATENATE(RIGHT(D16,LEN(D16)-FIND(" ",D16)),G16,E16) -> I-Beam35.7 | D16: Steel, I-Beam | E16: 5.7 | F16: 0.17 | G16: 3 | I16: 2.33 | J16: 0.26 | K16: - | L16: YC | M16: 001-07638-000 | N16: I-Beam 3 X 5.7 Lb/Ft, R-18 Std | O16: A36 HRS | P16: R18 | Q16: 324 IN length | R16: IN | S16: - | T16: -
A17: =CONCATENATE(RIGHT(D17,LEN(D17)-FIND(" ",D17)),G17,E17) -> I-Beam47.7 | D17: Steel, I-Beam | E17: 7.7 | F17: 0.19 | G17: 4 | I17: 2.66 | J17: 0.293 | K17: XT | L17: YC | M17: 001-08409-004 | N17: I-Beam 4 X 7.7 Lb/Ft,R-18 Std | O17: A36 HRS | P17: R18 | Q17: 324 IN length | R17: IN | S17: - | T17: -
A18: =CONCATENATE(RIGHT(D18,LEN(D18)-FIND(" ",D18)),G18,E18) -> I-Beam612.5 | D18: Steel, I-Beam | E18: 12.5 | F18: 0.23 | G18: 6 | I18: 3.33 | J18: 0.359 | K18: - | L18: YC | M18: 001-07509-000 | N18: I-Beam 6 X 12.5 Lb/Ft,R-18 Std | O18: A36 HRS | P18: R18 | Q18: 324 IN length | R18: IN | S18: - | T18: -
A19: =CONCATENATE(RIGHT(D19,LEN(D19)-FIND(" ",D19)),G19,E19) -> I-Beam818.4 | D19: Steel, I-Beam | E19: 18.4 | F19: 0.27 | G19: 8 | I19: 4 | J19: 0.425 | K19: - | L19: YC | M19: 001-07510-000 | N19: I-Beam 8 X 18.4 Lb/Ft,R-18 Std | O19: A36 HRS | P19: R18 | Q19: 324 IN length | R19: IN | S19: - | T19: -
A20: =CONCATENATE(RIGHT(D20,LEN(D20)-FIND(" ",D20)),G20,I20,F20) -> Angle0.750.750.125 | D20: Steel, Angle | E20: 0.59 | F20: 0.125 | G20: 0.75 | I20: 0.75 | J20: 0.125 | K20: XT | L20: - | M20: 001 08406 075 | N20: 3/4" x 3/4" x 1/8" Structural Angle | O20: A36 HRS | P20: R18 | Q20: 324 IN length | R20: IN | S20: - | T20: -
A21: =CONCATENATE(RIGHT(D21,LEN(D21)-FIND(" ",D21)),G21,I21,F21) -> Angle110.25 | D21: Steel, Angle | E21: 1.49 | F21: 0.25 | G21: 1 | I21: 1 | J21: 0.125 | K21: XT | L21: - | M21: 001 08406 100 | N21: 1" x 1" x 1/4" Structural Angle | O21: A36 HRS | P21: R18 | Q21: 324 IN length | R21: IN | S21: - | T21: -
A22: =CONCATENATE(RIGHT(D22,LEN(D22)-FIND(" ",D22)),G22,I22,F22) -> Angle1.251.250.25 | D22: Steel, Angle | E22: 1.92 | F22: 0.25 | G22: 1.25 | I22: 1.25 | J22: 0.188 | K22: XT | L22: - | M22: 001 08406 125 | N22: 1-1/4" x 1-1/4" x 1/4" Structural Angle | O22: A36 HRS | P22: R18 | Q22: 324 IN length | R22: IN | S22: - | T22: -
A23: =CONCATENATE(RIGHT(D23,LEN(D23)-FIND(" ",D23)),G23,I23,F23) -> Angle1.51.50.25 | D23: Steel, Angle | E23: 2.34 | F23: 0.25 | G23: 1.5 | I23: 1.5 | J23: 0.188 | K23: XT | L23: - | M23: 001 08406 150 | N23: 1-1/2" x 1-1/2" x 1/4" Structural Angle | O23: A36 HRS | P23: R18 | Q23: 324 IN length | R23: IN | S23: - | T23: -
A24: =CONCATENATE(RIGHT(D24,LEN(D24)-FIND(" ",D24)),G24,I24,F24) -> Angle220.25 | D24: Steel, Angle | E24: 3.19 | F24: 0.25 | G24: 2 | I24: 2 | J24: 0.281 | K24: XT | L24: YC | M24: 001 08406 200 | N24: 2" x 2" x 1/4" Structural Angle | O24: A36 HRS | P24: R18 | Q24: 324 IN length | R24: IN | S24: - | T24: -
A25: =CONCATENATE(RIGHT(D25,LEN(D25)-FIND(" ",D25)),G25,I25,F25) -> AngleCoped220.25 | D25: Steel, AngleCoped | E25: 3.19 | F25: 0.25 | G25: 2 | I25: 2 | J25: 0.281 | K25: XT | L25: - | M25: 001 08407 200 | N25: 2" x 2" x 1/4" Structural Angle, Coped Both Ends | O25: A36 HRS | P25: R18 | Q25: 324 IN length | R25: IN | S25: - | T25: -
A26: =CONCATENATE(RIGHT(D26,LEN(D26)-FIND(" ",D26)),G26,I26,F26) -> Angle220.188 | D26: Steel, Angle | E26: 2.44 | F26: 0.188 | G26: 2 | I26: 2 | J26: 0.281 | K26: - | L26: YC | M26: 001-05057-000 | N26: Angle Blk 2 X 2 X .19 | O26: A36 HRS | P26: R18 | Q26: 324 IN length | R26: IN | S26: - | T26: -
A27: =CONCATENATE(RIGHT(D27,LEN(D27)-FIND(" ",D27)),G27,I27,F27) -> Angle430.375 | D27: Steel, Angle | E27: 8.5 | F27: 0.375 | G27: 4 | I27: 3 | J27: 0.5 | K27: - | L27: YC | M27: 001 08406 403 | N27: Angle Blk 4 x 3 x .38 thk | O27: A36 HRS | P27: R19 | Q27: 324 IN length | R27: IN | S27: - | T27: -
A28: =CONCATENATE(RIGHT(D28,LEN(D28)-FIND(" ",D28)),G28,I28,F28) -> Angle440.375 | D28: Steel, Angle | E28: 9.8 | F28: 0.375 | G28: 4 | I28: 4 | J28: 0.5 | K28: - | L28: YC | M28: 001 08406 404 | N28: Angle Blk 4 x 4 x .38 thk | O28: A36 HRS | P28: R19 | Q28: 324 IN length | R28: IN | S28: - | T28: -
A29: =CONCATENATE(RIGHT(D29,LEN(D29)-FIND(" ",D29)),G29,I29,F29) -> Angle640.375 | D29: Steel, Angle | E29: 12.3 | F29: 0.375 | G29: 6 | I29: 4 | J29: 0.5 | K29: - | L29: YC | M29: 001 07501 064 | N29: Angle Blk 6 x 4 x .38 thk | O29: A36 HRS | P29: R18 | Q29: 324 IN length | R29: IN | S29: - | T29: -
A30: =CONCATENATE(RIGHT(D30,LEN(D30)-FIND(" ",D30)),G30,I30,F30) -> Tubing110.065 | D30: Steel, Tubing | E30: 0.8265 | F30: 0.065 | G30: 1 | I30: 1 | J30: - | K30: - | L30: YC | M30: 001-07517-000 | N30: Tubing 1 X 1 X .065 | O30: A36 | P30: - | Q30: 324 IN length | R30: IN | S30: - | T30: -
A31: =CONCATENATE(RIGHT(D31,LEN(D31)-FIND(" ",D31)),G31,I31,F31) -> Tubing330.12 | D31: Steel, Tubing | E31: 4.58 | F31: 0.12 | G31: 3 | I31: 3 | J31: - | K31: XT | L31: YC | M31: 001-08408-003 | N31: Tubing 3 X 3 X .120 | O31: A36 | P31: - | Q31: 324 IN length | R31: IN | S31: - | T31: -
A32: =CONCATENATE(RIGHT(D32,LEN(D32)-FIND(" ",D32)),G32,I32,F32) -> Tubing440.12 | D32: Steel, Tubing | E32: 6.22 | F32: 0.12 | G32: 4 | I32: 4 | J32: - | K32: - | L32: YC | M32: 001-07519-000 | N32: Tubing 4 X 4 X .120 | O32: A36 | P32: - | Q32: 324 IN length | R32: IN | S32: - | T32: -
A33: =CONCATENATE(RIGHT(D33,LEN(D33)-FIND(" ",D33)),G33,I33,F33) -> Tubing220.12 | D33: Steel, Tubing | E33: 2.94 | F33: 0.12 | G33: 2 | I33: 2 | J33: - | K33: XT | L33: YC | M33: 001-08408-002 | N33: Tubing 2 X 2 X .120 | O33: A36 | P33: - | Q33: 324 IN length | R33: IN | S33: - | T33: -
A34: =CONCATENATE(RIGHT(D34,LEN(D34)-FIND(" ",D34)),G34,I34,F34) -> Tubing1.50.750.12 | D34: Steel, Tubing | E34: 1.64 | F34: 0.12 | G34: 1.5 | I34: 0.75 | J34: - | K34: - | L34: YC | M34: 001 08570 000 | N34: Tubing, Blk 3/4"x1 1/2"x.120 | O34: A36 | P34: - | Q34: 324 IN length | R34: IN | S34: - | T34: -
A35: =CONCATENATE(RIGHT(D35,LEN(D35)-FIND(" ",D35)),I35,F35) -> Flat Bar30.25 | D35: Steel, Flat Bar | E35: 2.975 | F35: 0.25 | G35: - | I35: 3 | J35: - | K35: - | L35: YC | M35: 001-07578-000 | N35: Flat Bar 3 x .25 THK | O35: A36 | P35: - | Q35: 324 IN length | R35: IN | S35: - | T35: -
A36: =CONCATENATE(E36,S36)
A37: =CONCATENATE(E37,S37)
A38: =CONCATENATE(E38,S38) | C38: Aluminum, Extruded, Shapes
A39: =T39 -> ALUT12TB | D39: Alum, Extrude, Track | E39: - | F39: - | G39: - | I39: - | J39: - | K39: XT | L39: - | M39: 008 02326 010 | N39: Track,Fltr,Top/Btm,W/2_Pre | O39: extru. Al. | P39: - | Q39: IN length | R39: IN | S39: ALM TRK 12TB | T39: ALUT12TB
A40: =T40 -> ALUT12M- | D40: Alum, Extrude, Track | E40: - | F40: - | G40: - | I40: - | J40: - | K40: XT | L40: - | M40: 008 02327 010 | N40: Track,Fltr,Mid,W/2_Pre | O40: extru. Al. | P40: - | Q40: IN length | R40: IN | S40: ALM TRK 12M | T40: ALUT12M-
A41: =T41 -> ALUT14TB | D41: Alum, Extrude, Track | E41: - | F41: - | G41: - | I41: - | J41: - | K41: XT | L41: - | M41: 008 02328 010 | N41: Track,Fltr,Top/Btm,W/4_Pre | O41: extru. Al. | P41: - | Q41: IN length | R41: IN | S41: ALM TRK 14TB | T41: ALUT14TB
...

Sheet Revision List
A1: Revision | B1: Date | C1: Description | D1: By | E1: ECN Number
A2: - | B2: 42262 | C2: NEW | D2: PS | E2: 15-8703
A3: A | B3: 43628 | C3: ADDED INPUT LISTS FOR DROPDOWN MENU | D3: WWO | E3: 19-10292
A4: B | B4: 45183 | C4: SPLIT FORMULA UPDATED AND SPLIT SEAM MADE VERTICAL | D4: SJ | E4: 23-11434
A5: C | B5: 45334 | C5: ROOF ANGLE AND PERF EDGE COVER ADDED | D5: SJ | E5: 24-11496
